Workbook
Name NombreIntervalo1: DATOS!$D$2:$D$5
Name CURSO: CONFIGURACION!$E$2:$E$17

Sheet CONFIGURACION
A1: ANIO_ACADEMICO | C1: CICLO | D1: GRADO | E1: CURSO | G1: GENERO | I1: PERIODO | K1: PRUEBA | L1: HABILITAR | M1: NOMBRE_PRUEBA | N1: UNIDAD | O1: TIPO | P1: OBJETIVO | Q1: MEDIO | R1: MATERIAL | S1: DESCRIPCION | T1: VALORACION
A2: 2024-2025 | C2: ESO | D2: 1 | E2: A | G2: MASCULINO | I2: 1 TRIMESTRE | K2: S. HORIZONTAL | L2: SI | M2: Test de Salto Horizontal | N2: cm | O2: Fuerza | P2: Determinar la potencia de las piernas. | Q2: Superficie plana y antideslizante, con una línea dibujada en el suelo. | S2: Posición inicial: El ejecutante ha de situarse derecho con los pies ligeramente separados y la punta de los pies detrás de la línea de salida. Desarrollo: Ha de tomar impulso para saltar, flexionando las piernas y empujando con los brazos desde detrás hacia adelante. Se salta haciendo una rápida extensión de las piernas y estirando los brazos hacia adelante. Finalización: En el momento de la caída, el ejecutante ha de mantener los pies en el mismo sitio donde ha tomado contacto con el suelo sin perder el equilibrio. | T2: Se registrará la distancia en centímetros. Hay que anotar el mejor de los dos resultados.
C3: ESO | D3: 1 | E3: B | G3: FEMENINO | I3: 2 TRIMESTRE | K3: L. BALON | L3: SI | M3: Test de Balón medicinal | N3: m | O3: Fuerza | P3: Medir la fuerza del tren superior. | Q3: Superficie plana y antideslizante. | R3: Balón medicinal. | S3: Posición inicial: El ejecutante se colocará en la línea con los pies separados a la anchura de los hombros, cogiendo el balón con las dos manos por detrás de la cabeza. Desarrollo: Lanzar el balón lo más lejos posible. No se podrá saltar en el momento del lanzamiento. De igual modo, se tendrá que mantener la posición de equilibrio. Se ejecutarán dos intentos. | T3: Se registrará la distancia en centímetros. Hay que anotar el mejor de los dos resultados.
C4: ESO | D4: 2 | E4: A | I4: 3 TRIMESTRE | K4: ABDOMINALES | L4: SI | M4: Test de Abdominales | N4: repeticiones | O4: Fuerza | P4: Medir la fuerza-resistencia de los músculos abdominales. | Q4: Superficie plana y lisa. | R4: Cronómetro con precisión de centésimas de segundo. | S4: Posición Inicial: El ejecutante ha de colocarse en decúbito supino con las piernas flexionadas 90o, los pies ligeramente separados y los dedos entrelazados detrás de la nuca o brazos cruzados sobre el pecho. Un ayudante ha de sujetarle los pies para fijarlos al suelo. Desarrollo: Al oír la señal del observador "preparado...ya!", el ejecutante ha de tratar de hacer el mayor número de repeticiones posibles, tocando siempre con los codos las rodillas y con la espalda en la colchoneta. El ayudante contará el número de repeticiones. Finalización: Cuando hayan pasado 30” se indicará el final. | T4: Se registra el número de repeticiones realizadas correctamente. Solo habrá un intento.
C5: ESO | D5: 2 | E5: B | K5: FLEXIBILIDAD | L5: SI | M5: Test de Flexión anterior del tronco | N5: cm | O5: Flexibilidad | P5: Medir la flexibilidad del tronco. | Q5: Superficie antideslizante. | S5: Posición Inicial: El ejecutante descalzo, se ha de sentar enfrente del cajón con las piernas completamente extendidas y las plantas de los pies en completo contacto con la pared del cajón. Desarrollo: Flexionar el tronco hacia adelante sin doblar las piernas, y extender los brazos y las palmas de la mano sobre la regla, ha de tratar de llegar lo más lejos posible. Finalización: El ejecutante, en el momento en que llega a la posición máxima, ha de permanecer inmóvil durante 2 segundos para que se pueda registrar el resultado conseguido. | T5: El registro se hará en centímetros. Se anota el mejor de los 2 resultados.
C6: ESO | D6: 3 | E6: A | K6: S. VERTICAL | L6: SI | M6: Test de Salto Vertical | N6: cm | O6: Fuerza | P6: Medir la fuerza explosiva del tren inferior en el sentido vertical. | Q6: Superficie plana y antideslizante. | R6: Tabla graduada o escala pintada sobre la pared. | S6: Posición Inicial: El ejecutante se colocará junto a una pared, lateralmente, y con el brazo más próximo a ella señalará su punto más alto. Desarrollo: A la señal y previa separación de la pared, ha de tomar impulso para saltar, flexionando las piernas, hasta alcanzar el máximo posible dejando marca con los dedos en la tabla. | T6: Se registrará la diferencia entre el máximo estático y el de la marca del salto en centímetros. Hay que anotar el mejor de los dos resultados.
C7: ESO | D7: 3 | E7: B | K7: COOPER | L7: SI | M7: Test de Cooper | N7: m | O7: Resistencia | P7: Valorar la resistencia aeróbica. Determinar el VO2 máximo. | Q7: Pista o terreno liso y sin pendiente. | R7: Cronómetro | S7: Consiste en cubrir la máxima distancia posible durante 12 minutos de carrera continua. | T7: Se anotará la distancia recorrida al finalizar los doce minutos.
C8: ESO | D8: 4 | E8: A | K8: VELOCIDAD | L8: SI | M8: Test de Velocidad en 50m | N8: seg | O8: Velocidad | P8: Medir la velocidad de traslación partiendo de una velocidad inicial igual a 0. | Q8: Pista o terreno liso y sin pendiente. | R8: Cronómetro | S8: Recorrer la distancia de 50 metros en el menor tiempo posible. Se realizarán dos intentos con un periodo de reposo entre cada uno. | T8: El registro se hará en centésimas de segundo. Se anota el mejor de los dos resultados.
C9: ESO | D9: 4 | E9: B | K9: INTESIDAD FISICA | L9: NO | M9: Test de intensidad de esfuerzos físicos | N9: fc | O9: Medición | P9: Calcular la zona de actividad a partir de la frecuencia cardiaca y ejercicio físico | Q9: Cualquier medio | R9: Cronómetro | S9: Conocer la intensidad de nuestros esfuerzos y nos va a ayudar a situarnos en la ZONA DE ACTIVIDAD apropiada según el objetivo que pretendamos. | T9: Toma el pulso nada más parar la actividad física, durante 15” y multiplica tu resultado por 4 para saber los latidos por minuto.
C10: ESO | D10: 1 | E10: A1
C11: ESO | D11: 1 | E11: A2-C
C12: BCH | D12: 1 | E12: B1
C13: BCH | D13: 1 | E13: B2
C14: BCH | D14: 2 | E14: A1
C15: BCH | D15: 2 | E15: B1
C16: BCH | D16: 2 | E16: B2
C17: BCH | D17: 2 | E17: C

Sheet ALUMNOS
A1: CICLO | B1: GRADO | C1: CURSO | D1: NOMBRE_ALUMNO | E1: GENERO | F1: Peso (kg) | G1: Talla (cm)
A2: {=IF(C2="","",IFERROR(INDEX(CONFIGURACION!C:C,MATCH(C2,CONFIGURACION!E:E,0)),""))} -> BCH | B2: {=IF(C2="","",IFERROR(INDEX(CONFIGURACION!D:D,MATCH(C2,CONFIGURACION!E:E,0)),""))} -> 1 | C2: B1 | D2: Manolo Díaz Camacho | E2: MASCULINO
A3: {=IF(C3="","",IFERROR(INDEX(CONFIGURACION!C:C,MATCH(C3,CONFIGURACION!E:E,0)),""))} -> BCH | B3: {=IF(C3="","",IFERROR(INDEX(CONFIGURACION!D:D,MATCH(C3,CONFIGURACION!E:E,0)),""))} -> 1 | C3: B1 | D3: Juan Carlos Huizar Moreno | E3: MASCULINO
A4: {=IF(C4="","",IFERROR(INDEX(CONFIGURACION!C:C,MATCH(C4,CONFIGURACION!E:E,0)),""))} -> BCH | B4: {=IF(C4="","",IFERROR(INDEX(CONFIGURACION!D:D,MATCH(C4,CONFIGURACION!E:E,0)),""))} -> 1 | C4: B1 | D4: Gerardo Huizar Castro | E4: MASCULINO
A5: BCH | B5: 1 | C5: B2 | D5: Alumno de prueba | E5: MASCULINO
A6: ESO | B6: 1 | C6: A | D6: Alumno de prueba 2 | E6: MASCULINO
A7: ESO | B7: 1 | C7: A | D7: Alumna de prueba 3 | E7: MASCULINO

Sheet DATOS
A1: CICLO | B1: GRADO | C1: GENERO | D1: CURSO | E1: PRUEBA | F1: NOMBRE_ALUMNO | G1: PERIODO | H1: MEDICION | I1: NOMBRE_CORTO | J1: POSICION_TABLA_BAREMO | K1: BAREMO
A2: {=IF(D2="","",IFERROR(INDEX(CONFIGURACION!C:C,MATCH(D2,CONFIGURACION!E:E,0)),""))} -> BCH | B2: {=IF(D2="","",IFERROR(INDEX(CONFIGURACION!D:D,MATCH(D2,CONFIGURACION!E:E,0)),""))} -> 1 | C2: MASCULINO | D2: B1 | E2: COOPER | F2: Manolo Díaz Camacho | G2: 1 TRIMESTRE | H2: 1900 | I2: =IFERROR(__xludf.DUMMYFUNCTION("IF(F2="""","""",LET( nombre, TRIM(F2), primer, REGEXEXTRACT(nombre, ""^\S+""), resto, TRIM(REGEXREPLACE(nombre, ""^\S+\s*"", """")), iniciales, IF( resto="""", """", TEXTJOIN("""",1,ARRAYFORMULA(LEFT(SPLIT(resto,"" ""),1) & ""."")) )"&", UPPER(primer) & "" "" & UPPER(iniciales) ))"),"MANOLO D.C.") -> MANOLO D.C. | J2: =IFERROR(__xludf.DUMMYFUNCTION("IF(H2="""","""",IFERROR( IF(REGEXMATCH(E2,""VELOCIDAD""), IF(H2>=MAX(INDEX(BAREMOS!G:Y,MATCH(1,(BAREMOS!A:A=A2)*(BAREMOS!B:B=B2)*(BAREMOS!C:C=C2)*(BAREMOS!D:D=E2),0),0)),1, IF(H2<=MIN(INDEX(BAREMOS!G:Y,MATCH(1,(BAREMOS!A:A=A2)*(BAREMOS!B:B=B2)*(B"&"AREMOS!C:C=C2)*(BAREMOS!D:D=E2),0),0)),19, MATCH(H2,INDEX(BAREMOS!G:Y,MATCH(1,(BAREMOS!A:A=A2)*(BAREMOS!B:B=B2)*(BAREMOS!C:C=C2)*(BAREMOS!D:D=E2),0),0),-1) ) ), IF(H2<=MIN(INDEX(BAREMOS!G:Y,MATCH(1,(BAREMOS!A:A=A2)*(BAREMOS!B:B=B2)*(B"&"AREMOS!C:C=C2)*(BAREMOS!D:D=E2),0),0)),1, IF(H2>=MAX(INDEX(BAREMOS!G:Y,MATCH(1,(BAREMOS!A:A=A2)*(BAREMOS!B:B=B2)*(BAREMOS!C:C=C2)*(BAREMOS!D:D=E2),0),0)),19, MATCH(H2,INDEX(BAREMOS!G:Y,MATCH(1,(BAREMOS!A:A=A2)*(BAREMOS!B:B=B2)*(BAREMOS!C:C="&"C2)*(BAREMOS!D:D=E2),0),0),1) ) ) ) ,"""")) "),1.0) -> 1 | K2: =IF(J2="","",INDEX(SEQUENCE(1,19,1,0.5),1,J2)) -> 1
A3: {=IF(D3="","",IFERROR(INDEX(CONFIGURACION!C:C,MATCH(D3,CONFIGURACION!E:E,0)),""))} -> BCH | B3: {=IF(D3="","",IFERROR(INDEX(CONFIGURACION!D:D,MATCH(D3,CONFIGURACION!E:E,0)),""))} -> 1 | C3: MASCULINO | D3: B1 | E3: S. HORIZONTAL | F3: Manolo Díaz Camacho | G3: 1 TRIMESTRE | H3: 33 | I3: =IFERROR(__xludf.DUMMYFUNCTION("IF(F3="""","""",LET( nombre, TRIM(F3), primer, REGEXEXTRACT(nombre, ""^\S+""), resto, TRIM(REGEXREPLACE(nombre, ""^\S+\s*"", """")), iniciales, IF( resto="""", """", TEXTJOIN("""",1,ARRAYFORMULA(LEFT(SPLIT(resto,"" ""),1) & ""."")) )"&", UPPER(primer) & "" "" & UPPER(iniciales) ))"),"MANOLO D.C.") -> MANOLO D.C. | J3: =IFERROR(__xludf.DUMMYFUNCTION("IF(H3="""","""",IFERROR( IF(REGEXMATCH(E3,""VELOCIDAD""), IF(H3>=MAX(INDEX(BAREMOS!G:Y,MATCH(1,(BAREMOS!A:A=A3)*(BAREMOS!B:B=B3)*(BAREMOS!C:C=C3)*(BAREMOS!D:D=E3),0),0)),1, IF(H3<=MIN(INDEX(BAREMOS!G:Y,MATCH(1,(BAREMOS!A:A=A3)*(BAREMOS!B:B=B3)*(B"&"AREMOS!C:C=C3)*(BAREMOS!D:D=E3),0),0)),19, MATCH(H3,INDEX(BAREMOS!G:Y,MATCH(1,(BAREMOS!A:A=A3)*(BAREMOS!B:B=B3)*(BAREMOS!C:C=C3)*(BAREMOS!D:D=E3),0),0),-1) ) ), IF(H3<=MIN(INDEX(BAREMOS!G:Y,MATCH(1,(BAREMOS!A:A=A3)*(BAREMOS!B:B=B3)*(B"&"AREMOS!C:C=C3)*(BAREMOS!D:D=E3),0),0)),1, IF(H3>=MAX(INDEX(BAREMOS!G:Y,MATCH(1,(BAREMOS!A:A=A3)*(BAREMOS!B:B=B3)*(BAREMOS!C:C=C3)*(BAREMOS!D:D=E3),0),0)),19, MATCH(H3,INDEX(BAREMOS!G:Y,MATCH(1,(BAREMOS!A:A=A3)*(BAREMOS!B:B=B3)*(BAREMOS!C:C="&"C3)*(BAREMOS!D:D=E3),0),0),1) ) ) ) ,"""")) "),1.0) -> 1 | K3: =IF(J3="","",INDEX(SEQUENCE(1,19,1,0.5),1,J3)) -> 1
A4: {=IF(D4="","",IFERROR(INDEX(CONFIGURACION!C:C,MATCH(D4,CONFIGURACION!E:E,0)),""))} -> BCH | B4: {=IF(D4="","",IFERROR(INDEX(CONFIGURACION!D:D,MATCH(D4,CONFIGURACION!E:E,0)),""))} -> 1 | C4: MASCULINO | D4: B1 | E4: S. VERTICAL | F4: Manolo Díaz Camacho | G4: 1 TRIMESTRE | H4: 37 | I4: =IFERROR(__xludf.DUMMYFUNCTION("IF(F4="""","""",LET( nombre, TRIM(F4), primer, REGEXEXTRACT(nombre, ""^\S+""), resto, TRIM(REGEXREPLACE(nombre, ""^\S+\s*"", """")), iniciales, IF( resto="""", """", TEXTJOIN("""",1,ARRAYFORMULA(LEFT(SPLIT(resto,"" ""),1) & ""."")) )"&", UPPER(primer) & "" "" & UPPER(iniciales) ))"),"MANOLO D.C.") -> MANOLO D.C. | J4: =IFERROR(__xludf.DUMMYFUNCTION("IF(H4="""","""",IFERROR( IF(REGEXMATCH(E4,""VELOCIDAD""), IF(H4>=MAX(INDEX(BAREMOS!G:Y,MATCH(1,(BAREMOS!A:A=A4)*(BAREMOS!B:B=B4)*(BAREMOS!C:C=C4)*(BAREMOS!D:D=E4),0),0)),1, IF(H4<=MIN(INDEX(BAREMOS!G:Y,MATCH(1,(BAREMOS!A:A=A4)*(BAREMOS!B:B=B4)*(B"&"AREMOS!C:C=C4)*(BAREMOS!D:D=E4),0),0)),19, MATCH(H4,INDEX(BAREMOS!G:Y,MATCH(1,(BAREMOS!A:A=A4)*(BAREMOS!B:B=B4)*(BAREMOS!C:C=C4)*(BAREMOS!D:D=E4),0),0),-1) ) ), IF(H4<=MIN(INDEX(BAREMOS!G:Y,MATCH(1,(BAREMOS!A:A=A4)*(BAREMOS!B:B=B4)*(B"&"AREMOS!C:C=C4)*(BAREMOS!D:D=E4),0),0)),1, IF(H4>=MAX(INDEX(BAREMOS!G:Y,MATCH(1,(BAREMOS!A:A=A4)*(BAREMOS!B:B=B4)*(BAREMOS!C:C=C4)*(BAREMOS!D:D=E4),0),0)),19, MATCH(H4,INDEX(BAREMOS!G:Y,MATCH(1,(BAREMOS!A:A=A4)*(BAREMOS!B:B=B4)*(BAREMOS!C:C="&"C4)*(BAREMOS!D:D=E4),0),0),1) ) ) ) ,"""")) "),3.0) -> 3 | K4: =IF(J4="","",INDEX(SEQUENCE(1,19,1,0.5),1,J4)) -> 2
A5: {=IF(D5="","",IFERROR(INDEX(CONFIGURACION!C:C,MATCH(D5,CONFIGURACION!E:E,0)),""))} -> BCH | B5: {=IF(D5="","",IFERROR(INDEX(CONFIGURACION!D:D,MATCH(D5,CONFIGURACION!E:E,0)),""))} -> 1 | C5: MASCULINO | D5: B1 | E5: S. HORIZONTAL | F5: Manolo Díaz Camacho | G5: 1 TRIMESTRE | H5: 144 | I5: =IFERROR(__xludf.DUMMYFUNCTION("IF(F5="""","""",LET( nombre, TRIM(F5), primer, REGEXEXTRACT(nombre, ""^\S+""), resto, TRIM(REGEXREPLACE(nombre, ""^\S+\s*"", """")), iniciales, IF( resto="""", """", TEXTJOIN("""",1,ARRAYFORMULA(LEFT(SPLIT(resto,"" ""),1) & ""."")) )"&", UPPER(primer) & "" "" & UPPER(iniciales) ))"),"MANOLO D.C.") -> MANOLO D.C. | J5: =IFERROR(__xludf.DUMMYFUNCTION("IF(H5="""","""",IFERROR( IF(REGEXMATCH(E5,""VELOCIDAD""), IF(H5>=MAX(INDEX(BAREMOS!G:Y,MATCH(1,(BAREMOS!A:A=A5)*(BAREMOS!B:B=B5)*(BAREMOS!C:C=C5)*(BAREMOS!D:D=E5),0),0)),1, IF(H5<=MIN(INDEX(BAREMOS!G:Y,MATCH(1,(BAREMOS!A:A=A5)*(BAREMOS!B:B=B5)*(B"&"AREMOS!C:C=C5)*(BAREMOS!D:D=E5),0),0)),19, MATCH(H5,INDEX(BAREMOS!G:Y,MATCH(1,(BAREMOS!A:A=A5)*(BAREMOS!B:B=B5)*(BAREMOS!C:C=C5)*(BAREMOS!D:D=E5),0),0),-1) ) ), IF(H5<=MIN(INDEX(BAREMOS!G:Y,MATCH(1,(BAREMOS!A:A=A5)*(BAREMOS!B:B=B5)*(B"&"AREMOS!C:C=C5)*(BAREMOS!D:D=E5),0),0)),1, IF(H5>=MAX(INDEX(BAREMOS!G:Y,MATCH(1,(BAREMOS!A:A=A5)*(BAREMOS!B:B=B5)*(BAREMOS!C:C=C5)*(BAREMOS!D:D=E5),0),0)),19, MATCH(H5,INDEX(BAREMOS!G:Y,MATCH(1,(BAREMOS!A:A=A5)*(BAREMOS!B:B=B5)*(BAREMOS!C:C="&"C5)*(BAREMOS!D:D=E5),0),0),1) ) ) ) ,"""")) "),1.0) -> 1 | K5: =IF(J5="","",INDEX(SEQUENCE(1,19,1,0.5),1,J5)) -> 1
A6: {=IF(D6="","",IFERROR(INDEX(CONFIGURACION!C:C,MATCH(D6,CONFIGURACION!E:E,0)),""))} -> BCH | B6: {=IF(D6="","",IFERROR(INDEX(CONFIGURACION!D:D,MATCH(D6,CONFIGURACION!E:E,0)),""))} -> 1 | C6: MASCULINO | D6: B1 | E6: S. HORIZONTAL | F6: Manolo Díaz Camacho | G6: 1 TRIMESTRE | H6: 10 | I6: =IFERROR(__xludf.DUMMYFUNCTION("IF(F6="""","""",LET( nombre, TRIM(F6), primer, REGEXEXTRACT(nombre, ""^\S+""), resto, TRIM(REGEXREPLACE(nombre, ""^\S+\s*"", """")), iniciales, IF( resto="""", """", TEXTJOIN("""",1,ARRAYFORMULA(LEFT(SPLIT(resto,"" ""),1) & ""."")) )"&", UPPER(primer) & "" "" & UPPER(iniciales) ))"),"MANOLO D.C.") -> MANOLO D.C. | J6: =IFERROR(__xludf.DUMMYFUNCTION("IF(H6="""","""",IFERROR( IF(REGEXMATCH(E6,""VELOCIDAD""), IF(H6>=MAX(INDEX(BAREMOS!G:Y,MATCH(1,(BAREMOS!A:A=A6)*(BAREMOS!B:B=B6)*(BAREMOS!C:C=C6)*(BAREMOS!D:D=E6),0),0)),1, IF(H6<=MIN(INDEX(BAREMOS!G:Y,MATCH(1,(BAREMOS!A:A=A6)*(BAREMOS!B:B=B6)*(B"&"AREMOS!C:C=C6)*(BAREMOS!D:D=E6),0),0)),19, MATCH(H6,INDEX(BAREMOS!G:Y,MATCH(1,(BAREMOS!A:A=A6)*(BAREMOS!B:B=B6)*(BAREMOS!C:C=C6)*(BAREMOS!D:D=E6),0),0),-1) ) ), IF(H6<=MIN(INDEX(BAREMOS!G:Y,MATCH(1,(BAREMOS!A:A=A6)*(BAREMOS!B:B=B6)*(B"&"AREMOS!C:C=C6)*(BAREMOS!D:D=E6),0),0)),1, IF(H6>=MAX(INDEX(BAREMOS!G:Y,MATCH(1,(BAREMOS!A:A=A6)*(BAREMOS!B:B=B6)*(BAREMOS!C:C=C6)*(BAREMOS!D:D=E6),0),0)),19, MATCH(H6,INDEX(BAREMOS!G:Y,MATCH(1,(BAREMOS!A:A=A6)*(BAREMOS!B:B=B6)*(BAREMOS!C:C="&"C6)*(BAREMOS!D:D=E6),0),0),1) ) ) ) ,"""")) "),1.0) -> 1 | K6: =IF(J6="","",INDEX(SEQUENCE(1,19,1,0.5),1,J6)) -> 1
A7: {=IF(D7="","",IFERROR(INDEX(CONFIGURACION!C:C,MATCH(D7,CONFIGURACION!E:E,0)),""))} -> BCH | B7: {=IF(D7="","",IFERROR(INDEX(CONFIGURACION!D:D,MATCH(D7,CONFIGURACION!E:E,0)),""))} -> 1 | C7: MASCULINO | D7: B1 | E7: L. BALON | F7: Juan Carlos Huizar Moreno | G7: 1 TRIMESTRE | H7: 15 | I7: =IFERROR(__xludf.DUMMYFUNCTION("IF(F7="""","""",LET( nombre, TRIM(F7), primer, REGEXEXTRACT(nombre, ""^\S+""), resto, TRIM(REGEXREPLACE(nombre, ""^\S+\s*"", """")), iniciales, IF( resto="""", """", TEXTJOIN("""",1,ARRAYFORMULA(LEFT(SPLIT(resto,"" ""),1) & ""."")) )"&", UPPER(primer) & "" "" & UPPER(iniciales) ))"),"JUAN C.H.M.") -> JUAN C.H.M. | J7: =IFERROR(__xludf.DUMMYFUNCTION("IF(H7="""","""",IFERROR( IF(REGEXMATCH(E7,""VELOCIDAD""), IF(H7>=MAX(INDEX(BAREMOS!G:Y,MATCH(1,(BAREMOS!A:A=A7)*(BAREMOS!B:B=B7)*(BAREMOS!C:C=C7)*(BAREMOS!D:D=E7),0),0)),1, IF(H7<=MIN(INDEX(BAREMOS!G:Y,MATCH(1,(BAREMOS!A:A=A7)*(BAREMOS!B:B=B7)*(B"&"AREMOS!C:C=C7)*(BAREMOS!D:D=E7),0),0)),19, MATCH(H7,INDEX(BAREMOS!G:Y,MATCH(1,(BAREMOS!A:A=A7)*(BAREMOS!B:B=B7)*(BAREMOS!C:C=C7)*(BAREMOS!D:D=E7),0),0),-1) ) ), IF(H7<=MIN(INDEX(BAREMOS!G:Y,MATCH(1,(BAREMOS!A:A=A7)*(BAREMOS!B:B=B7)*(B"&"AREMOS!C:C=C7)*(BAREMOS!D:D=E7),0),0)),1, IF(H7>=MAX(INDEX(BAREMOS!G:Y,MATCH(1,(BAREMOS!A:A=A7)*(BAREMOS!B:B=B7)*(BAREMOS!C:C=C7)*(BAREMOS!D:D=E7),0),0)),19, MATCH(H7,INDEX(BAREMOS!G:Y,MATCH(1,(BAREMOS!A:A=A7)*(BAREMOS!B:B=B7)*(BAREMOS!C:C="&"C7)*(BAREMOS!D:D=E7),0),0),1) ) ) ) ,"""")) "),11.0) -> 11 | K7: =IF(J7="","",INDEX(SEQUENCE(1,19,1,0.5),1,J7)) -> 6
A8: {=IF(D8="","",IFERROR(INDEX(CONFIGURACION!C:C,MATCH(D8,CONFIGURACION!E:E,0)),""))} -> BCH | B8: {=IF(D8="","",IFERROR(INDEX(CONFIGURACION!D:D,MATCH(D8,CONFIGURACION!E:E,0)),""))} -> 1 | C8: MASCULINO | D8: B1 | E8: ABDOMINALES | F8: Juan Carlos Huizar Moreno | G8: 1 TRIMESTRE | H8: 20 | I8: =IFERROR(__xludf.DUMMYFUNCTION("IF(F8="""","""",LET( nombre, TRIM(F8), primer, REGEXEXTRACT(nombre, ""^\S+""), resto, TRIM(REGEXREPLACE(nombre, ""^\S+\s*"", """")), iniciales, IF( resto="""", """", TEXTJOIN("""",1,ARRAYFORMULA(LEFT(SPLIT(resto,"" ""),1) & ""."")) )"&", UPPER(primer) & "" "" & UPPER(iniciales) ))"),"JUAN C.H.M.") -> JUAN C.H.M. | J8: =IFERROR(__xludf.DUMMYFUNCTION("IF(H8="""","""",IFERROR( IF(REGEXMATCH(E8,""VELOCIDAD""), IF(H8>=MAX(INDEX(BAREMOS!G:Y,MATCH(1,(BAREMOS!A:A=A8)*(BAREMOS!B:B=B8)*(BAREMOS!C:C=C8)*(BAREMOS!D:D=E8),0),0)),1, IF(H8<=MIN(INDEX(BAREMOS!G:Y,MATCH(1,(BAREMOS!A:A=A8)*(BAREMOS!B:B=B8)*(B"&"AREMOS!C:C=C8)*(BAREMOS!D:D=E8),0),0)),19, MATCH(H8,INDEX(BAREMOS!G:Y,MATCH(1,(BAREMOS!A:A=A8)*(BAREMOS!B:B=B8)*(BAREMOS!C:C=C8)*(BAREMOS!D:D=E8),0),0),-1) ) ), IF(H8<=MIN(INDEX(BAREMOS!G:Y,MATCH(1,(BAREMOS!A:A=A8)*(BAREMOS!B:B=B8)*(B"&"AREMOS!C:C=C8)*(BAREMOS!D:D=E8),0),0)),1, IF(H8>=MAX(INDEX(BAREMOS!G:Y,MATCH(1,(BAREMOS!A:A=A8)*(BAREMOS!B:B=B8)*(BAREMOS!C:C=C8)*(BAREMOS!D:D=E8),0),0)),19, MATCH(H8,INDEX(BAREMOS!G:Y,MATCH(1,(BAREMOS!A:A=A8)*(BAREMOS!B:B=B8)*(BAREMOS!C:C="&"C8)*(BAREMOS!D:D=E8),0),0),1) ) ) ) ,"""")) "),6.0) -> 6 | K8: =IF(J8="","",INDEX(SEQUENCE(1,19,1,0.5),1,J8)) -> 3.5
A9: {=IF(D9="","",IFERROR(INDEX(CONFIGURACION!C:C,MATCH(D9,CONFIGURACION!E:E,0)),""))} -> BCH | B9: {=IF(D9="","",IFERROR(INDEX(CONFIGURACION!D:D,MATCH(D9,CONFIGURACION!E:E,0)),""))} -> 1 | C9: MASCULINO | D9: B1 | E9: FLEXIBILIDAD | F9: Juan Carlos Huizar Moreno | G9: 1 TRIMESTRE | H9: 25 | I9: =IFERROR(__xludf.DUMMYFUNCTION("IF(F9="""","""",LET( nombre, TRIM(F9), primer, REGEXEXTRACT(nombre, ""^\S+""), resto, TRIM(REGEXREPLACE(nombre, ""^\S+\s*"", """")), iniciales, IF( resto="""", """", TEXTJOIN("""",1,ARRAYFORMULA(LEFT(SPLIT(resto,"" ""),1) & ""."")) )"&", UPPER(primer) & "" "" & UPPER(iniciales) ))"),"JUAN C.H.M.") -> JUAN C.H.M. | J9: =IFERROR(__xludf.DUMMYFUNCTION("IF(H9="""","""",IFERROR( IF(REGEXMATCH(E9,""VELOCIDAD""), IF(H9>=MAX(INDEX(BAREMOS!G:Y,MATCH(1,(BAREMOS!A:A=A9)*(BAREMOS!B:B=B9)*(BAREMOS!C:C=C9)*(BAREMOS!D:D=E9),0),0)),1, IF(H9<=MIN(INDEX(BAREMOS!G:Y,MATCH(1,(BAREMOS!A:A=A9)*(BAREMOS!B:B=B9)*(B"&"AREMOS!C:C=C9)*(BAREMOS!D:D=E9),0),0)),19, MATCH(H9,INDEX(BAREMOS!G:Y,MATCH(1,(BAREMOS!A:A=A9)*(BAREMOS!B:B=B9)*(BAREMOS!C:C=C9)*(BAREMOS!D:D=E9),0),0),-1) ) ), IF(H9<=MIN(INDEX(BAREMOS!G:Y,MATCH(1,(BAREMOS!A:A=A9)*(BAREMOS!B:B=B9)*(B"&"AREMOS!C:C=C9)*(BAREMOS!D:D=E9),0),0)),1, IF(H9>=MAX(INDEX(BAREMOS!G:Y,MATCH(1,(BAREMOS!A:A=A9)*(BAREMOS!B:B=B9)*(BAREMOS!C:C=C9)*(BAREMOS!D:D=E9),0),0)),19, MATCH(H9,INDEX(BAREMOS!G:Y,MATCH(1,(BAREMOS!A:A=A9)*(BAREMOS!B:B=B9)*(BAREMOS!C:C="&"C9)*(BAREMOS!D:D=E9),0),0),1) ) ) ) ,"""")) "),1.0) -> 1 | K9: =IF(J9="","",INDEX(SEQUENCE(1,19,1,0.5),1,J9)) -> 1
A10: {=IF(D10="","",IFERROR(INDEX(CONFIGURACION!C:C,MATCH(D10,CONFIGURACION!E:E,0)),""))} -> BCH | B10: {=IF(D10="","",IFERROR(INDEX(CONFIGURACION!D:D,MATCH(D10,CONFIGURACION!E:E,0)),""))} -> 1 | C10: MASCULINO | D10: B1 | E10: S. VERTICAL | F10: Juan Carlos Huizar Moreno | G10: 1 TRIMESTRE | H10: 30 | I10: =IFERROR(__xludf.DUMMYFUNCTION("IF(F10="""","""",LET( nombre, TRIM(F10), primer, REGEXEXTRACT(nombre, ""^\S+""), resto, TRIM(REGEXREPLACE(nombre, ""^\S+\s*"", """")), iniciales, IF( resto="""", """", TEXTJOIN("""",1,ARRAYFORMULA(LEFT(SPLIT(resto,"" ""),1) & ""."")) "&" ), UPPER(primer) & "" "" & UPPER(iniciales) ))"),"JUAN C.H.M.") -> JUAN C.H.M. | J10: =IFERROR(__xludf.DUMMYFUNCTION("IF(H10="""","""",IFERROR( IF(REGEXMATCH(E10,""VELOCIDAD""), IF(H10>=MAX(INDEX(BAREMOS!G:Y,MATCH(1,(BAREMOS!A:A=A10)*(BAREMOS!B:B=B10)*(BAREMOS!C:C=C10)*(BAREMOS!D:D=E10),0),0)),1, IF(H10<=MIN(INDEX(BAREMOS!G:Y,MATCH(1,(BAREMOS!A:A=A10)*(BAREMOS!B"&":B=B10)*(BAREMOS!C:C=C10)*(BAREMOS!D:D=E10),0),0)),19, MATCH(H10,INDEX(BAREMOS!G:Y,MATCH(1,(BAREMOS!A:A=A10)*(BAREMOS!B:B=B10)*(BAREMOS!C:C=C10)*(BAREMOS!D:D=E10),0),0),-1) ) ), IF(H10<=MIN(INDEX(BAREMOS!G:Y,MATCH(1,(BAREMOS!A:A=A10)*"&"(BAREMOS!B:B=B10)*(BAREMOS!C:C=C10)*(BAREMOS!D:D=E10),0),0)),1, IF(H10>=MAX(INDEX(BAREMOS!G:Y,MATCH(1,(BAREMOS!A:A=A10)*(BAREMOS!B:B=B10)*(BAREMOS!C:C=C10)*(BAREMOS!D:D=E10),0),0)),19, MATCH(H10,INDEX(BAREMOS!G:Y,MATCH(1,(BAREMOS!A:A=A10)*("&"BAREMOS!B:B=B10)*(BAREMOS!C:C=C10)*(BAREMOS!D:D=E10),0),0),1) ) ) ) ,"""")) "),1.0) -> 1 | K10: =IF(J10="","",INDEX(SEQUENCE(1,19,1,0.5),1,J10)) -> 1
A11: {=IF(D11="","",IFERROR(INDEX(CONFIGURACION!C:C,MATCH(D11,CONFIGURACION!E:E,0)),""))} -> BCH | B11: {=IF(D11="","",IFERROR(INDEX(CONFIGURACION!D:D,MATCH(D11,CONFIGURACION!E:E,0)),""))} -> 1 | C11: MASCULINO | D11: B1 | E11: COOPER | F11: Juan Carlos Huizar Moreno | G11: 1 TRIMESTRE | H11: 35 | I11: =IFERROR(__xludf.DUMMYFUNCTION("IF(F11="""","""",LET( nombre, TRIM(F11), primer, REGEXEXTRACT(nombre, ""^\S+""), resto, TRIM(REGEXREPLACE(nombre, ""^\S+\s*"", """")), iniciales, IF( resto="""", """", TEXTJOIN("""",1,ARRAYFORMULA(LEFT(SPLIT(resto,"" ""),1) & ""."")) "&" ), UPPER(primer) & "" "" & UPPER(iniciales) ))"),"JUAN C.H.M.") -> JUAN C.H.M. | J11: =IFERROR(__xludf.DUMMYFUNCTION("IF(H11="""","""",IFERROR( IF(REGEXMATCH(E11,""VELOCIDAD""), IF(H11>=MAX(INDEX(BAREMOS!G:Y,MATCH(1,(BAREMOS!A:A=A11)*(BAREMOS!B:B=B11)*(BAREMOS!C:C=C11)*(BAREMOS!D:D=E11),0),0)),1, IF(H11<=MIN(INDEX(BAREMOS!G:Y,MATCH(1,(BAREMOS!A:A=A11)*(BAREMOS!B"&":B=B11)*(BAREMOS!C:C=C11)*(BAREMOS!D:D=E11),0),0)),19, MATCH(H11,INDEX(BAREMOS!G:Y,MATCH(1,(BAREMOS!A:A=A11)*(BAREMOS!B:B=B11)*(BAREMOS!C:C=C11)*(BAREMOS!D:D=E11),0),0),-1) ) ), IF(H11<=MIN(INDEX(BAREMOS!G:Y,MATCH(1,(BAREMOS!A:A=A11)*"&"(BAREMOS!B:B=B11)*(BAREMOS!C:C=C11)*(BAREMOS!D:D=E11),0),0)),1, IF(H11>=MAX(INDEX(BAREMOS!G:Y,MATCH(1,(BAREMOS!A:A=A11)*(BAREMOS!B:B=B11)*(BAREMOS!C:C=C11)*(BAREMOS!D:D=E11),0),0)),19, MATCH(H11,INDEX(BAREMOS!G:Y,MATCH(1,(BAREMOS!A:A=A11)*("&"BAREMOS!B:B=B11)*(BAREMOS!C:C=C11)*(BAREMOS!D:D=E11),0),0),1) ) ) ) ,"""")) "),1.0) -> 1 | K11: =IF(J11="","",INDEX(SEQUENCE(1,19,1,0.5),1,J11)) -> 1
A12: {=IF(D12="","",IFERROR(INDEX(CONFIGURACION!C:C,MATCH(D12,CONFIGURACION!E:E,0)),""))} -> BCH | B12: {=IF(D12="","",IFERROR(INDEX(CONFIGURACION!D:D,MATCH(D12,CONFIGURACION!E:E,0)),""))} -> 1 | C12: MASCULINO | D12: B1 | E12: VELOCIDAD | F12: Juan Carlos Huizar Moreno | G12: 1 TRIMESTRE | H12: 40 | I12: =IFERROR(__xludf.DUMMYFUNCTION("IF(F12="""","""",LET( nombre, TRIM(F12), primer, REGEXEXTRACT(nombre, ""^\S+""), resto, TRIM(REGEXREPLACE(nombre, ""^\S+\s*"", """")), iniciales, IF( resto="""", """", TEXTJOIN("""",1,ARRAYFORMULA(LEFT(SPLIT(resto,"" ""),1) & ""."")) "&" ), UPPER(primer) & "" "" & UPPER(iniciales) ))"),"JUAN C.H.M.") -> JUAN C.H.M. | J12: =IFERROR(__xludf.DUMMYFUNCTION("IF(H12="""","""",IFERROR( IF(REGEXMATCH(E12,""VELOCIDAD""), IF(H12>=MAX(INDEX(BAREMOS!G:Y,MATCH(1,(BAREMOS!A:A=A12)*(BAREMOS!B:B=B12)*(BAREMOS!C:C=C12)*(BAREMOS!D:D=E12),0),0)),1, IF(H12<=MIN(INDEX(BAREMOS!G:Y,MATCH(1,(BAREMOS!A:A=A12)*(BAREMOS!B"&":B=B12)*(BAREMOS!C:C=C12)*(BAREMOS!D:D=E12),0),0)),19, MATCH(H12,INDEX(BAREMOS!G:Y,MATCH(1,(BAREMOS!A:A=A12)*(BAREMOS!B:B=B12)*(BAREMOS!C:C=C12)*(BAREMOS!D:D=E12),0),0),-1) ) ), IF(H12<=MIN(INDEX(BAREMOS!G:Y,MATCH(1,(BAREMOS!A:A=A12)*"&"(BAREMOS!B:B=B12)*(BAREMOS!C:C=C12)*(BAREMOS!D:D=E12),0),0)),1, IF(H12>=MAX(INDEX(BAREMOS!G:Y,MATCH(1,(BAREMOS!A:A=A12)*(BAREMOS!B:B=B12)*(BAREMOS!C:C=C12)*(BAREMOS!D:D=E12),0),0)),19, MATCH(H12,INDEX(BAREMOS!G:Y,MATCH(1,(BAREMOS!A:A=A12)*("&"BAREMOS!B:B=B12)*(BAREMOS!C:C=C12)*(BAREMOS!D:D=E12),0),0),1) ) ) ) ,"""")) "),19.0) -> 19 | K12: =IF(J12="","",INDEX(SEQUENCE(1,19,1,0.5),1,J12)) -> 10
A13: {=IF(D13="","",IFERROR(INDEX(CONFIGURACION!C:C,MATCH(D13,CONFIGURACION!E:E,0)),""))} -> BCH | B13: {=IF(D13="","",IFERROR(INDEX(CONFIGURACION!D:D,MATCH(D13,CONFIGURACION!E:E,0)),""))} -> 1 | C13: MASCULINO | D13: B1 | E13: INTESIDAD FISICA | F13: Juan Carlos Huizar Moreno | G13: 1 TRIMESTRE | H13: 45 | I13: =IFERROR(__xludf.DUMMYFUNCTION("IF(F13="""","""",LET( nombre, TRIM(F13), primer, REGEXEXTRACT(nombre, ""^\S+""), resto, TRIM(REGEXREPLACE(nombre, ""^\S+\s*"", """")), iniciales, IF( resto="""", """", TEXTJOIN("""",1,ARRAYFORMULA(LEFT(SPLIT(resto,"" ""),1) & ""."")) "&" ), UPPER(primer) & "" "" & UPPER(iniciales) ))"),"JUAN C.H.M.") -> JUAN C.H.M. | J13: =IFERROR(__xludf.DUMMYFUNCTION("IF(H13="""","""",IFERROR( IF(REGEXMATCH(E13,""VELOCIDAD""), IF(H13>=MAX(INDEX(BAREMOS!G:Y,MATCH(1,(BAREMOS!A:A=A13)*(BAREMOS!B:B=B13)*(BAREMOS!C:C=C13)*(BAREMOS!D:D=E13),0),0)),1, IF(H13<=MIN(INDEX(BAREMOS!G:Y,MATCH(1,(BAREMOS!A:A=A13)*(BAREMOS!B"&":B=B13)*(BAREMOS!C:C=C13)*(BAREMOS!D:D=E13),0),0)),19, MATCH(H13,INDEX(BAREMOS!G:Y,MATCH(1,(BAREMOS!A:A=A13)*(BAREMOS!B:B=B13)*(BAREMOS!C:C=C13)*(BAREMOS!D:D=E13),0),0),-1) ) ), IF(H13<=MIN(INDEX(BAREMOS!G:Y,MATCH(1,(BAREMOS!A:A=A13)*"&"(BAREMOS!B:B=B13)*(BAREMOS!C:C=C13)*(BAREMOS!D:D=E13),0),0)),1, IF(H13>=MAX(INDEX(BAREMOS!G:Y,MATCH(1,(BAREMOS!A:A=A13)*(BAREMOS!B:B=B13)*(BAREMOS!C:C=C13)*(BAREMOS!D:D=E13),0),0)),19, MATCH(H13,INDEX(BAREMOS!G:Y,MATCH(1,(BAREMOS!A:A=A13)*("&"BAREMOS!B:B=B13)*(BAREMOS!C:C=C13)*(BAREMOS!D:D=E13),0),0),1) ) ) ) ,"""")) "),"") | K13: =IF(J13="","",INDEX(SEQUENCE(1,19,1,0.5),1,J13))
A14: {=IF(D14="","",IFERROR(INDEX(CONFIGURACION!C:C,MATCH(D14,CONFIGURACION!E:E,0)),""))} -> BCH | B14: {=IF(D14="","",IFERROR(INDEX(CONFIGURACION!D:D,MATCH(D14,CONFIGURACION!E:E,0)),""))} -> 1 | C14: MASCULINO | D14: B1 | E14: S. HORIZONTAL | F14: Gerardo Huizar Castro | G14: 1 TRIMESTRE | H14: 1 | I14: =IFERROR(__xludf.DUMMYFUNCTION("IF(F14="""","""",LET( nombre, TRIM(F14), primer, REGEXEXTRACT(nombre, ""^\S+""), resto, TRIM(REGEXREPLACE(nombre, ""^\S+\s*"", """")), iniciales, IF( resto="""", """", TEXTJOIN("""",1,ARRAYFORMULA(LEFT(SPLIT(resto,"" ""),1) & ""."")) "&" ), UPPER(primer) & "" "" & UPPER(iniciales) ))"),"GERARDO H.C.") -> GERARDO H.C. | J14: =IFERROR(__xludf.DUMMYFUNCTION("IF(H14="""","""",IFERROR( IF(REGEXMATCH(E14,""VELOCIDAD""), IF(H14>=MAX(INDEX(BAREMOS!G:Y,MATCH(1,(BAREMOS!A:A=A14)*(BAREMOS!B:B=B14)*(BAREMOS!C:C=C14)*(BAREMOS!D:D=E14),0),0)),1, IF(H14<=MIN(INDEX(BAREMOS!G:Y,MATCH(1,(BAREMOS!A:A=A14)*(BAREMOS!B"&":B=B14)*(BAREMOS!C:C=C14)*(BAREMOS!D:D=E14),0),0)),19, MATCH(H14,INDEX(BAREMOS!G:Y,MATCH(1,(BAREMOS!A:A=A14)*(BAREMOS!B:B=B14)*(BAREMOS!C:C=C14)*(BAREMOS!D:D=E14),0),0),-1) ) ), IF(H14<=MIN(INDEX(BAREMOS!G:Y,MATCH(1,(BAREMOS!A:A=A14)*"&"(BAREMOS!B:B=B14)*(BAREMOS!C:C=C14)*(BAREMOS!D:D=E14),0),0)),1, IF(H14>=MAX(INDEX(BAREMOS!G:Y,MATCH(1,(BAREMOS!A:A=A14)*(BAREMOS!B:B=B14)*(BAREMOS!C:C=C14)*(BAREMOS!D:D=E14),0),0)),19, MATCH(H14,INDEX(BAREMOS!G:Y,MATCH(1,(BAREMOS!A:A=A14)*("&"BAREMOS!B:B=B14)*(BAREMOS!C:C=C14)*(BAREMOS!D:D=E14),0),0),1) ) ) ) ,"""")) "),1.0) -> 1 | K14: =IF(J14="","",INDEX(SEQUENCE(1,19,1,0.5),1,J14)) -> 1
A15: {=IF(D15="","",IFERROR(INDEX(CONFIGURACION!C:C,MATCH(D15,CONFIGURACION!E:E,0)),""))} -> BCH | B15: {=IF(D15="","",IFERROR(INDEX(CONFIGURACION!D:D,MATCH(D15,CONFIGURACION!E:E,0)),""))} -> 1 | C15: MASCULINO | D15: B1 | E15: L. BALON | F15: Gerardo Huizar Castro | G15: 1 TRIMESTRE | H15: 23 | I15: =IFERROR(__xludf.DUMMYFUNCTION("IF(F15="""","""",LET( nombre, TRIM(F15), primer, REGEXEXTRACT(nombre, ""^\S+""), resto, TRIM(REGEXREPLACE(nombre, ""^\S+\s*"", """")), iniciales, IF( resto="""", """", TEXTJOIN("""",1,ARRAYFORMULA(LEFT(SPLIT(resto,"" ""),1) & ""."")) "&" ), UPPER(primer) & "" "" & UPPER(iniciales) ))"),"GERARDO H.C.") -> GERARDO H.C. | J15: =IFERROR(__xludf.DUMMYFUNCTION("IF(H15="""","""",IFERROR( IF(REGEXMATCH(E15,""VELOCIDAD""), IF(H15>=MAX(INDEX(BAREMOS!G:Y,MATCH(1,(BAREMOS!A:A=A15)*(BAREMOS!B:B=B15)*(BAREMOS!C:C=C15)*(BAREMOS!D:D=E15),0),0)),1, IF(H15<=MIN(INDEX(BAREMOS!G:Y,MATCH(1,(BAREMOS!A:A=A15)*(BAREMOS!B"&":B=B15)*(BAREMOS!C:C=C15)*(BAREMOS!D:D=E15),0),0)),19, MATCH(H15,INDEX(BAREMOS!G:Y,MATCH(1,(BAREMOS!A:A=A15)*(BAREMOS!B:B=B15)*(BAREMOS!C:C=C15)*(BAREMOS!D:D=E15),0),0),-1) ) ), IF(H15<=MIN(INDEX(BAREMOS!G:Y,MATCH(1,(BAREMOS!A:A=A15)*"&"(BAREMOS!B:B=B15)*(BAREMOS!C:C=C15)*(BAREMOS!D:D=E15),0),0)),1, IF(H15>=MAX(INDEX(BAREMOS!G:Y,MATCH(1,(BAREMOS!A:A=A15)*(BAREMOS!B:B=B15)*(BAREMOS!C:C=C15)*(BAREMOS!D:D=E15),0),0)),19, MATCH(H15,INDEX(BAREMOS!G:Y,MATCH(1,(BAREMOS!A:A=A15)*("&"BAREMOS!B:B=B15)*(BAREMOS!C:C=C15)*(BAREMOS!D:D=E15),0),0),1) ) ) ) ,"""")) "),11.0) -> 11 | K15: =IF(J15="","",INDEX(SEQUENCE(1,19,1,0.5),1,J15)) -> 6
A16: {=IF(D16="","",IFERROR(INDEX(CONFIGURACION!C:C,MATCH(D16,CONFIGURACION!E:E,0)),""))} -> BCH | B16: {=IF(D16="","",IFERROR(INDEX(CONFIGURACION!D:D,MATCH(D16,CONFIGURACION!E:E,0)),""))} -> 1 | C16: MASCULINO | D16: B1 | E16: ABDOMINALES | F16: Gerardo Huizar Castro | G16: 1 TRIMESTRE | H16: 3 | I16: =IFERROR(__xludf.DUMMYFUNCTION("IF(F16="""","""",LET( nombre, TRIM(F16), primer, REGEXEXTRACT(nombre, ""^\S+""), resto, TRIM(REGEXREPLACE(nombre, ""^\S+\s*"", """")), iniciales, IF( resto="""", """", TEXTJOIN("""",1,ARRAYFORMULA(LEFT(SPLIT(resto,"" ""),1) & ""."")) "&" ), UPPER(primer) & "" "" & UPPER(iniciales) ))"),"GERARDO H.C.") -> GERARDO H.C. | J16: =IFERROR(__xludf.DUMMYFUNCTION("IF(H16="""","""",IFERROR( IF(REGEXMATCH(E16,""VELOCIDAD""), IF(H16>=MAX(INDEX(BAREMOS!G:Y,MATCH(1,(BAREMOS!A:A=A16)*(BAREMOS!B:B=B16)*(BAREMOS!C:C=C16)*(BAREMOS!D:D=E16),0),0)),1, IF(H16<=MIN(INDEX(BAREMOS!G:Y,MATCH(1,(BAREMOS!A:A=A16)*(BAREMOS!B"&":B=B16)*(BAREMOS!C:C=C16)*(BAREMOS!D:D=E16),0),0)),19, MATCH(H16,INDEX(BAREMOS!G:Y,MATCH(1,(BAREMOS!A:A=A16)*(BAREMOS!B:B=B16)*(BAREMOS!C:C=C16)*(BAREMOS!D:D=E16),0),0),-1) ) ), IF(H16<=MIN(INDEX(BAREMOS!G:Y,MATCH(1,(BAREMOS!A:A=A16)*"&"(BAREMOS!B:B=B16)*(BAREMOS!C:C=C16)*(BAREMOS!D:D=E16),0),0)),1, IF(H16>=MAX(INDEX(BAREMOS!G:Y,MATCH(1,(BAREMOS!A:A=A16)*(BAREMOS!B:B=B16)*(BAREMOS!C:C=C16)*(BAREMOS!D:D=E16),0),0)),19, MATCH(H16,INDEX(BAREMOS!G:Y,MATCH(1,(BAREMOS!A:A=A16)*("&"BAREMOS!B:B=B16)*(BAREMOS!C:C=C16)*(BAREMOS!D:D=E16),0),0),1) ) ) ) ,"""")) "),1.0) -> 1 | K16: =IF(J16="","",INDEX(SEQUENCE(1,19,1,0.5),1,J16)) -> 1
A17: {=IF(D17="","",IFERROR(INDEX(CONFIGURACION!C:C,MATCH(D17,CONFIGURACION!E:E,0)),""))} -> BCH | B17: {=IF(D17="","",IFERROR(INDEX(CONFIGURACION!D:D,MATCH(D17,CONFIGURACION!E:E,0)),""))} -> 1 | C17: MASCULINO | D17: B1 | E17: FLEXIBILIDAD | F17: Gerardo Huizar Castro | G17: 1 TRIMESTRE | H17: 4 | I17: =IFERROR(__xludf.DUMMYFUNCTION("IF(F17="""","""",LET( nombre, TRIM(F17), primer, REGEXEXTRACT(nombre, ""^\S+""), resto, TRIM(REGEXREPLACE(nombre, ""^\S+\s*"", """")), iniciales, IF( resto="""", """", TEXTJOIN("""",1,ARRAYFORMULA(LEFT(SPLIT(resto,"" ""),1) & ""."")) "&" ), UPPER(primer) & "" "" & UPPER(iniciales) ))"),"GERARDO H.C.") -> GERARDO H.C. | J17: =IFERROR(__xludf.DUMMYFUNCTION("IF(H17="""","""",IFERROR( IF(REGEXMATCH(E17,""VELOCIDAD""), IF(H17>=MAX(INDEX(BAREMOS!G:Y,MATCH(1,(BAREMOS!A:A=A17)*(BAREMOS!B:B=B17)*(BAREMOS!C:C=C17)*(BAREMOS!D:D=E17),0),0)),1, IF(H17<=MIN(INDEX(BAREMOS!G:Y,MATCH(1,(BAREMOS!A:A=A17)*(BAREMOS!B"&":B=B17)*(BAREMOS!C:C=C17)*(BAREMOS!D:D=E17),0),0)),19, MATCH(H17,INDEX(BAREMOS!G:Y,MATCH(1,(BAREMOS!A:A=A17)*(BAREMOS!B:B=B17)*(BAREMOS!C:C=C17)*(BAREMOS!D:D=E17),0),0),-1) ) ), IF(H17<=MIN(INDEX(BAREMOS!G:Y,MATCH(1,(BAREMOS!A:A=A17)*"&"(BAREMOS!B:B=B17)*(BAREMOS!C:C=C17)*(BAREMOS!D:D=E17),0),0)),1, IF(H17>=MAX(INDEX(BAREMOS!G:Y,MATCH(1,(BAREMOS!A:A=A17)*(BAREMOS!B:B=B17)*(BAREMOS!C:C=C17)*(BAREMOS!D:D=E17),0),0)),19, MATCH(H17,INDEX(BAREMOS!G:Y,MATCH(1,(BAREMOS!A:A=A17)*("&"BAREMOS!B:B=B17)*(BAREMOS!C:C=C17)*(BAREMOS!D:D=E17),0),0),1) ) ) ) ,"""")) "),1.0) -> 1 | K17: =IF(J17="","",INDEX(SEQUENCE(1,19,1,0.5),1,J17)) -> 1
A18: {=IF(D18="","",IFERROR(INDEX(CONFIGURACION!C:C,MATCH(D18,CONFIGURACION!E:E,0)),""))} -> BCH | B18: {=IF(D18="","",IFERROR(INDEX(CONFIGURACION!D:D,MATCH(D18,CONFIGURACION!E:E,0)),""))} -> 1 | C18: MASCULINO | D18: B1 | E18: S. VERTICAL | F18: Gerardo Huizar Castro | G18: 1 TRIMESTRE | H18: 5 | I18: =IFERROR(__xludf.DUMMYFUNCTION("IF(F18="""","""",LET( nombre, TRIM(F18), primer, REGEXEXTRACT(nombre, ""^\S+""), resto, TRIM(REGEXREPLACE(nombre, ""^\S+\s*"", """")), iniciales, IF( resto="""", """", TEXTJOIN("""",1,ARRAYFORMULA(LEFT(SPLIT(resto,"" ""),1) & ""."")) "&" ), UPPER(primer) & "" "" & UPPER(iniciales) ))"),"GERARDO H.C.") -> GERARDO H.C. | J18: =IFERROR(__xludf.DUMMYFUNCTION("IF(H18="""","""",IFERROR( IF(REGEXMATCH(E18,""VELOCIDAD""), IF(H18>=MAX(INDEX(BAREMOS!G:Y,MATCH(1,(BAREMOS!A:A=A18)*(BAREMOS!B:B=B18)*(BAREMOS!C:C=C18)*(BAREMOS!D:D=E18),0),0)),1, IF(H18<=MIN(INDEX(BAREMOS!G:Y,MATCH(1,(BAREMOS!A:A=A18)*(BAREMOS!B"&":B=B18)*(BAREMOS!C:C=C18)*(BAREMOS!D:D=E18),0),0)),19, MATCH(H18,INDEX(BAREMOS!G:Y,MATCH(1,(BAREMOS!A:A=A18)*(BAREMOS!B:B=B18)*(BAREMOS!C:C=C18)*(BAREMOS!D:D=E18),0),0),-1) ) ), IF(H18<=MIN(INDEX(BAREMOS!G:Y,MATCH(1,(BAREMOS!A:A=A18)*"&"(BAREMOS!B:B=B18)*(BAREMOS!C:C=C18)*(BAREMOS!D:D=E18),0),0)),1, IF(H18>=MAX(INDEX(BAREMOS!G:Y,MATCH(1,(BAREMOS!A:A=A18)*(BAREMOS!B:B=B18)*(BAREMOS!C:C=C18)*(BAREMOS!D:D=E18),0),0)),19, MATCH(H18,INDEX(BAREMOS!G:Y,MATCH(1,(BAREMOS!A:A=A18)*("&"BAREMOS!B:B=B18)*(BAREMOS!C:C=C18)*(BAREMOS!D:D=E18),0),0),1) ) ) ) ,"""")) "),1.0) -> 1 | K18: =IF(J18="","",INDEX(SEQUENCE(1,19,1,0.5),1,J18)) -> 1
A19: {=IF(D19="","",IFERROR(INDEX(CONFIGURACION!C:C,MATCH(D19,CONFIGURACION!E:E,0)),""))} -> BCH | B19: {=IF(D19="","",IFERROR(INDEX(CONFIGURACION!D:D,MATCH(D19,CONFIGURACION!E:E,0)),""))} -> 1 | C19: MASCULINO | D19: B1 | E19: COOPER | F19: Gerardo Huizar Castro | G19: 1 TRIMESTRE | H19: 6 | I19: =IFERROR(__xludf.DUMMYFUNCTION("IF(F19="""","""",LET( nombre, TRIM(F19), primer, REGEXEXTRACT(nombre, ""^\S+""), resto, TRIM(REGEXREPLACE(nombre, ""^\S+\s*"", """")), iniciales, IF( resto="""", """", TEXTJOIN("""",1,ARRAYFORMULA(LEFT(SPLIT(resto,"" ""),1) & ""."")) "&" ), UPPER(primer) & "" "" & UPPER(iniciales) ))"),"GERARDO H.C.") -> GERARDO H.C. | J19: =IFERROR(__xludf.DUMMYFUNCTION("IF(H19="""","""",IFERROR( IF(REGEXMATCH(E19,""VELOCIDAD""), IF(H19>=MAX(INDEX(BAREMOS!G:Y,MATCH(1,(BAREMOS!A:A=A19)*(BAREMOS!B:B=B19)*(BAREMOS!C:C=C19)*(BAREMOS!D:D=E19),0),0)),1, IF(H19<=MIN(INDEX(BAREMOS!G:Y,MATCH(1,(BAREMOS!A:A=A19)*(BAREMOS!B"&":B=B19)*(BAREMOS!C:C=C19)*(BAREMOS!D:D=E19),0),0)),19, MATCH(H19,INDEX(BAREMOS!G:Y,MATCH(1,(BAREMOS!A:A=A19)*(BAREMOS!B:B=B19)*(BAREMOS!C:C=C19)*(BAREMOS!D:D=E19),0),0),-1) ) ), IF(H19<=MIN(INDEX(BAREMOS!G:Y,MATCH(1,(BAREMOS!A:A=A19)*"&"(BAREMOS!B:B=B19)*(BAREMOS!C:C=C19)*(BAREMOS!D:D=E19),0),0)),1, IF(H19>=MAX(INDEX(BAREMOS!G:Y,MATCH(1,(BAREMOS!A:A=A19)*(BAREMOS!B:B=B19)*(BAREMOS!C:C=C19)*(BAREMOS!D:D=E19),0),0)),19, MATCH(H19,INDEX(BAREMOS!G:Y,MATCH(1,(BAREMOS!A:A=A19)*("&"BAREMOS!B:B=B19)*(BAREMOS!C:C=C19)*(BAREMOS!D:D=E19),0),0),1) ) ) ) ,"""")) "),1.0) -> 1 | K19: =IF(J19="","",INDEX(SEQUENCE(1,19,1,0.5),1,J19)) -> 1
A20: {=IF(D20="","",IFERROR(INDEX(CONFIGURACION!C:C,MATCH(D20,CONFIGURACION!E:E,0)),""))} -> BCH | B20: {=IF(D20="","",IFERROR(INDEX(CONFIGURACION!D:D,MATCH(D20,CONFIGURACION!E:E,0)),""))} -> 1 | C20: MASCULINO | D20: B1 | E20: VELOCIDAD | F20: Gerardo Huizar Castro | G20: 1 TRIMESTRE | H20: 7 | I20: =IFERROR(__xludf.DUMMYFUNCTION("IF(F20="""","""",LET( nombre, TRIM(F20), primer, REGEXEXTRACT(nombre, ""^\S+""), resto, TRIM(REGEXREPLACE(nombre, ""^\S+\s*"", """")), iniciales, IF( resto="""", """", TEXTJOIN("""",1,ARRAYFORMULA(LEFT(SPLIT(resto,"" ""),1) & ""."")) "&" ), UPPER(primer) & "" "" & UPPER(iniciales) ))"),"GERARDO H.C.") -> GERARDO H.C. | J20: =IFERROR(__xludf.DUMMYFUNCTION("IF(H20="""","""",IFERROR( IF(REGEXMATCH(E20,""VELOCIDAD""), IF(H20>=MAX(INDEX(BAREMOS!G:Y,MATCH(1,(BAREMOS!A:A=A20)*(BAREMOS!B:B=B20)*(BAREMOS!C:C=C20)*(BAREMOS!D:D=E20),0),0)),1, IF(H20<=MIN(INDEX(BAREMOS!G:Y,MATCH(1,(BAREMOS!A:A=A20)*(BAREMOS!B"&":B=B20)*(BAREMOS!C:C=C20)*(BAREMOS!D:D=E20),0),0)),19, MATCH(H20,INDEX(BAREMOS!G:Y,MATCH(1,(BAREMOS!A:A=A20)*(BAREMOS!B:B=B20)*(BAREMOS!C:C=C20)*(BAREMOS!D:D=E20),0),0),-1) ) ), IF(H20<=MIN(INDEX(BAREMOS!G:Y,MATCH(1,(BAREMOS!A:A=A20)*"&"(BAREMOS!B:B=B20)*(BAREMOS!C:C=C20)*(BAREMOS!D:D=E20),0),0)),1, IF(H20>=MAX(INDEX(BAREMOS!G:Y,MATCH(1,(BAREMOS!A:A=A20)*(BAREMOS!B:B=B20)*(BAREMOS!C:C=C20)*(BAREMOS!D:D=E20),0),0)),19, MATCH(H20,INDEX(BAREMOS!G:Y,MATCH(1,(BAREMOS!A:A=A20)*("&"BAREMOS!B:B=B20)*(BAREMOS!C:C=C20)*(BAREMOS!D:D=E20),0),0),1) ) ) ) ,"""")) "),19.0) -> 19 | K20: =IF(J20="","",INDEX(SEQUENCE(1,19,1,0.5),1,J20)) -> 10
A21: {=IF(D21="","",IFERROR(INDEX(CONFIGURACION!C:C,MATCH(D21,CONFIGURACION!E:E,0)),""))} -> BCH | B21: {=IF(D21="","",IFERROR(INDEX(CONFIGURACION!D:D,MATCH(D21,CONFIGURACION!E:E,0)),""))} -> 1 | C21: MASCULINO | D21: B1 | E21: INTESIDAD FISICA | F21: Gerardo Huizar Castro | G21: 1 TRIMESTRE | H21: 8 | I21: =IFERROR(__xludf.DUMMYFUNCTION("IF(F21="""","""",LET( nombre, TRIM(F21), primer, REGEXEXTRACT(nombre, ""^\S+""), resto, TRIM(REGEXREPLACE(nombre, ""^\S+\s*"", """")), iniciales, IF( resto="""", """", TEXTJOIN("""",1,ARRAYFORMULA(LEFT(SPLIT(resto,"" ""),1) & ""."")) "&" ), UPPER(primer) & "" "" & UPPER(iniciales) ))"),"GERARDO H.C.") -> GERARDO H.C. | J21: =IFERROR(__xludf.DUMMYFUNCTION("IF(H21="""","""",IFERROR( IF(REGEXMATCH(E21,""VELOCIDAD""), IF(H21>=MAX(INDEX(BAREMOS!G:Y,MATCH(1,(BAREMOS!A:A=A21)*(BAREMOS!B:B=B21)*(BAREMOS!C:C=C21)*(BAREMOS!D:D=E21),0),0)),1, IF(H21<=MIN(INDEX(BAREMOS!G:Y,MATCH(1,(BAREMOS!A:A=A21)*(BAREMOS!B"&":B=B21)*(BAREMOS!C:C=C21)*(BAREMOS!D:D=E21),0),0)),19, MATCH(H21,INDEX(BAREMOS!G:Y,MATCH(1,(BAREMOS!A:A=A21)*(BAREMOS!B:B=B21)*(BAREMOS!C:C=C21)*(BAREMOS!D:D=E21),0),0),-1) ) ), IF(H21<=MIN(INDEX(BAREMOS!G:Y,MATCH(1,(BAREMOS!A:A=A21)*"&"(BAREMOS!B:B=B21)*(BAREMOS!C:C=C21)*(BAREMOS!D:D=E21),0),0)),1, IF(H21>=MAX(INDEX(BAREMOS!G:Y,MATCH(1,(BAREMOS!A:A=A21)*(BAREMOS!B:B=B21)*(BAREMOS!C:C=C21)*(BAREMOS!D:D=E21),0),0)),19, MATCH(H21,INDEX(BAREMOS!G:Y,MATCH(1,(BAREMOS!A:A=A21)*("&"BAREMOS!B:B=B21)*(BAREMOS!C:C=C21)*(BAREMOS!D:D=E21),0),0),1) ) ) ) ,"""")) "),"") | K21: =IF(J21="","",INDEX(SEQUENCE(1,19,1,0.5),1,J21))
A22: {=IF(D22="","",IFERROR(INDEX(CONFIGURACION!C:C,MATCH(D22,CONFIGURACION!E:E,0)),""))} -> BCH | B22: {=IF(D22="","",IFERROR(INDEX(CONFIGURACION!D:D,MATCH(D22,CONFIGURACION!E:E,0)),""))} -> 1 | C22: MASCULINO | D22: B1 | E22: S. HORIZONTAL | F22: Juan Carlos Huizar Moreno | G22: 2 TRIMESTRE | H22: 10 | I22: =IFERROR(__xludf.DUMMYFUNCTION("IF(F22="""","""",LET( nombre, TRIM(F22), primer, REGEXEXTRACT(nombre, ""^\S+""), resto, TRIM(REGEXREPLACE(nombre, ""^\S+\s*"", """")), iniciales, IF( resto="""", """", TEXTJOIN("""",1,ARRAYFORMULA(LEFT(SPLIT(resto,"" ""),1) & ""."")) "&" ), UPPER(primer) & "" "" & UPPER(iniciales) ))"),"JUAN C.H.M.") -> JUAN C.H.M. | J22: =IFERROR(__xludf.DUMMYFUNCTION("IF(H22="""","""",IFERROR( IF(REGEXMATCH(E22,""VELOCIDAD""), IF(H22>=MAX(INDEX(BAREMOS!G:Y,MATCH(1,(BAREMOS!A:A=A22)*(BAREMOS!B:B=B22)*(BAREMOS!C:C=C22)*(BAREMOS!D:D=E22),0),0)),1, IF(H22<=MIN(INDEX(BAREMOS!G:Y,MATCH(1,(BAREMOS!A:A=A22)*(BAREMOS!B"&":B=B22)*(BAREMOS!C:C=C22)*(BAREMOS!D:D=E22),0),0)),19, MATCH(H22,INDEX(BAREMOS!G:Y,MATCH(1,(BAREMOS!A:A=A22)*(BAREMOS!B:B=B22)*(BAREMOS!C:C=C22)*(BAREMOS!D:D=E22),0),0),-1) ) ), IF(H22<=MIN(INDEX(BAREMOS!G:Y,MATCH(1,(BAREMOS!A:A=A22)*"&"(BAREMOS!B:B=B22)*(BAREMOS!C:C=C22)*(BAREMOS!D:D=E22),0),0)),1, IF(H22>=MAX(INDEX(BAREMOS!G:Y,MATCH(1,(BAREMOS!A:A=A22)*(BAREMOS!B:B=B22)*(BAREMOS!C:C=C22)*(BAREMOS!D:D=E22),0),0)),19, MATCH(H22,INDEX(BAREMOS!G:Y,MATCH(1,(BAREMOS!A:A=A22)*("&"BAREMOS!B:B=B22)*(BAREMOS!C:C=C22)*(BAREMOS!D:D=E22),0),0),1) ) ) ) ,"""")) "),1.0) -> 1 | K22: =IF(J22="","",INDEX(SEQUENCE(1,19,1,0.5),1,J22)) -> 1
A23: {=IF(D23="","",IFERROR(INDEX(CONFIGURACION!C:C,MATCH(D23,CONFIGURACION!E:E,0)),""))} -> BCH | B23: {=IF(D23="","",IFERROR(INDEX(CONFIGURACION!D:D,MATCH(D23,CONFIGURACION!E:E,0)),""))} -> 1 | C23: MASCULINO | D23: B1 | E23: L. BALON | F23: Juan Carlos Huizar Moreno | G23: 2 TRIMESTRE | H23: 11 | I23: =IFERROR(__xludf.DUMMYFUNCTION("IF(F23="""","""",LET( nombre, TRIM(F23), primer, REGEXEXTRACT(nombre, ""^\S+""), resto, TRIM(REGEXREPLACE(nombre, ""^\S+\s*"", """")), iniciales, IF( resto="""", """", TEXTJOIN("""",1,ARRAYFORMULA(LEFT(SPLIT(resto,"" ""),1) & ""."")) "&" ), UPPER(primer) & "" "" & UPPER(iniciales) ))"),"JUAN C.H.M.") -> JUAN C.H.M. | J23: =IFERROR(__xludf.DUMMYFUNCTION("IF(H23="""","""",IFERROR( IF(REGEXMATCH(E23,""VELOCIDAD""), IF(H23>=MAX(INDEX(BAREMOS!G:Y,MATCH(1,(BAREMOS!A:A=A23)*(BAREMOS!B:B=B23)*(BAREMOS!C:C=C23)*(BAREMOS!D:D=E23),0),0)),1, IF(H23<=MIN(INDEX(BAREMOS!G:Y,MATCH(1,(BAREMOS!A:A=A23)*(BAREMOS!B"&":B=B23)*(BAREMOS!C:C=C23)*(BAREMOS!D:D=E23),0),0)),19, MATCH(H23,INDEX(BAREMOS!G:Y,MATCH(1,(BAREMOS!A:A=A23)*(BAREMOS!B:B=B23)*(BAREMOS!C:C=C23)*(BAREMOS!D:D=E23),0),0),-1) ) ), IF(H23<=MIN(INDEX(BAREMOS!G:Y,MATCH(1,(BAREMOS!A:A=A23)*"&"(BAREMOS!B:B=B23)*(BAREMOS!C:C=C23)*(BAREMOS!D:D=E23),0),0)),1, IF(H23>=MAX(INDEX(BAREMOS!G:Y,MATCH(1,(BAREMOS!A:A=A23)*(BAREMOS!B:B=B23)*(BAREMOS!C:C=C23)*(BAREMOS!D:D=E23),0),0)),19, MATCH(H23,INDEX(BAREMOS!G:Y,MATCH(1,(BAREMOS!A:A=A23)*("&"BAREMOS!B:B=B23)*(BAREMOS!C:C=C23)*(BAREMOS!D:D=E23),0),0),1) ) ) ) ,"""")) "),11.0) -> 11 | K23: =IF(J23="","",INDEX(SEQUENCE(1,19,1,0.5),1,J23)) -> 6
A24: {=IF(D24="","",IFERROR(INDEX(CONFIGURACION!C:C,MATCH(D24,CONFIGURACION!E:E,0)),""))} -> BCH | B24: {=IF(D24="","",IFERROR(INDEX(CONFIGURACION!D:D,MATCH(D24,CONFIGURACION!E:E,0)),""))} -> 1 | C24: MASCULINO | D24: B1 | E24: ABDOMINALES | F24: Juan Carlos Huizar Moreno | G24: 2 TRIMESTRE | H24: 12 | I24: =IFERROR(__xludf.DUMMYFUNCTION("IF(F24="""","""",LET( nombre, TRIM(F24), primer, REGEXEXTRACT(nombre, ""^\S+""), resto, TRIM(REGEXREPLACE(nombre, ""^\S+\s*"", """")), iniciales, IF( resto="""", """", TEXTJOIN("""",1,ARRAYFORMULA(LEFT(SPLIT(resto,"" ""),1) & ""."")) "&" ), UPPER(primer) & "" "" & UPPER(iniciales) ))"),"JUAN C.H.M.") -> JUAN C.H.M. | J24: =IFERROR(__xludf.DUMMYFUNCTION("IF(H24="""","""",IFERROR( IF(REGEXMATCH(E24,""VELOCIDAD""), IF(H24>=MAX(INDEX(BAREMOS!G:Y,MATCH(1,(BAREMOS!A:A=A24)*(BAREMOS!B:B=B24)*(BAREMOS!C:C=C24)*(BAREMOS!D:D=E24),0),0)),1, IF(H24<=MIN(INDEX(BAREMOS!G:Y,MATCH(1,(BAREMOS!A:A=A24)*(BAREMOS!B"&":B=B24)*(BAREMOS!C:C=C24)*(BAREMOS!D:D=E24),0),0)),19, MATCH(H24,INDEX(BAREMOS!G:Y,MATCH(1,(BAREMOS!A:A=A24)*(BAREMOS!B:B=B24)*(BAREMOS!C:C=C24)*(BAREMOS!D:D=E24),0),0),-1) ) ), IF(H24<=MIN(INDEX(BAREMOS!G:Y,MATCH(1,(BAREMOS!A:A=A24)*"&"(BAREMOS!B:B=B24)*(BAREMOS!C:C=C24)*(BAREMOS!D:D=E24),0),0)),1, IF(H24>=MAX(INDEX(BAREMOS!G:Y,MATCH(1,(BAREMOS!A:A=A24)*(BAREMOS!B:B=B24)*(BAREMOS!C:C=C24)*(BAREMOS!D:D=E24),0),0)),19, MATCH(H24,INDEX(BAREMOS!G:Y,MATCH(1,(BAREMOS!A:A=A24)*("&"BAREMOS!B:B=B24)*(BAREMOS!C:C=C24)*(BAREMOS!D:D=E24),0),0),1) ) ) ) ,"""")) "),1.0) -> 1 | K24: =IF(J24="","",INDEX(SEQUENCE(1,19,1,0.5),1,J24)) -> 1
A25: {=IF(D25="","",IFERROR(INDEX(CONFIGURACION!C:C,MATCH(D25,CONFIGURACION!E:E,0)),""))} -> BCH | B25: {=IF(D25="","",IFERROR(INDEX(CONFIGURACION!D:D,MATCH(D25,CONFIGURACION!E:E,0)),""))} -> 1 | C25: MASCULINO | D25: B1 | E25: FLEXIBILIDAD | F25: Juan Carlos Huizar Moreno | G25: 2 TRIMESTRE | H25: 13 | I25: =IFERROR(__xludf.DUMMYFUNCTION("IF(F25="""","""",LET( nombre, TRIM(F25), primer, REGEXEXTRACT(nombre, ""^\S+""), resto, TRIM(REGEXREPLACE(nombre, ""^\S+\s*"", """")), iniciales, IF( resto="""", """", TEXTJOIN("""",1,ARRAYFORMULA(LEFT(SPLIT(resto,"" ""),1) & ""."")) "&" ), UPPER(primer) & "" "" & UPPER(iniciales) ))"),"JUAN C.H.M.") -> JUAN C.H.M. | J25: =IFERROR(__xludf.DUMMYFUNCTION("IF(H25="""","""",IFERROR( IF(REGEXMATCH(E25,""VELOCIDAD""), IF(H25>=MAX(INDEX(BAREMOS!G:Y,MATCH(1,(BAREMOS!A:A=A25)*(BAREMOS!B:B=B25)*(BAREMOS!C:C=C25)*(BAREMOS!D:D=E25),0),0)),1, IF(H25<=MIN(INDEX(BAREMOS!G:Y,MATCH(1,(BAREMOS!A:A=A25)*(BAREMOS!B"&":B=B25)*(BAREMOS!C:C=C25)*(BAREMOS!D:D=E25),0),0)),19, MATCH(H25,INDEX(BAREMOS!G:Y,MATCH(1,(BAREMOS!A:A=A25)*(BAREMOS!B:B=B25)*(BAREMOS!C:C=C25)*(BAREMOS!D:D=E25),0),0),-1) ) ), IF(H25<=MIN(INDEX(BAREMOS!G:Y,MATCH(1,(BAREMOS!A:A=A25)*"&"(BAREMOS!B:B=B25)*(BAREMOS!C:C=C25)*(BAREMOS!D:D=E25),0),0)),1, IF(H25>=MAX(INDEX(BAREMOS!G:Y,MATCH(1,(BAREMOS!A:A=A25)*(BAREMOS!B:B=B25)*(BAREMOS!C:C=C25)*(BAREMOS!D:D=E25),0),0)),19, MATCH(H25,INDEX(BAREMOS!G:Y,MATCH(1,(BAREMOS!A:A=A25)*("&"BAREMOS!B:B=B25)*(BAREMOS!C:C=C25)*(BAREMOS!D:D=E25),0),0),1) ) ) ) ,"""")) "),1.0) -> 1 | K25: =IF(J25="","",INDEX(SEQUENCE(1,19,1,0.5),1,J25)) -> 1
A26: {=IF(D26="","",IFERROR(INDEX(CONFIGURACION!C:C,MATCH(D26,CONFIGURACION!E:E,0)),""))} -> BCH | B26: {=IF(D26="","",IFERROR(INDEX(CONFIGURACION!D:D,MATCH(D26,CONFIGURACION!E:E,0)),""))} -> 1 | C26: MASCULINO | D26: B1 | E26: S. VERTICAL | F26: Juan Carlos Huizar Moreno | G26: 2 TRIMESTRE | H26: 14 | I26: =IFERROR(__xludf.DUMMYFUNCTION("IF(F26="""","""",LET( nombre, TRIM(F26), primer, REGEXEXTRACT(nombre, ""^\S+""), resto, TRIM(REGEXREPLACE(nombre, ""^\S+\s*"", """")), iniciales, IF( resto="""", """", TEXTJOIN("""",1,ARRAYFORMULA(LEFT(SPLIT(resto,"" ""),1) & ""."")) "&" ), UPPER(primer) & "" "" & UPPER(iniciales) ))"),"JUAN C.H.M.") -> JUAN C.H.M. | J26: =IFERROR(__xludf.DUMMYFUNCTION("IF(H26="""","""",IFERROR( IF(REGEXMATCH(E26,""VELOCIDAD""), IF(H26>=MAX(INDEX(BAREMOS!G:Y,MATCH(1,(BAREMOS!A:A=A26)*(BAREMOS!B:B=B26)*(BAREMOS!C:C=C26)*(BAREMOS!D:D=E26),0),0)),1, IF(H26<=MIN(INDEX(BAREMOS!G:Y,MATCH(1,(BAREMOS!A:A=A26)*(BAREMOS!B"&":B=B26)*(BAREMOS!C:C=C26)*(BAREMOS!D:D=E26),0),0)),19, MATCH(H26,INDEX(BAREMOS!G:Y,MATCH(1,(BAREMOS!A:A=A26)*(BAREMOS!B:B=B26)*(BAREMOS!C:C=C26)*(BAREMOS!D:D=E26),0),0),-1) ) ), IF(H26<=MIN(INDEX(BAREMOS!G:Y,MATCH(1,(BAREMOS!A:A=A26)*"&"(BAREMOS!B:B=B26)*(BAREMOS!C:C=C26)*(BAREMOS!D:D=E26),0),0)),1, IF(H26>=MAX(INDEX(BAREMOS!G:Y,MATCH(1,(BAREMOS!A:A=A26)*(BAREMOS!B:B=B26)*(BAREMOS!C:C=C26)*(BAREMOS!D:D=E26),0),0)),19, MATCH(H26,INDEX(BAREMOS!G:Y,MATCH(1,(BAREMOS!A:A=A26)*("&"BAREMOS!B:B=B26)*(BAREMOS!C:C=C26)*(BAREMOS!D:D=E26),0),0),1) ) ) ) ,"""")) "),1.0) -> 1 | K26: =IF(J26="","",INDEX(SEQUENCE(1,19,1,0.5),1,J26)) -> 1
A27: {=IF(D27="","",IFERROR(INDEX(CONFIGURACION!C:C,MATCH(D27,CONFIGURACION!E:E,0)),""))} -> BCH | B27: {=IF(D27="","",IFERROR(INDEX(CONFIGURACION!D:D,MATCH(D27,CONFIGURACION!E:E,0)),""))} -> 1 | C27: MASCULINO | D27: B1 | E27: COOPER | F27: Juan Carlos Huizar Moreno | G27: 2 TRIMESTRE | H27: 15 | I27: =IFERROR(__xludf.DUMMYFUNCTION("IF(F27="""","""",LET( nombre, TRIM(F27), primer, REGEXEXTRACT(nombre, ""^\S+""), resto, TRIM(REGEXREPLACE(nombre, ""^\S+\s*"", """")), iniciales, IF( resto="""", """", TEXTJOIN("""",1,ARRAYFORMULA(LEFT(SPLIT(resto,"" ""),1) & ""."")) "&" ), UPPER(primer) & "" "" & UPPER(iniciales) ))"),"JUAN C.H.M.") -> JUAN C.H.M. | J27: =IFERROR(__xludf.DUMMYFUNCTION("IF(H27="""","""",IFERROR( IF(REGEXMATCH(E27,""VELOCIDAD""), IF(H27>=MAX(INDEX(BAREMOS!G:Y,MATCH(1,(BAREMOS!A:A=A27)*(BAREMOS!B:B=B27)*(BAREMOS!C:C=C27)*(BAREMOS!D:D=E27),0),0)),1, IF(H27<=MIN(INDEX(BAREMOS!G:Y,MATCH(1,(BAREMOS!A:A=A27)*(BAREMOS!B"&":B=B27)*(BAREMOS!C:C=C27)*(BAREMOS!D:D=E27),0),0)),19, MATCH(H27,INDEX(BAREMOS!G:Y,MATCH(1,(BAREMOS!A:A=A27)*(BAREMOS!B:B=B27)*(BAREMOS!C:C=C27)*(BAREMOS!D:D=E27),0),0),-1) ) ), IF(H27<=MIN(INDEX(BAREMOS!G:Y,MATCH(1,(BAREMOS!A:A=A27)*"&"(BAREMOS!B:B=B27)*(BAREMOS!C:C=C27)*(BAREMOS!D:D=E27),0),0)),1, IF(H27>=MAX(INDEX(BAREMOS!G:Y,MATCH(1,(BAREMOS!A:A=A27)*(BAREMOS!B:B=B27)*(BAREMOS!C:C=C27)*(BAREMOS!D:D=E27),0),0)),19, MATCH(H27,INDEX(BAREMOS!G:Y,MATCH(1,(BAREMOS!A:A=A27)*("&"BAREMOS!B:B=B27)*(BAREMOS!C:C=C27)*(BAREMOS!D:D=E27),0),0),1) ) ) ) ,"""")) "),1.0) -> 1 | K27: =IF(J27="","",INDEX(SEQUENCE(1,19,1,0.5),1,J27)) -> 1
A28: {=IF(D28="","",IFERROR(INDEX(CONFIGURACION!C:C,MATCH(D28,CONFIGURACION!E:E,0)),""))} -> BCH | B28: {=IF(D28="","",IFERROR(INDEX(CONFIGURACION!D:D,MATCH(D28,CONFIGURACION!E:E,0)),""))} -> 1 | C28: MASCULINO | D28: B1 | E28: VELOCIDAD | F28: Juan Carlos Huizar Moreno | G28: 2 TRIMESTRE | H28: 16 | I28: =IFERROR(__xludf.DUMMYFUNCTION("IF(F28="""","""",LET( nombre, TRIM(F28), primer, REGEXEXTRACT(nombre, ""^\S+""), resto, TRIM(REGEXREPLACE(nombre, ""^\S+\s*"", """")), iniciales, IF( resto="""", """", TEXTJOIN("""",1,ARRAYFORMULA(LEFT(SPLIT(resto,"" ""),1) & ""."")) "&" ), UPPER(primer) & "" "" & UPPER(iniciales) ))"),"JUAN C.H.M.") -> JUAN C.H.M. | J28: =IFERROR(__xludf.DUMMYFUNCTION("IF(H28="""","""",IFERROR( IF(REGEXMATCH(E28,""VELOCIDAD""), IF(H28>=MAX(INDEX(BAREMOS!G:Y,MATCH(1,(BAREMOS!A:A=A28)*(BAREMOS!B:B=B28)*(BAREMOS!C:C=C28)*(BAREMOS!D:D=E28),0),0)),1, IF(H28<=MIN(INDEX(BAREMOS!G:Y,MATCH(1,(BAREMOS!A:A=A28)*(BAREMOS!B"&":B=B28)*(BAREMOS!C:C=C28)*(BAREMOS!D:D=E28),0),0)),19, MATCH(H28,INDEX(BAREMOS!G:Y,MATCH(1,(BAREMOS!A:A=A28)*(BAREMOS!B:B=B28)*(BAREMOS!C:C=C28)*(BAREMOS!D:D=E28),0),0),-1) ) ), IF(H28<=MIN(INDEX(BAREMOS!G:Y,MATCH(1,(BAREMOS!A:A=A28)*"&"(BAREMOS!B:B=B28)*(BAREMOS!C:C=C28)*(BAREMOS!D:D=E28),0),0)),1, IF(H28>=MAX(INDEX(BAREMOS!G:Y,MATCH(1,(BAREMOS!A:A=A28)*(BAREMOS!B:B=B28)*(BAREMOS!C:C=C28)*(BAREMOS!D:D=E28),0),0)),19, MATCH(H28,INDEX(BAREMOS!G:Y,MATCH(1,(BAREMOS!A:A=A28)*("&"BAREMOS!B:B=B28)*(BAREMOS!C:C=C28)*(BAREMOS!D:D=E28),0),0),1) ) ) ) ,"""")) "),19.0) -> 19 | K28: =IF(J28="","",INDEX(SEQUENCE(1,19,1,0.5),1,J28)) -> 10
A29: {=IF(D29="","",IFERROR(INDEX(CONFIGURACION!C:C,MATCH(D29,CONFIGURACION!E:E,0)),""))} -> BCH | B29: {=IF(D29="","",IFERROR(INDEX(CONFIGURACION!D:D,MATCH(D29,CONFIGURACION!E:E,0)),""))} -> 1 | C29: MASCULINO | D29: B1 | E29: INTESIDAD FISICA | F29: Juan Carlos Huizar Moreno | G29: 2 TRIMESTRE | H29: 17 | I29: =IFERROR(__xludf.DUMMYFUNCTION("IF(F29="""","""",LET( nombre, TRIM(F29), primer, REGEXEXTRACT(nombre, ""^\S+""), resto, TRIM(REGEXREPLACE(nombre, ""^\S+\s*"", """")), iniciales, IF( resto="""", """", TEXTJOIN("""",1,ARRAYFORMULA(LEFT(SPLIT(resto,"" ""),1) & ""."")) "&" ), UPPER(primer) & "" "" & UPPER(iniciales) ))"),"JUAN C.H.M.") -> JUAN C.H.M. | J29: =IFERROR(__xludf.DUMMYFUNCTION("IF(H29="""","""",IFERROR( IF(REGEXMATCH(E29,""VELOCIDAD""), IF(H29>=MAX(INDEX(BAREMOS!G:Y,MATCH(1,(BAREMOS!A:A=A29)*(BAREMOS!B:B=B29)*(BAREMOS!C:C=C29)*(BAREMOS!D:D=E29),0),0)),1, IF(H29<=MIN(INDEX(BAREMOS!G:Y,MATCH(1,(BAREMOS!A:A=A29)*(BAREMOS!B"&":B=B29)*(BAREMOS!C:C=C29)*(BAREMOS!D:D=E29),0),0)),19, MATCH(H29,INDEX(BAREMOS!G:Y,MATCH(1,(BAREMOS!A:A=A29)*(BAREMOS!B:B=B29)*(BAREMOS!C:C=C29)*(BAREMOS!D:D=E29),0),0),-1) ) ), IF(H29<=MIN(INDEX(BAREMOS!G:Y,MATCH(1,(BAREMOS!A:A=A29)*"&"(BAREMOS!B:B=B29)*(BAREMOS!C:C=C29)*(BAREMOS!D:D=E29),0),0)),1, IF(H29>=MAX(INDEX(BAREMOS!G:Y,MATCH(1,(BAREMOS!A:A=A29)*(BAREMOS!B:B=B29)*(BAREMOS!C:C=C29)*(BAREMOS!D:D=E29),0),0)),19, MATCH(H29,INDEX(BAREMOS!G:Y,MATCH(1,(BAREMOS!A:A=A29)*("&"BAREMOS!B:B=B29)*(BAREMOS!C:C=C29)*(BAREMOS!D:D=E29),0),0),1) ) ) ) ,"""")) "),"") | K29: =IF(J29="","",INDEX(SEQUENCE(1,19,1,0.5),1,J29))
A30: {=IF(D30="","",IFERROR(INDEX(CONFIGURACION!C:C,MATCH(D30,CONFIGURACION!E:E,0)),""))} -> BCH | B30: {=IF(D30="","",IFERROR(INDEX(CONFIGURACION!D:D,MATCH(D30,CONFIGURACION!E:E,0)),""))} -> 1 | C30: MASCULINO | D30: B1 | E30: S. HORIZONTAL | F30: Juan Carlos Huizar Moreno | G30: 3 TRIMESTRE | H30: 15 | I30: =IFERROR(__xludf.DUMMYFUNCTION("IF(F30="""","""",LET( nombre, TRIM(F30), primer, REGEXEXTRACT(nombre, ""^\S+""), resto, TRIM(REGEXREPLACE(nombre, ""^\S+\s*"", """")), iniciales, IF( resto="""", """", TEXTJOIN("""",1,ARRAYFORMULA(LEFT(SPLIT(resto,"" ""),1) & ""."")) "&" ), UPPER(primer) & "" "" & UPPER(iniciales) ))"),"JUAN C.H.M.") -> JUAN C.H.M. | J30: =IFERROR(__xludf.DUMMYFUNCTION("IF(H30="""","""",IFERROR( IF(REGEXMATCH(E30,""VELOCIDAD""), IF(H30>=MAX(INDEX(BAREMOS!G:Y,MATCH(1,(BAREMOS!A:A=A30)*(BAREMOS!B:B=B30)*(BAREMOS!C:C=C30)*(BAREMOS!D:D=E30),0),0)),1, IF(H30<=MIN(INDEX(BAREMOS!G:Y,MATCH(1,(BAREMOS!A:A=A30)*(BAREMOS!B"&":B=B30)*(BAREMOS!C:C=C30)*(BAREMOS!D:D=E30),0),0)),19, MATCH(H30,INDEX(BAREMOS!G:Y,MATCH(1,(BAREMOS!A:A=A30)*(BAREMOS!B:B=B30)*(BAREMOS!C:C=C30)*(BAREMOS!D:D=E30),0),0),-1) ) ), IF(H30<=MIN(INDEX(BAREMOS!G:Y,MATCH(1,(BAREMOS!A:A=A30)*"&"(BAREMOS!B:B=B30)*(BAREMOS!C:C=C30)*(BAREMOS!D:D=E30),0),0)),1, IF(H30>=MAX(INDEX(BAREMOS!G:Y,MATCH(1,(BAREMOS!A:A=A30)*(BAREMOS!B:B=B30)*(BAREMOS!C:C=C30)*(BAREMOS!D:D=E30),0),0)),19, MATCH(H30,INDEX(BAREMOS!G:Y,MATCH(1,(BAREMOS!A:A=A30)*("&"BAREMOS!B:B=B30)*(BAREMOS!C:C=C30)*(BAREMOS!D:D=E30),0),0),1) ) ) ) ,"""")) "),1.0) -> 1 | K30: =IF(J30="","",INDEX(SEQUENCE(1,19,1,0.5),1,J30)) -> 1
A31: {=IF(D31="","",IFERROR(INDEX(CONFIGURACION!C:C,MATCH(D31,CONFIGURACION!E:E,0)),""))} -> BCH | B31: {=IF(D31="","",IFERROR(INDEX(CONFIGURACION!D:D,MATCH(D31,CONFIGURACION!E:E,0)),""))} -> 1 | C31: MASCULINO | D31: B1 | E31: L. BALON | F31: Juan Carlos Huizar Moreno | G31: 3 TRIMESTRE | H31: 4 | I31: =IFERROR(__xludf.DUMMYFUNCTION("IF(F31="""","""",LET( nombre, TRIM(F31), primer, REGEXEXTRACT(nombre, ""^\S+""), resto, TRIM(REGEXREPLACE(nombre, ""^\S+\s*"", """")), iniciales, IF( resto="""", """", TEXTJOIN("""",1,ARRAYFORMULA(LEFT(SPLIT(resto,"" ""),1) & ""."")) "&" ), UPPER(primer) & "" "" & UPPER(iniciales) ))"),"JUAN C.H.M.") -> JUAN C.H.M. | J31: =IFERROR(__xludf.DUMMYFUNCTION("IF(H31="""","""",IFERROR( IF(REGEXMATCH(E31,""VELOCIDAD""), IF(H31>=MAX(INDEX(BAREMOS!G:Y,MATCH(1,(BAREMOS!A:A=A31)*(BAREMOS!B:B=B31)*(BAREMOS!C:C=C31)*(BAREMOS!D:D=E31),0),0)),1, IF(H31<=MIN(INDEX(BAREMOS!G:Y,MATCH(1,(BAREMOS!A:A=A31)*(BAREMOS!B"&":B=B31)*(BAREMOS!C:C=C31)*(BAREMOS!D:D=E31),0),0)),19, MATCH(H31,INDEX(BAREMOS!G:Y,MATCH(1,(BAREMOS!A:A=A31)*(BAREMOS!B:B=B31)*(BAREMOS!C:C=C31)*(BAREMOS!D:D=E31),0),0),-1) ) ), IF(H31<=MIN(INDEX(BAREMOS!G:Y,MATCH(1,(BAREMOS!A:A=A31)*"&"(BAREMOS!B:B=B31)*(BAREMOS!C:C=C31)*(BAREMOS!D:D=E31),0),0)),1, IF(H31>=MAX(INDEX(BAREMOS!G:Y,MATCH(1,(BAREMOS!A:A=A31)*(BAREMOS!B:B=B31)*(BAREMOS!C:C=C31)*(BAREMOS!D:D=E31),0),0)),19, MATCH(H31,INDEX(BAREMOS!G:Y,MATCH(1,(BAREMOS!A:A=A31)*("&"BAREMOS!B:B=B31)*(BAREMOS!C:C=C31)*(BAREMOS!D:D=E31),0),0),1) ) ) ) ,"""")) "),1.0) -> 1 | K31: =IF(J31="","",INDEX(SEQUENCE(1,19,1,0.5),1,J31)) -> 1
A32: {=IF(D32="","",IFERROR(INDEX(CONFIGURACION!C:C,MATCH(D32,CONFIGURACION!E:E,0)),""))} -> BCH | B32: {=IF(D32="","",IFERROR(INDEX(CONFIGURACION!D:D,MATCH(D32,CONFIGURACION!E:E,0)),""))} -> 1 | C32: MASCULINO | D32: B1 | E32: ABDOMINALES | F32: Juan Carlos Huizar Moreno | G32: 3 TRIMESTRE | H32: 5 | I32: =IFERROR(__xludf.DUMMYFUNCTION("IF(F32="""","""",LET( nombre, TRIM(F32), primer, REGEXEXTRACT(nombre, ""^\S+""), resto, TRIM(REGEXREPLACE(nombre, ""^\S+\s*"", """")), iniciales, IF( resto="""", """", TEXTJOIN("""",1,ARRAYFORMULA(LEFT(SPLIT(resto,"" ""),1) & ""."")) "&" ), UPPER(primer) & "" "" & UPPER(iniciales) ))"),"JUAN C.H.M.") -> JUAN C.H.M. | J32: =IFERROR(__xludf.DUMMYFUNCTION("IF(H32="""","""",IFERROR( IF(REGEXMATCH(E32,""VELOCIDAD""), IF(H32>=MAX(INDEX(BAREMOS!G:Y,MATCH(1,(BAREMOS!A:A=A32)*(BAREMOS!B:B=B32)*(BAREMOS!C:C=C32)*(BAREMOS!D:D=E32),0),0)),1, IF(H32<=MIN(INDEX(BAREMOS!G:Y,MATCH(1,(BAREMOS!A:A=A32)*(BAREMOS!B"&":B=B32)*(BAREMOS!C:C=C32)*(BAREMOS!D:D=E32),0),0)),19, MATCH(H32,INDEX(BAREMOS!G:Y,MATCH(1,(BAREMOS!A:A=A32)*(BAREMOS!B:B=B32)*(BAREMOS!C:C=C32)*(BAREMOS!D:D=E32),0),0),-1) ) ), IF(H32<=MIN(INDEX(BAREMOS!G:Y,MATCH(1,(BAREMOS!A:A=A32)*"&"(BAREMOS!B:B=B32)*(BAREMOS!C:C=C32)*(BAREMOS!D:D=E32),0),0)),1, IF(H32>=MAX(INDEX(BAREMOS!G:Y,MATCH(1,(BAREMOS!A:A=A32)*(BAREMOS!B:B=B32)*(BAREMOS!C:C=C32)*(BAREMOS!D:D=E32),0),0)),19, MATCH(H32,INDEX(BAREMOS!G:Y,MATCH(1,(BAREMOS!A:A=A32)*("&"BAREMOS!B:B=B32)*(BAREMOS!C:C=C32)*(BAREMOS!D:D=E32),0),0),1) ) ) ) ,"""")) "),1.0) -> 1 | K32: =IF(J32="","",INDEX(SEQUENCE(1,19,1,0.5),1,J32)) -> 1
A33: {=IF(D33="","",IFERROR(INDEX(CONFIGURACION!C:C,MATCH(D33,CONFIGURACION!E:E,0)),""))} -> BCH | B33: {=IF(D33="","",IFERROR(INDEX(CONFIGURACION!D:D,MATCH(D33,CONFIGURACION!E:E,0)),""))} -> 1 | C33: MASCULINO | D33: B1 | E33: FLEXIBILIDAD | F33: Juan Carlos Huizar Moreno | G33: 3 TRIMESTRE | H33: 6 | I33: =IFERROR(__xludf.DUMMYFUNCTION("IF(F33="""","""",LET( nombre, TRIM(F33), primer, REGEXEXTRACT(nombre, ""^\S+""), resto, TRIM(REGEXREPLACE(nombre, ""^\S+\s*"", """")), iniciales, IF( resto="""", """", TEXTJOIN("""",1,ARRAYFORMULA(LEFT(SPLIT(resto,"" ""),1) & ""."")) "&" ), UPPER(primer) & "" "" & UPPER(iniciales) ))"),"JUAN C.H.M.") -> JUAN C.H.M. | J33: =IFERROR(__xludf.DUMMYFUNCTION("IF(H33="""","""",IFERROR( IF(REGEXMATCH(E33,""VELOCIDAD""), IF(H33>=MAX(INDEX(BAREMOS!G:Y,MATCH(1,(BAREMOS!A:A=A33)*(BAREMOS!B:B=B33)*(BAREMOS!C:C=C33)*(BAREMOS!D:D=E33),0),0)),1, IF(H33<=MIN(INDEX(BAREMOS!G:Y,MATCH(1,(BAREMOS!A:A=A33)*(BAREMOS!B"&":B=B33)*(BAREMOS!C:C=C33)*(BAREMOS!D:D=E33),0),0)),19, MATCH(H33,INDEX(BAREMOS!G:Y,MATCH(1,(BAREMOS!A:A=A33)*(BAREMOS!B:B=B33)*(BAREMOS!C:C=C33)*(BAREMOS!D:D=E33),0),0),-1) ) ), IF(H33<=MIN(INDEX(BAREMOS!G:Y,MATCH(1,(BAREMOS!A:A=A33)*"&"(BAREMOS!B:B=B33)*(BAREMOS!C:C=C33)*(BAREMOS!D:D=E33),0),0)),1, IF(H33>=MAX(INDEX(BAREMOS!G:Y,MATCH(1,(BAREMOS!A:A=A33)*(BAREMOS!B:B=B33)*(BAREMOS!C:C=C33)*(BAREMOS!D:D=E33),0),0)),19, MATCH(H33,INDEX(BAREMOS!G:Y,MATCH(1,(BAREMOS!A:A=A33)*("&"BAREMOS!B:B=B33)*(BAREMOS!C:C=C33)*(BAREMOS!D:D=E33),0),0),1) ) ) ) ,"""")) "),1.0) -> 1 | K33: =IF(J33="","",INDEX(SEQUENCE(1,19,1,0.5),1,J33)) -> 1
A34: {=IF(D34="","",IFERROR(INDEX(CONFIGURACION!C:C,MATCH(D34,CONFIGURACION!E:E,0)),""))} -> BCH | B34: {=IF(D34="","",IFERROR(INDEX(CONFIGURACION!D:D,MATCH(D34,CONFIGURACION!E:E,0)),""))} -> 1 | C34: MASCULINO | D34: B1 | E34: S. VERTICAL | F34: Juan Carlos Huizar Moreno | G34: 3 TRIMESTRE | H34: 7 | I34: =IFERROR(__xludf.DUMMYFUNCTION("IF(F34="""","""",LET( nombre, TRIM(F34), primer, REGEXEXTRACT(nombre, ""^\S+""), resto, TRIM(REGEXREPLACE(nombre, ""^\S+\s*"", """")), iniciales, IF( resto="""", """", TEXTJOIN("""",1,ARRAYFORMULA(LEFT(SPLIT(resto,"" ""),1) & ""."")) "&" ), UPPER(primer) & "" "" & UPPER(iniciales) ))"),"JUAN C.H.M.") -> JUAN C.H.M. | J34: =IFERROR(__xludf.DUMMYFUNCTION("IF(H34="""","""",IFERROR( IF(REGEXMATCH(E34,""VELOCIDAD""), IF(H34>=MAX(INDEX(BAREMOS!G:Y,MATCH(1,(BAREMOS!A:A=A34)*(BAREMOS!B:B=B34)*(BAREMOS!C:C=C34)*(BAREMOS!D:D=E34),0),0)),1, IF(H34<=MIN(INDEX(BAREMOS!G:Y,MATCH(1,(BAREMOS!A:A=A34)*(BAREMOS!B"&":B=B34)*(BAREMOS!C:C=C34)*(BAREMOS!D:D=E34),0),0)),19, MATCH(H34,INDEX(BAREMOS!G:Y,MATCH(1,(BAREMOS!A:A=A34)*(BAREMOS!B:B=B34)*(BAREMOS!C:C=C34)*(BAREMOS!D:D=E34),0),0),-1) ) ), IF(H34<=MIN(INDEX(BAREMOS!G:Y,MATCH(1,(BAREMOS!A:A=A34)*"&"(BAREMOS!B:B=B34)*(BAREMOS!C:C=C34)*(BAREMOS!D:D=E34),0),0)),1, IF(H34>=MAX(INDEX(BAREMOS!G:Y,MATCH(1,(BAREMOS!A:A=A34)*(BAREMOS!B:B=B34)*(BAREMOS!C:C=C34)*(BAREMOS!D:D=E34),0),0)),19, MATCH(H34,INDEX(BAREMOS!G:Y,MATCH(1,(BAREMOS!A:A=A34)*("&"BAREMOS!B:B=B34)*(BAREMOS!C:C=C34)*(BAREMOS!D:D=E34),0),0),1) ) ) ) ,"""")) "),1.0) -> 1 | K34: =IF(J34="","",INDEX(SEQUENCE(1,19,1,0.5),1,J34)) -> 1
