Workbook
Name NombreIntervalo1: DATOS!$E$2:$E$23
Name CURSO: CONFIGURACION!$E$2:$E$17

Sheet CONFIGURACION
A1: ANIO_ACADEMICO | C1: CICLO | D1: GRADO | E1: CURSO | G1: GENERO | I1: PERIODO | K1: PRUEBA | L1: HABILITAR | M1: NOMBRE_PRUEBA | N1: UNIDAD | O1: TIPO | P1: OBJETIVO | Q1: MEDIO | R1: MATERIAL | S1: DESCRIPCION | T1: VALORACION
A2: 2024-2025 | C2: ESO | D2: 1 | E2: A | G2: MASCULINO | I2: 1 TRIMESTRE | K2: S. HORIZONTAL | L2: SI | M2: Test de Salto Horizontal | N2: cm | O2: Fuerza | P2: Determinar la potencia de las piernas. | Q2: Superficie plana y antideslizante, con una línea dibujada en el suelo. | S2: Posición Inicial: El ejecutante ha de situarse derecho con los pies ligeramente separados y la punta de los pies detrás de la línea de salida. Desarrollo: Ha de tomar impulso para saltar, flexionando las piernas y empujando con los brazos desde detrás hacia adelante. Se salta haciendo una rápida extensión de las piernas y estirando los brazos hacia adelante. Finalización: En el momento de la caída, el ejecutante ha de mantener los pies en el mismo sitio donde ha tomado contacto con el suelo sin perder el equilibrio. | T2: Se registrará la distancia en centímetros. Hay que anotar el mejor de los dos resultados.
C3: ESO | D3: 1 | E3: B | G3: FEMENINO | I3: 2 TRIMESTRE | K3: L. BALON | L3: SI | M3: Test de Balón medicinal | N3: m | O3: Fuerza | P3: Medir la fuerza del tren superior. | Q3: Superficie plana y antideslizante. | R3: Balón medicinal. | S3: Posición Inicial: El ejecutante se colocará en la línea con los pies separados a la anchura de los hombros, cogiendo el balón con las dos manos por detrás de la cabeza. Desarrollo: Lanzar el balón lo más lejos posible. No se podrá saltar en el momento del lanzamiento. De igual modo se tendrá que mantener la posición de equilibrio. Se ejecutarán dos intentos. | T3: Se registrará la distancia en centímetros. Hay que anotar el mejor de los dos resultados.
C4: ESO | D4: 2 | E4: A | I4: 3 TRIMESTRE | K4: ABDOMINALES | L4: SI | M4: Test de Abdominales | N4: repeticiones | O4: Fuerza | P4: Medir la fuerza-resistencia de los músculos abdominales. | Q4: Superficie plana y lisa. | R4: Cronómetro con precisión de centésimas de segundo. | S4: Posición Inicial: El ejecutante ha de colocarse en decúbito supino con las piernas flexionadas 90o, los pies ligeramente separados y los dedos entrelazados detrás de la nuca o brazos cruzados sobre el pecho. Un ayudante ha de sujetarle los pies para fijarlos al suelo. Desarrollo: Al oír la señal del observador "preparado...ya!", el ejecutante ha de tratar de hacer el mayor número de repeticiones posibles, tocando siempre con los codos las rodillas y con la espalda en la colchoneta. El ayudante contará el número de repeticiones. Finalización: Cuando hayan pasado 30” se indicará el final. | T4: Se registra el número de repeticiones realizadas correctamente. Solo habrá un intento.
C5: ESO | D5: 2 | E5: B | I5: 4 TRIMESTRE | K5: FLEXIBILIDAD | L5: SI | M5: Test de Flexión anterior del tronco | N5: cm | O5: Flexibilidad | P5: Medir la flexibilidad del tronco. | Q5: Superficie antideslizante. | S5: Posición Inicial: El ejecutante descalzo, se ha de sentar enfrente del cajón con las piernas completamente extendidas y las plantas de los pies en completo contacto con la pared del cajón. Desarrollo: Flexionar el tronco hacia adelante sin doblar las piernas, y extender los brazos y las palmas de la mano sobre la regla, ha de tratar de llegar lo más lejos posible. Finalización: El ejecutante, en el momento en que llega a la posición máxima, ha de permanecer inmóvil durante 2 segundos para que se pueda registrar el resultado conseguido. | T5: El registro se hará en centímetros. Se anota el mejor de los 2 resultados.
C6: ESO | D6: 3 | E6: A | K6: S. VERTICAL | L6: SI | M6: Test de Salto Vertical | N6: cm | O6: Fuerza | P6: Medir la fuerza explosiva del tren inferior en el sentido vertical. | Q6: Superficie plana y antideslizante. | R6: Tabla graduada o escala pintada sobre la pared. | S6: Posición Inicial: El ejecutante se colocará junto a una pared, lateralmente, y con el brazo más próximo a ella señalará su punto más alto. Desarrollo: A la señal y previa separación de la pared, ha de tomar impulso para saltar, flexionando las piernas, hasta alcanzar el máximo posible dejando marca con los dedos en la tabla. | T6: Se registrará la diferencia entre el máximo estático y el de la marca del salto en centímetros. Hay que anotar el mejor de los dos resultados.
C7: ESO | D7: 3 | E7: B | K7: COOPER | L7: SI | M7: Test de Cooper | N7: m | O7: Resistencia | P7: Valorar la resistencia aeróbica. Determinar el VO2 máximo. | Q7: Pista o terreno liso y sin pendiente. | R7: Cronómetro | S7: Consiste en cubrir la máxima distancia posible durante 12 minutos de carrera continua. | T7: Se anotará la distancia recorrida al finalizar los doce minutos.
C8: ESO | D8: 4 | E8: A | K8: VELOCIDAD | L8: SI | M8: Test de Velocidad en 50m | N8: seg | O8: Velocidad | P8: Medir la velocidad de traslación partiendo de una velocidad inicial igual a 0. | Q8: Pista o terreno liso y sin pendiente. | R8: Cronómetro | S8: Recorrer la distancia de 50 metros en el menor tiempo posible. Se realizarán dos intentos con un periodo de reposo entre cada uno. | T8: El registro se hará en centésimas de segundo. Se anota el mejor de los dos resultados.
C9: ESO | D9: 4 | E9: B | K9: INTESIDAD FISICA | L9: SI | M9: Test de intensidad de esfuerzos físicos | N9: fc | O9: Medición | P9: Calcular la zona de actividad a partir de la frecuencia cardiaca y ejercicio físico | Q9: Cualquier medio | R9: Cronómetro | S9: Conocer la intensidad de nuestros esfuerzos y nos va a ayudar a situarnos en la ZONA DE ACTIVIDAD apropiada según el objetivo que pretendamos. | T9: Toma el pulso nada más parar la actividad física, durante 15” y multiplica tu resultado por 4 para saber los latidos por minuto.
C10: ESO | D10: 1 | E10: A1
C11: ESO | D11: 1 | E11: A2-C
C12: BCH | D12: 1 | E12: B1
C13: BCH | D13: 1 | E13: B2
C14: BCH | D14: 2 | E14: A1
C15: BCH | D15: 2 | E15: B1
C16: BCH | D16: 2 | E16: B2
C17: BCH | D17: 2 | E17: C

Sheet ALUMNOS
A1: CICLO | B1: GRADO | C1: CURSO | D1: NOMBRE _ALUMNO | E1: GENERO
A2: {=IF(C2="","",IFERROR(INDEX(CONFIGURACION!C:C,MATCH(C2,CONFIGURACION!E:E,0)),""))} -> BCH | B2: {=IF(C2="","",IFERROR(INDEX(CONFIGURACION!D:D,MATCH(C2,CONFIGURACION!E:E,0)),""))} -> 1 | C2: B1 | D2: Manolo Díaz Camacho | E2: MASCULINO
A3: {=IF(C3="","",IFERROR(INDEX(CONFIGURACION!C:C,MATCH(C3,CONFIGURACION!E:E,0)),""))} -> BCH | B3: {=IF(C3="","",IFERROR(INDEX(CONFIGURACION!D:D,MATCH(C3,CONFIGURACION!E:E,0)),""))} -> 1 | C3: B1 | D3: María Domínguez García. | E3: FEMENINO
A4: {=IF(C4="","",IFERROR(INDEX(CONFIGURACION!C:C,MATCH(C4,CONFIGURACION!E:E,0)),""))} -> BCH | B4: {=IF(C4="","",IFERROR(INDEX(CONFIGURACION!D:D,MATCH(C4,CONFIGURACION!E:E,0)),""))} -> 1 | C4: B1 | D4: Juan Pérez Holguín | E4: MASCULINO
A5: {=IF(C5="","",IFERROR(INDEX(CONFIGURACION!C:C,MATCH(C5,CONFIGURACION!E:E,0)),""))} -> BCH | B5: {=IF(C5="","",IFERROR(INDEX(CONFIGURACION!D:D,MATCH(C5,CONFIGURACION!E:E,0)),""))} -> 1 | C5: B1 | D5: María García Andrade | E5: FEMENINO
A6: {=IF(C6="","",IFERROR(INDEX(CONFIGURACION!C:C,MATCH(C6,CONFIGURACION!E:E,0)),""))} -> BCH | B6: {=IF(C6="","",IFERROR(INDEX(CONFIGURACION!D:D,MATCH(C6,CONFIGURACION!E:E,0)),""))} -> 1 | C6: B1 | D6: Rubén Fernández Ríos | E6: MASCULINO
A7: {=IF(C7="","",IFERROR(INDEX(CONFIGURACION!C:C,MATCH(C7,CONFIGURACION!E:E,0)),""))} -> BCH | B7: {=IF(C7="","",IFERROR(INDEX(CONFIGURACION!D:D,MATCH(C7,CONFIGURACION!E:E,0)),""))} -> 1 | C7: B1 | D7: Paty Vergara González | E7: FEMENINO
A8: {=IF(C8="","",IFERROR(INDEX(CONFIGURACION!C:C,MATCH(C8,CONFIGURACION!E:E,0)),""))} -> BCH | B8: {=IF(C8="","",IFERROR(INDEX(CONFIGURACION!D:D,MATCH(C8,CONFIGURACION!E:E,0)),""))} -> 1 | C8: B1 | D8: Jorge López Ortega | E8: MASCULINO
A9: {=IF(C9="","",IFERROR(INDEX(CONFIGURACION!C:C,MATCH(C9,CONFIGURACION!E:E,0)),""))} -> BCH | B9: {=IF(C9="","",IFERROR(INDEX(CONFIGURACION!D:D,MATCH(C9,CONFIGURACION!E:E,0)),""))} -> 1 | C9: B1 | D9: Olga Contreras Méndez | E9: FEMENINO
A10: {=IF(C10="","",IFERROR(INDEX(CONFIGURACION!C:C,MATCH(C10,CONFIGURACION!E:E,0)),""))} -> BCH | B10: {=IF(C10="","",IFERROR(INDEX(CONFIGURACION!D:D,MATCH(C10,CONFIGURACION!E:E,0)),""))} -> 1 | C10: B1 | D10: Job Gabriel Yepes Espitia | E10: MASCULINO
A11: {=IF(C11="","",IFERROR(INDEX(CONFIGURACION!C:C,MATCH(C11,CONFIGURACION!E:E,0)),""))} -> BCH | B11: {=IF(C11="","",IFERROR(INDEX(CONFIGURACION!D:D,MATCH(C11,CONFIGURACION!E:E,0)),""))} -> 1 | C11: B1 | D11: Gloria Patricia Rincón Montoya | E11: FEMENINO
A12: {=IF(C12="","",IFERROR(INDEX(CONFIGURACION!C:C,MATCH(C12,CONFIGURACION!E:E,0)),""))} -> BCH | B12: {=IF(C12="","",IFERROR(INDEX(CONFIGURACION!D:D,MATCH(C12,CONFIGURACION!E:E,0)),""))} -> 1 | C12: B1 | D12: Carlos Antonio Barragán Torres | E12: MASCULINO
A13: {=IF(C13="","",IFERROR(INDEX(CONFIGURACION!C:C,MATCH(C13,CONFIGURACION!E:E,0)),""))} -> BCH | B13: {=IF(C13="","",IFERROR(INDEX(CONFIGURACION!D:D,MATCH(C13,CONFIGURACION!E:E,0)),""))} -> 1 | C13: B1 | D13: Daniel Efren Daza Timaná | E13: MASCULINO
... A23: {=IF(C23="","",IFERROR(INDEX(CONFIGURACION!C:C,MATCH(C23,CONFIGURACION!E:E,0)),""))} -> BCH | B23: {=IF(C23="","",IFERROR(INDEX(CONFIGURACION!D:D,MATCH(C23,CONFIGURACION!E:E,0)),""))} -> 1 | C23: B1 | D23: Roberto Urriaga Bonachera | E23: MASCULINO
A24: {=IF(C24="","",IFERROR(INDEX(CONFIGURACION!C:C,MATCH(C24,CONFIGURACION!E:E,0)),""))} | B24: {=IF(C24="","",IFERROR(INDEX(CONFIGURACION!D:D,MATCH(C24,CONFIGURACION!E:E,0)),""))}
A25: {=IF(I25="","",IFERROR(INDEX(CONFIGURACION!H:H,MATCH(I25,CONFIGURACION!J:J,0)),""))} | B25: {=IF(I25="","",IFERROR(INDEX(CONFIGURACION!I:I,MATCH(I25,CONFIGURACION!J:J,0)),""))}
A26: {=IF(I26="","",IFERROR(INDEX(CONFIGURACION!H:H,MATCH(I26,CONFIGURACION!J:J,0)),""))} | B26: {=IF(I26="","",IFERROR(INDEX(CONFIGURACION!I:I,MATCH(I26,CONFIGURACION!J:J,0)),""))}
A27: {=IF(I27="","",IFERROR(INDEX(CONFIGURACION!H:H,MATCH(I27,CONFIGURACION!J:J,0)),""))} | B27: {=IF(I27="","",IFERROR(INDEX(CONFIGURACION!I:I,MATCH(I27,CONFIGURACION!J:J,0)),""))}
A28: {=IF(I28="","",IFERROR(INDEX(CONFIGURACION!H:H,MATCH(I28,CONFIGURACION!J:J,0)),""))} | B28: {=IF(I28="","",IFERROR(INDEX(CONFIGURACION!I:I,MATCH(I28,CONFIGURACION!J:J,0)),""))}
A29: {=IF(I29="","",IFERROR(INDEX(CONFIGURACION!H:H,MATCH(I29,CONFIGURACION!J:J,0)),""))} | B29: {=IF(I29="","",IFERROR(INDEX(CONFIGURACION!I:I,MATCH(I29,CONFIGURACION!J:J,0)),""))}
A30: {=IF(I30="","",IFERROR(INDEX(CONFIGURACION!H:H,MATCH(I30,CONFIGURACION!J:J,0)),""))} | B30: {=IF(I30="","",IFERROR(INDEX(CONFIGURACION!I:I,MATCH(I30,CONFIGURACION!J:J,0)),""))}
A31: {=IF(I31="","",IFERROR(INDEX(CONFIGURACION!H:H,MATCH(I31,CONFIGURACION!J:J,0)),""))} | B31: {=IF(I31="","",IFERROR(INDEX(CONFIGURACION!I:I,MATCH(I31,CONFIGURACION!J:J,0)),""))}
A32: {=IF(I32="","",IFERROR(INDEX(CONFIGURACION!H:H,MATCH(I32,CONFIGURACION!J:J,0)),""))} | B32: {=IF(I32="","",IFERROR(INDEX(CONFIGURACION!I:I,MATCH(I32,CONFIGURACION!J:J,0)),""))}
A33: {=IF(I33="","",IFERROR(INDEX(CONFIGURACION!H:H,MATCH(I33,CONFIGURACION!J:J,0)),""))} | B33: {=IF(I33="","",IFERROR(INDEX(CONFIGURACION!I:I,MATCH(I33,CONFIGURACION!J:J,0)),""))}
A34: {=IF(I34="","",IFERROR(INDEX(CONFIGURACION!H:H,MATCH(I34,CONFIGURACION!J:J,0)),""))} | B34: {=IF(I34="","",IFERROR(INDEX(CONFIGURACION!I:I,MATCH(I34,CONFIGURACION!J:J,0)),""))}
A35: {=IF(I35="","",IFERROR(INDEX(CONFIGURACION!H:H,MATCH(I35,CONFIGURACION!J:J,0)),""))} | B35: {=IF(I35="","",IFERROR(INDEX(CONFIGURACION!I:I,MATCH(I35,CONFIGURACION!J:J,0)),""))}
A36: {=IF(I36="","",IFERROR(INDEX(CONFIGURACION!H:H,MATCH(I36,CONFIGURACION!J:J,0)),""))} | B36: {=IF(I36="","",IFERROR(INDEX(CONFIGURACION!I:I,MATCH(I36,CONFIGURACION!J:J,0)),""))}
... A499: {=IF(I499="","",IFERROR(INDEX(CONFIGURACION!H:H,MATCH(I499,CONFIGURACION!J:J,0)),""))} | B499: {=IF(I499="","",IFERROR(INDEX(CONFIGURACION!I:I,MATCH(I499,CONFIGURACION!J:J,0)),""))}
A500: CICLO | B500: GRADO | C500: CURSO
A501: {=IF(I501="","",IFERROR(INDEX(CONFIGURACION!H:H,MATCH(I501,CONFIGURACION!J:J,0)),""))} | B501: {=IF(I501="","",IFERROR(INDEX(CONFIGURACION!I:I,MATCH(I501,CONFIGURACION!J:J,0)),""))} | C501: B1
A502: {=IF(I502="","",IFERROR(INDEX(CONFIGURACION!H:H,MATCH(I502,CONFIGURACION!J:J,0)),""))} | B502: {=IF(I502="","",IFERROR(INDEX(CONFIGURACION!I:I,MATCH(I502,CONFIGURACION!J:J,0)),""))} | C502: B1
A503: {=IF(I503="","",IFERROR(INDEX(CONFIGURACION!H:H,MATCH(I503,CONFIGURACION!J:J,0)),""))} | B503: {=IF(I503="","",IFERROR(INDEX(CONFIGURACION!I:I,MATCH(I503,CONFIGURACION!J:J,0)),""))} | C503: B1
A504: {=IF(I504="","",IFERROR(INDEX(CONFIGURACION!H:H,MATCH(I504,CONFIGURACION!J:J,0)),""))} | B504: {=IF(I504="","",IFERROR(INDEX(CONFIGURACION!I:I,MATCH(I504,CONFIGURACION!J:J,0)),""))} | C504: B1
A505: {=IF(I505="","",IFERROR(INDEX(CONFIGURACION!H:H,MATCH(I505,CONFIGURACION!J:J,0)),""))} | B505: {=IF(I505="","",IFERROR(INDEX(CONFIGURACION!I:I,MATCH(I505,CONFIGURACION!J:J,0)),""))} | C505: B1
A506: {=IF(I506="","",IFERROR(INDEX(CONFIGURACION!H:H,MATCH(I506,CONFIGURACION!J:J,0)),""))} | B506: {=IF(I506="","",IFERROR(INDEX(CONFIGURACION!I:I,MATCH(I506,CONFIGURACION!J:J,0)),""))} | C506: B1
A507: {=IF(I507="","",IFERROR(INDEX(CONFIGURACION!H:H,MATCH(I507,CONFIGURACION!J:J,0)),""))} | B507: {=IF(I507="","",IFERROR(INDEX(CONFIGURACION!I:I,MATCH(I507,CONFIGURACION!J:J,0)),""))} | C507: B1
A508: {=IF(I508="","",IFERROR(INDEX(CONFIGURACION!H:H,MATCH(I508,CONFIGURACION!J:J,0)),""))} | B508: {=IF(I508="","",IFERROR(INDEX(CONFIGURACION!I:I,MATCH(I508,CONFIGURACION!J:J,0)),""))} | C508: B1
A509: {=IF(I509="","",IFERROR(INDEX(CONFIGURACION!H:H,MATCH(I509,CONFIGURACION!J:J,0)),""))} | B509: {=IF(I509="","",IFERROR(INDEX(CONFIGURACION!I:I,MATCH(I509,CONFIGURACION!J:J,0)),""))} | C509: B1
A510: {=IF(I510="","",IFERROR(INDEX(CONFIGURACION!H:H,MATCH(I510,CONFIGURACION!J:J,0)),""))} | B510: {=IF(I510="","",IFERROR(INDEX(CONFIGURACION!I:I,MATCH(I510,CONFIGURACION!J:J,0)),""))} | C510: B1
A511: {=IF(I511="","",IFERROR(INDEX(CONFIGURACION!H:H,MATCH(I511,CONFIGURACION!J:J,0)),""))} | B511: {=IF(I511="","",IFERROR(INDEX(CONFIGURACION!I:I,MATCH(I511,CONFIGURACION!J:J,0)),""))} | C511: B1
...

Sheet DATOS
A1: CICLO | B1: GRADO | C1: GENERO | D1: PRUEBA | E1: CURSO | F1: NOMBRE _ALUMNO | G1: PERIODO | H1: MEDICION | I1: NOMBRE _CORTO | J1: POSICION_TABLA | K1: BAREMO
A2: {=IF(E2="","",IFERROR(INDEX(CONFIGURACION!C:C,MATCH(E2,CONFIGURACION!E:E,0)),""))} -> BCH | B2: {=IF(E2="","",IFERROR(INDEX(CONFIGURACION!D:D,MATCH(E2,CONFIGURACION!E:E,0)),""))} -> 1 | C2: MASCULINO | D2: COOPER | E2: B1 | F2: Manolo Díaz Camacho | G2: 1 TRIMESTRE | H2: 1900 | I2: =IFERROR(__xludf.DUMMYFUNCTION("IF(F2="""","""",LET( nombre, TRIM(F2), primer, REGEXEXTRACT(nombre, ""^\S+""), resto, TRIM(REGEXREPLACE(nombre, ""^\S+\s*"", """")), iniciales, IF( resto="""", """", TEXTJOIN("""",1,ARRAYFORMULA(LEFT(SPLIT(resto,"" ""),1) & ""."")) )"&", UPPER(primer) & "" "" & UPPER(iniciales) ))"),"MANOLO D.C.") -> MANOLO D.C. | J2: =IFERROR(__xludf.DUMMYFUNCTION("IF(H2="""","""",IFERROR( IF(REGEXMATCH(E2,""VELOCIDAD""), IF(H2>=MAX(INDEX(BAREMOS!F:X,MATCH(1,(BAREMOS!A:A=A2)*(BAREMOS!B:B=B2)*(BAREMOS!C:C=C2)*(BAREMOS!D:D=D2),0),0)),1, IF(H2<=MIN(INDEX(BAREMOS!F:X,MATCH(1,(BAREMOS!A:A=A2)*(BAREMOS!B:B=B2)*(B"&"AREMOS!C:C=C2)*(BAREMOS!D:D=D2),0),0)),19, MATCH(H2,INDEX(BAREMOS!F:X,MATCH(1,(BAREMOS!A:A=A2)*(BAREMOS!B:B=B2)*(BAREMOS!C:C=C2)*(BAREMOS!D:D=D2),0),0),-1) ) ), IF(H2<=MIN(INDEX(BAREMOS!F:X,MATCH(1,(BAREMOS!A:A=A2)*(BAREMOS!B:B=B2)*(B"&"AREMOS!C:C=C2)*(BAREMOS!D:D=D2),0),0)),1, IF(H2>=MAX(INDEX(BAREMOS!F:X,MATCH(1,(BAREMOS!A:A=A2)*(BAREMOS!B:B=B2)*(BAREMOS!C:C=C2)*(BAREMOS!D:D=D2),0),0)),19, MATCH(H2,INDEX(BAREMOS!F:X,MATCH(1,(BAREMOS!A:A=A2)*(BAREMOS!B:B=B2)*(BAREMOS!C:C="&"C2)*(BAREMOS!D:D=D2),0),0),1) ) ) ) ,"""")) "),1.0) -> 1 | K2: =IF(J2="","",INDEX(SEQUENCE(1,19,1,0.5),1,J2)) -> 1 | M2: PUNTUACIONES X ALUMNO
A3: {=IF(E3="","",IFERROR(INDEX(CONFIGURACION!C:C,MATCH(E3,CONFIGURACION!E:E,0)),""))} -> BCH | B3: {=IF(E3="","",IFERROR(INDEX(CONFIGURACION!D:D,MATCH(E3,CONFIGURACION!E:E,0)),""))} -> 1 | C3: FEMENINO | D3: S. HORIZONTAL | E3: B1 | F3: María Domínguez García. | G3: 1 TRIMESTRE | H3: 33 | I3: =IFERROR(__xludf.DUMMYFUNCTION("IF(F3="""","""",LET( nombre, TRIM(F3), primer, REGEXEXTRACT(nombre, ""^\S+""), resto, TRIM(REGEXREPLACE(nombre, ""^\S+\s*"", """")), iniciales, IF( resto="""", """", TEXTJOIN("""",1,ARRAYFORMULA(LEFT(SPLIT(resto,"" ""),1) & ""."")) )"&", UPPER(primer) & "" "" & UPPER(iniciales) ))"),"MARÍA D.G.") -> MARÍA D.G. | J3: =IFERROR(__xludf.DUMMYFUNCTION("IF(H3="""","""",IFERROR( IF(REGEXMATCH(E3,""VELOCIDAD""), IF(H3>=MAX(INDEX(BAREMOS!F:X,MATCH(1,(BAREMOS!A:A=A3)*(BAREMOS!B:B=B3)*(BAREMOS!C:C=C3)*(BAREMOS!D:D=D3),0),0)),1, IF(H3<=MIN(INDEX(BAREMOS!F:X,MATCH(1,(BAREMOS!A:A=A3)*(BAREMOS!B:B=B3)*(B"&"AREMOS!C:C=C3)*(BAREMOS!D:D=D3),0),0)),19, MATCH(H3,INDEX(BAREMOS!F:X,MATCH(1,(BAREMOS!A:A=A3)*(BAREMOS!B:B=B3)*(BAREMOS!C:C=C3)*(BAREMOS!D:D=D3),0),0),-1) ) ), IF(H3<=MIN(INDEX(BAREMOS!F:X,MATCH(1,(BAREMOS!A:A=A3)*(BAREMOS!B:B=B3)*(B"&"AREMOS!C:C=C3)*(BAREMOS!D:D=D3),0),0)),1, IF(H3>=MAX(INDEX(BAREMOS!F:X,MATCH(1,(BAREMOS!A:A=A3)*(BAREMOS!B:B=B3)*(BAREMOS!C:C=C3)*(BAREMOS!D:D=D3),0),0)),19, MATCH(H3,INDEX(BAREMOS!F:X,MATCH(1,(BAREMOS!A:A=A3)*(BAREMOS!B:B=B3)*(BAREMOS!C:C="&"C3)*(BAREMOS!D:D=D3),0),0),1) ) ) ) ,"""")) "),1.0) -> 1 | K3: =IF(J3="","",INDEX(SEQUENCE(1,19,1,0.5),1,J3)) -> 1 | M3: PROMEDIO DE PUNTUACIONES BAREMO X ALUMNO
A4: {=IF(E4="","",IFERROR(INDEX(CONFIGURACION!C:C,MATCH(E4,CONFIGURACION!E:E,0)),""))} -> BCH | B4: {=IF(E4="","",IFERROR(INDEX(CONFIGURACION!D:D,MATCH(E4,CONFIGURACION!E:E,0)),""))} -> 1 | C4: MASCULINO | D4: S. VERTICAL | E4: B1 | F4: Juan Pérez Holguín | G4: 1 TRIMESTRE | H4: 37 | I4: =IFERROR(__xludf.DUMMYFUNCTION("IF(F4="""","""",LET( nombre, TRIM(F4), primer, REGEXEXTRACT(nombre, ""^\S+""), resto, TRIM(REGEXREPLACE(nombre, ""^\S+\s*"", """")), iniciales, IF( resto="""", """", TEXTJOIN("""",1,ARRAYFORMULA(LEFT(SPLIT(resto,"" ""),1) & ""."")) )"&", UPPER(primer) & "" "" & UPPER(iniciales) ))"),"JUAN P.H.") -> JUAN P.H. | J4: =IFERROR(__xludf.DUMMYFUNCTION("IF(H4="""","""",IFERROR( IF(REGEXMATCH(E4,""VELOCIDAD""), IF(H4>=MAX(INDEX(BAREMOS!F:X,MATCH(1,(BAREMOS!A:A=A4)*(BAREMOS!B:B=B4)*(BAREMOS!C:C=C4)*(BAREMOS!D:D=D4),0),0)),1, IF(H4<=MIN(INDEX(BAREMOS!F:X,MATCH(1,(BAREMOS!A:A=A4)*(BAREMOS!B:B=B4)*(B"&"AREMOS!C:C=C4)*(BAREMOS!D:D=D4),0),0)),19, MATCH(H4,INDEX(BAREMOS!F:X,MATCH(1,(BAREMOS!A:A=A4)*(BAREMOS!B:B=B4)*(BAREMOS!C:C=C4)*(BAREMOS!D:D=D4),0),0),-1) ) ), IF(H4<=MIN(INDEX(BAREMOS!F:X,MATCH(1,(BAREMOS!A:A=A4)*(BAREMOS!B:B=B4)*(B"&"AREMOS!C:C=C4)*(BAREMOS!D:D=D4),0),0)),1, IF(H4>=MAX(INDEX(BAREMOS!F:X,MATCH(1,(BAREMOS!A:A=A4)*(BAREMOS!B:B=B4)*(BAREMOS!C:C=C4)*(BAREMOS!D:D=D4),0),0)),19, MATCH(H4,INDEX(BAREMOS!F:X,MATCH(1,(BAREMOS!A:A=A4)*(BAREMOS!B:B=B4)*(BAREMOS!C:C="&"C4)*(BAREMOS!D:D=D4),0),0),1) ) ) ) ,"""")) "),3.0) -> 3 | K4: =IF(J4="","",INDEX(SEQUENCE(1,19,1,0.5),1,J4)) -> 2 | M4: PROMEDIO DE PUNTUACIONES BAREMO X CURSO
A5: {=IF(E5="","",IFERROR(INDEX(CONFIGURACION!C:C,MATCH(E5,CONFIGURACION!E:E,0)),""))} -> BCH | B5: {=IF(E5="","",IFERROR(INDEX(CONFIGURACION!D:D,MATCH(E5,CONFIGURACION!E:E,0)),""))} -> 1 | C5: FEMENINO | D5: S. HORIZONTAL | E5: B1 | F5: María García Andrade | G5: 1 TRIMESTRE | H5: 144 | I5: =IFERROR(__xludf.DUMMYFUNCTION("IF(F5="""","""",LET( nombre, TRIM(F5), primer, REGEXEXTRACT(nombre, ""^\S+""), resto, TRIM(REGEXREPLACE(nombre, ""^\S+\s*"", """")), iniciales, IF( resto="""", """", TEXTJOIN("""",1,ARRAYFORMULA(LEFT(SPLIT(resto,"" ""),1) & ""."")) )"&", UPPER(primer) & "" "" & UPPER(iniciales) ))"),"MARÍA G.A.") -> MARÍA G.A. | J5: =IFERROR(__xludf.DUMMYFUNCTION("IF(H5="""","""",IFERROR( IF(REGEXMATCH(E5,""VELOCIDAD""), IF(H5>=MAX(INDEX(BAREMOS!F:X,MATCH(1,(BAREMOS!A:A=A5)*(BAREMOS!B:B=B5)*(BAREMOS!C:C=C5)*(BAREMOS!D:D=D5),0),0)),1, IF(H5<=MIN(INDEX(BAREMOS!F:X,MATCH(1,(BAREMOS!A:A=A5)*(BAREMOS!B:B=B5)*(B"&"AREMOS!C:C=C5)*(BAREMOS!D:D=D5),0),0)),19, MATCH(H5,INDEX(BAREMOS!F:X,MATCH(1,(BAREMOS!A:A=A5)*(BAREMOS!B:B=B5)*(BAREMOS!C:C=C5)*(BAREMOS!D:D=D5),0),0),-1) ) ), IF(H5<=MIN(INDEX(BAREMOS!F:X,MATCH(1,(BAREMOS!A:A=A5)*(BAREMOS!B:B=B5)*(B"&"AREMOS!C:C=C5)*(BAREMOS!D:D=D5),0),0)),1, IF(H5>=MAX(INDEX(BAREMOS!F:X,MATCH(1,(BAREMOS!A:A=A5)*(BAREMOS!B:B=B5)*(BAREMOS!C:C=C5)*(BAREMOS!D:D=D5),0),0)),19, MATCH(H5,INDEX(BAREMOS!F:X,MATCH(1,(BAREMOS!A:A=A5)*(BAREMOS!B:B=B5)*(BAREMOS!C:C="&"C5)*(BAREMOS!D:D=D5),0),0),1) ) ) ) ,"""")) "),2.0) -> 2 | K5: =IF(J5="","",INDEX(SEQUENCE(1,19,1,0.5),1,J5)) -> 1.5 | M5: COMPARACIÓN DE MEJORA
A6: {=IF(E6="","",IFERROR(INDEX(CONFIGURACION!C:C,MATCH(E6,CONFIGURACION!E:E,0)),""))} -> BCH | B6: {=IF(E6="","",IFERROR(INDEX(CONFIGURACION!D:D,MATCH(E6,CONFIGURACION!E:E,0)),""))} -> 1 | C6: MASCULINO | D6: ABDOMINALES | E6: B1 | F6: Rubén Fernández Ríos | G6: 1 TRIMESTRE | H6: 30 | I6: =IFERROR(__xludf.DUMMYFUNCTION("IF(F6="""","""",LET( nombre, TRIM(F6), primer, REGEXEXTRACT(nombre, ""^\S+""), resto, TRIM(REGEXREPLACE(nombre, ""^\S+\s*"", """")), iniciales, IF( resto="""", """", TEXTJOIN("""",1,ARRAYFORMULA(LEFT(SPLIT(resto,"" ""),1) & ""."")) )"&", UPPER(primer) & "" "" & UPPER(iniciales) ))"),"RUBÉN F.R.") -> RUBÉN F.R. | J6: =IFERROR(__xludf.DUMMYFUNCTION("IF(H6="""","""",IFERROR( IF(REGEXMATCH(E6,""VELOCIDAD""), IF(H6>=MAX(INDEX(BAREMOS!F:X,MATCH(1,(BAREMOS!A:A=A6)*(BAREMOS!B:B=B6)*(BAREMOS!C:C=C6)*(BAREMOS!D:D=D6),0),0)),1, IF(H6<=MIN(INDEX(BAREMOS!F:X,MATCH(1,(BAREMOS!A:A=A6)*(BAREMOS!B:B=B6)*(B"&"AREMOS!C:C=C6)*(BAREMOS!D:D=D6),0),0)),19, MATCH(H6,INDEX(BAREMOS!F:X,MATCH(1,(BAREMOS!A:A=A6)*(BAREMOS!B:B=B6)*(BAREMOS!C:C=C6)*(BAREMOS!D:D=D6),0),0),-1) ) ), IF(H6<=MIN(INDEX(BAREMOS!F:X,MATCH(1,(BAREMOS!A:A=A6)*(BAREMOS!B:B=B6)*(B"&"AREMOS!C:C=C6)*(BAREMOS!D:D=D6),0),0)),1, IF(H6>=MAX(INDEX(BAREMOS!F:X,MATCH(1,(BAREMOS!A:A=A6)*(BAREMOS!B:B=B6)*(BAREMOS!C:C=C6)*(BAREMOS!D:D=D6),0),0)),19, MATCH(H6,INDEX(BAREMOS!F:X,MATCH(1,(BAREMOS!A:A=A6)*(BAREMOS!B:B=B6)*(BAREMOS!C:C="&"C6)*(BAREMOS!D:D=D6),0),0),1) ) ) ) ,"""")) "),15.0) -> 15 | K6: =IF(J6="","",INDEX(SEQUENCE(1,19,1,0.5),1,J6)) -> 8
A7: {=IF(E7="","",IFERROR(INDEX(CONFIGURACION!C:C,MATCH(E7,CONFIGURACION!E:E,0)),""))} -> BCH | B7: {=IF(E7="","",IFERROR(INDEX(CONFIGURACION!D:D,MATCH(E7,CONFIGURACION!E:E,0)),""))} -> 1 | C7: FEMENINO | D7: L. BALON | E7: B1 | F7: Paty Vergara González | G7: 1 TRIMESTRE | H7: 46238 | I7: =IFERROR(__xludf.DUMMYFUNCTION("IF(F7="""","""",LET( nombre, TRIM(F7), primer, REGEXEXTRACT(nombre, ""^\S+""), resto, TRIM(REGEXREPLACE(nombre, ""^\S+\s*"", """")), iniciales, IF( resto="""", """", TEXTJOIN("""",1,ARRAYFORMULA(LEFT(SPLIT(resto,"" ""),1) & ""."")) )"&", UPPER(primer) & "" "" & UPPER(iniciales) ))"),"PATY V.G.") -> PATY V.G. | J7: =IFERROR(__xludf.DUMMYFUNCTION("IF(H7="""","""",IFERROR( IF(REGEXMATCH(E7,""VELOCIDAD""), IF(H7>=MAX(INDEX(BAREMOS!F:X,MATCH(1,(BAREMOS!A:A=A7)*(BAREMOS!B:B=B7)*(BAREMOS!C:C=C7)*(BAREMOS!D:D=D7),0),0)),1, IF(H7<=MIN(INDEX(BAREMOS!F:X,MATCH(1,(BAREMOS!A:A=A7)*(BAREMOS!B:B=B7)*(B"&"AREMOS!C:C=C7)*(BAREMOS!D:D=D7),0),0)),19, MATCH(H7,INDEX(BAREMOS!F:X,MATCH(1,(BAREMOS!A:A=A7)*(BAREMOS!B:B=B7)*(BAREMOS!C:C=C7)*(BAREMOS!D:D=D7),0),0),-1) ) ), IF(H7<=MIN(INDEX(BAREMOS!F:X,MATCH(1,(BAREMOS!A:A=A7)*(BAREMOS!B:B=B7)*(B"&"AREMOS!C:C=C7)*(BAREMOS!D:D=D7),0),0)),1, IF(H7>=MAX(INDEX(BAREMOS!F:X,MATCH(1,(BAREMOS!A:A=A7)*(BAREMOS!B:B=B7)*(BAREMOS!C:C=C7)*(BAREMOS!D:D=D7),0),0)),19, MATCH(H7,INDEX(BAREMOS!F:X,MATCH(1,(BAREMOS!A:A=A7)*(BAREMOS!B:B=B7)*(BAREMOS!C:C="&"C7)*(BAREMOS!D:D=D7),0),0),1) ) ) ) ,"""")) "),14.0) -> 14 | K7: =IF(J7="","",INDEX(SEQUENCE(1,19,1,0.5),1,J7)) -> 7.5
A8: {=IF(E8="","",IFERROR(INDEX(CONFIGURACION!C:C,MATCH(E8,CONFIGURACION!E:E,0)),""))} -> BCH | B8: {=IF(E8="","",IFERROR(INDEX(CONFIGURACION!D:D,MATCH(E8,CONFIGURACION!E:E,0)),""))} -> 1 | C8: MASCULINO | D8: VELOCIDAD | E8: B1 | F8: Jorge López Ortega | G8: 1 TRIMESTRE | H8: 7 | I8: =IFERROR(__xludf.DUMMYFUNCTION("IF(F8="""","""",LET( nombre, TRIM(F8), primer, REGEXEXTRACT(nombre, ""^\S+""), resto, TRIM(REGEXREPLACE(nombre, ""^\S+\s*"", """")), iniciales, IF( resto="""", """", TEXTJOIN("""",1,ARRAYFORMULA(LEFT(SPLIT(resto,"" ""),1) & ""."")) )"&", UPPER(primer) & "" "" & UPPER(iniciales) ))"),"JORGE L.O.") -> JORGE L.O. | J8: =IFERROR(__xludf.DUMMYFUNCTION("IF(H8="""","""",IFERROR( IF(REGEXMATCH(E8,""VELOCIDAD""), IF(H8>=MAX(INDEX(BAREMOS!F:X,MATCH(1,(BAREMOS!A:A=A8)*(BAREMOS!B:B=B8)*(BAREMOS!C:C=C8)*(BAREMOS!D:D=D8),0),0)),1, IF(H8<=MIN(INDEX(BAREMOS!F:X,MATCH(1,(BAREMOS!A:A=A8)*(BAREMOS!B:B=B8)*(B"&"AREMOS!C:C=C8)*(BAREMOS!D:D=D8),0),0)),19, MATCH(H8,INDEX(BAREMOS!F:X,MATCH(1,(BAREMOS!A:A=A8)*(BAREMOS!B:B=B8)*(BAREMOS!C:C=C8)*(BAREMOS!D:D=D8),0),0),-1) ) ), IF(H8<=MIN(INDEX(BAREMOS!F:X,MATCH(1,(BAREMOS!A:A=A8)*(BAREMOS!B:B=B8)*(B"&"AREMOS!C:C=C8)*(BAREMOS!D:D=D8),0),0)),1, IF(H8>=MAX(INDEX(BAREMOS!F:X,MATCH(1,(BAREMOS!A:A=A8)*(BAREMOS!B:B=B8)*(BAREMOS!C:C=C8)*(BAREMOS!D:D=D8),0),0)),19, MATCH(H8,INDEX(BAREMOS!F:X,MATCH(1,(BAREMOS!A:A=A8)*(BAREMOS!B:B=B8)*(BAREMOS!C:C="&"C8)*(BAREMOS!D:D=D8),0),0),1) ) ) ) ,"""")) "),1.0) -> 1 | K8: =IF(J8="","",INDEX(SEQUENCE(1,19,1,0.5),1,J8)) -> 1
A9: {=IF(E9="","",IFERROR(INDEX(CONFIGURACION!C:C,MATCH(E9,CONFIGURACION!E:E,0)),""))} -> BCH | B9: {=IF(E9="","",IFERROR(INDEX(CONFIGURACION!D:D,MATCH(E9,CONFIGURACION!E:E,0)),""))} -> 1 | C9: FEMENINO | D9: COOPER | E9: B1 | F9: Olga Contreras Méndez | G9: 1 TRIMESTRE | H9: 2700 | I9: =IFERROR(__xludf.DUMMYFUNCTION("IF(F9="""","""",LET( nombre, TRIM(F9), primer, REGEXEXTRACT(nombre, ""^\S+""), resto, TRIM(REGEXREPLACE(nombre, ""^\S+\s*"", """")), iniciales, IF( resto="""", """", TEXTJOIN("""",1,ARRAYFORMULA(LEFT(SPLIT(resto,"" ""),1) & ""."")) )"&", UPPER(primer) & "" "" & UPPER(iniciales) ))"),"OLGA C.M.") -> OLGA C.M. | J9: =IFERROR(__xludf.DUMMYFUNCTION("IF(H9="""","""",IFERROR( IF(REGEXMATCH(E9,""VELOCIDAD""), IF(H9>=MAX(INDEX(BAREMOS!F:X,MATCH(1,(BAREMOS!A:A=A9)*(BAREMOS!B:B=B9)*(BAREMOS!C:C=C9)*(BAREMOS!D:D=D9),0),0)),1, IF(H9<=MIN(INDEX(BAREMOS!F:X,MATCH(1,(BAREMOS!A:A=A9)*(BAREMOS!B:B=B9)*(B"&"AREMOS!C:C=C9)*(BAREMOS!D:D=D9),0),0)),19, MATCH(H9,INDEX(BAREMOS!F:X,MATCH(1,(BAREMOS!A:A=A9)*(BAREMOS!B:B=B9)*(BAREMOS!C:C=C9)*(BAREMOS!D:D=D9),0),0),-1) ) ), IF(H9<=MIN(INDEX(BAREMOS!F:X,MATCH(1,(BAREMOS!A:A=A9)*(BAREMOS!B:B=B9)*(B"&"AREMOS!C:C=C9)*(BAREMOS!D:D=D9),0),0)),1, IF(H9>=MAX(INDEX(BAREMOS!F:X,MATCH(1,(BAREMOS!A:A=A9)*(BAREMOS!B:B=B9)*(BAREMOS!C:C=C9)*(BAREMOS!D:D=D9),0),0)),19, MATCH(H9,INDEX(BAREMOS!F:X,MATCH(1,(BAREMOS!A:A=A9)*(BAREMOS!B:B=B9)*(BAREMOS!C:C="&"C9)*(BAREMOS!D:D=D9),0),0),1) ) ) ) ,"""")) "),17.0) -> 17 | K9: =IF(J9="","",INDEX(SEQUENCE(1,19,1,0.5),1,J9)) -> 9
A10: {=IF(E10="","",IFERROR(INDEX(CONFIGURACION!C:C,MATCH(E10,CONFIGURACION!E:E,0)),""))} -> BCH | B10: {=IF(E10="","",IFERROR(INDEX(CONFIGURACION!D:D,MATCH(E10,CONFIGURACION!E:E,0)),""))} -> 1 | C10: MASCULINO | D10: S. HORIZONTAL | E10: B1 | F10: Job Gabriel Yepes Espitia | G10: 1 TRIMESTRE | H10: 29 | I10: =IFERROR(__xludf.DUMMYFUNCTION("IF(F10="""","""",LET( nombre, TRIM(F10), primer, REGEXEXTRACT(nombre, ""^\S+""), resto, TRIM(REGEXREPLACE(nombre, ""^\S+\s*"", """")), iniciales, IF( resto="""", """", TEXTJOIN("""",1,ARRAYFORMULA(LEFT(SPLIT(resto,"" ""),1) & ""."")) "&" ), UPPER(primer) & "" "" & UPPER(iniciales) ))"),"JOB G.Y.E.") -> JOB G.Y.E. | J10: =IFERROR(__xludf.DUMMYFUNCTION("IF(H10="""","""",IFERROR( IF(REGEXMATCH(E10,""VELOCIDAD""), IF(H10>=MAX(INDEX(BAREMOS!F:X,MATCH(1,(BAREMOS!A:A=A10)*(BAREMOS!B:B=B10)*(BAREMOS!C:C=C10)*(BAREMOS!D:D=D10),0),0)),1, IF(H10<=MIN(INDEX(BAREMOS!F:X,MATCH(1,(BAREMOS!A:A=A10)*(BAREMOS!B"&":B=B10)*(BAREMOS!C:C=C10)*(BAREMOS!D:D=D10),0),0)),19, MATCH(H10,INDEX(BAREMOS!F:X,MATCH(1,(BAREMOS!A:A=A10)*(BAREMOS!B:B=B10)*(BAREMOS!C:C=C10)*(BAREMOS!D:D=D10),0),0),-1) ) ), IF(H10<=MIN(INDEX(BAREMOS!F:X,MATCH(1,(BAREMOS!A:A=A10)*"&"(BAREMOS!B:B=B10)*(BAREMOS!C:C=C10)*(BAREMOS!D:D=D10),0),0)),1, IF(H10>=MAX(INDEX(BAREMOS!F:X,MATCH(1,(BAREMOS!A:A=A10)*(BAREMOS!B:B=B10)*(BAREMOS!C:C=C10)*(BAREMOS!D:D=D10),0),0)),19, MATCH(H10,INDEX(BAREMOS!F:X,MATCH(1,(BAREMOS!A:A=A10)*("&"BAREMOS!B:B=B10)*(BAREMOS!C:C=C10)*(BAREMOS!D:D=D10),0),0),1) ) ) ) ,"""")) "),1.0) -> 1 | K10: =IF(J10="","",INDEX(SEQUENCE(1,19,1,0.5),1,J10)) -> 1
A11: {=IF(E11="","",IFERROR(INDEX(CONFIGURACION!C:C,MATCH(E11,CONFIGURACION!E:E,0)),""))} -> BCH | B11: {=IF(E11="","",IFERROR(INDEX(CONFIGURACION!D:D,MATCH(E11,CONFIGURACION!E:E,0)),""))} -> 1 | C11: FEMENINO | D11: S. VERTICAL | E11: B1 | F11: Gloria Patricia Rincón Montoya | G11: 1 TRIMESTRE | H11: 30 | I11: =IFERROR(__xludf.DUMMYFUNCTION("IF(F11="""","""",LET( nombre, TRIM(F11), primer, REGEXEXTRACT(nombre, ""^\S+""), resto, TRIM(REGEXREPLACE(nombre, ""^\S+\s*"", """")), iniciales, IF( resto="""", """", TEXTJOIN("""",1,ARRAYFORMULA(LEFT(SPLIT(resto,"" ""),1) & ""."")) "&" ), UPPER(primer) & "" "" & UPPER(iniciales) ))"),"GLORIA P.R.M.") -> GLORIA P.R.M. | J11: =IFERROR(__xludf.DUMMYFUNCTION("IF(H11="""","""",IFERROR( IF(REGEXMATCH(E11,""VELOCIDAD""), IF(H11>=MAX(INDEX(BAREMOS!F:X,MATCH(1,(BAREMOS!A:A=A11)*(BAREMOS!B:B=B11)*(BAREMOS!C:C=C11)*(BAREMOS!D:D=D11),0),0)),1, IF(H11<=MIN(INDEX(BAREMOS!F:X,MATCH(1,(BAREMOS!A:A=A11)*(BAREMOS!B"&":B=B11)*(BAREMOS!C:C=C11)*(BAREMOS!D:D=D11),0),0)),19, MATCH(H11,INDEX(BAREMOS!F:X,MATCH(1,(BAREMOS!A:A=A11)*(BAREMOS!B:B=B11)*(BAREMOS!C:C=C11)*(BAREMOS!D:D=D11),0),0),-1) ) ), IF(H11<=MIN(INDEX(BAREMOS!F:X,MATCH(1,(BAREMOS!A:A=A11)*"&"(BAREMOS!B:B=B11)*(BAREMOS!C:C=C11)*(BAREMOS!D:D=D11),0),0)),1, IF(H11>=MAX(INDEX(BAREMOS!F:X,MATCH(1,(BAREMOS!A:A=A11)*(BAREMOS!B:B=B11)*(BAREMOS!C:C=C11)*(BAREMOS!D:D=D11),0),0)),19, MATCH(H11,INDEX(BAREMOS!F:X,MATCH(1,(BAREMOS!A:A=A11)*("&"BAREMOS!B:B=B11)*(BAREMOS!C:C=C11)*(BAREMOS!D:D=D11),0),0),1) ) ) ) ,"""")) "),6.0) -> 6 | K11: =IF(J11="","",INDEX(SEQUENCE(1,19,1,0.5),1,J11)) -> 3.5
A12: {=IF(E12="","",IFERROR(INDEX(CONFIGURACION!C:C,MATCH(E12,CONFIGURACION!E:E,0)),""))} -> BCH | B12: {=IF(E12="","",IFERROR(INDEX(CONFIGURACION!D:D,MATCH(E12,CONFIGURACION!E:E,0)),""))} -> 1 | C12: MASCULINO | D12: S. HORIZONTAL | E12: B1 | F12: Carlos Antonio Barragán Torres | G12: 1 TRIMESTRE | H12: 162 | I12: =IFERROR(__xludf.DUMMYFUNCTION("IF(F12="""","""",LET( nombre, TRIM(F12), primer, REGEXEXTRACT(nombre, ""^\S+""), resto, TRIM(REGEXREPLACE(nombre, ""^\S+\s*"", """")), iniciales, IF( resto="""", """", TEXTJOIN("""",1,ARRAYFORMULA(LEFT(SPLIT(resto,"" ""),1) & ""."")) "&" ), UPPER(primer) & "" "" & UPPER(iniciales) ))"),"CARLOS A.B.T.") -> CARLOS A.B.T. | J12: =IFERROR(__xludf.DUMMYFUNCTION("IF(H12="""","""",IFERROR( IF(REGEXMATCH(E12,""VELOCIDAD""), IF(H12>=MAX(INDEX(BAREMOS!F:X,MATCH(1,(BAREMOS!A:A=A12)*(BAREMOS!B:B=B12)*(BAREMOS!C:C=C12)*(BAREMOS!D:D=D12),0),0)),1, IF(H12<=MIN(INDEX(BAREMOS!F:X,MATCH(1,(BAREMOS!A:A=A12)*(BAREMOS!B"&":B=B12)*(BAREMOS!C:C=C12)*(BAREMOS!D:D=D12),0),0)),19, MATCH(H12,INDEX(BAREMOS!F:X,MATCH(1,(BAREMOS!A:A=A12)*(BAREMOS!B:B=B12)*(BAREMOS!C:C=C12)*(BAREMOS!D:D=D12),0),0),-1) ) ), IF(H12<=MIN(INDEX(BAREMOS!F:X,MATCH(1,(BAREMOS!A:A=A12)*"&"(BAREMOS!B:B=B12)*(BAREMOS!C:C=C12)*(BAREMOS!D:D=D12),0),0)),1, IF(H12>=MAX(INDEX(BAREMOS!F:X,MATCH(1,(BAREMOS!A:A=A12)*(BAREMOS!B:B=B12)*(BAREMOS!C:C=C12)*(BAREMOS!D:D=D12),0),0)),19, MATCH(H12,INDEX(BAREMOS!F:X,MATCH(1,(BAREMOS!A:A=A12)*("&"BAREMOS!B:B=B12)*(BAREMOS!C:C=C12)*(BAREMOS!D:D=D12),0),0),1) ) ) ) ,"""")) "),2.0) -> 2 | K12: =IF(J12="","",INDEX(SEQUENCE(1,19,1,0.5),1,J12)) -> 1.5
A13: {=IF(E13="","",IFERROR(INDEX(CONFIGURACION!C:C,MATCH(E13,CONFIGURACION!E:E,0)),""))} -> BCH | B13: {=IF(E13="","",IFERROR(INDEX(CONFIGURACION!D:D,MATCH(E13,CONFIGURACION!E:E,0)),""))} -> 1 | C13: MASCULINO | D13: ABDOMINALES | E13: B1 | F13: Daniel Efren Daza Timaná | G13: 1 TRIMESTRE | H13: 19 | I13: =IFERROR(__xludf.DUMMYFUNCTION("IF(F13="""","""",LET( nombre, TRIM(F13), primer, REGEXEXTRACT(nombre, ""^\S+""), resto, TRIM(REGEXREPLACE(nombre, ""^\S+\s*"", """")), iniciales, IF( resto="""", """", TEXTJOIN("""",1,ARRAYFORMULA(LEFT(SPLIT(resto,"" ""),1) & ""."")) "&" ), UPPER(primer) & "" "" & UPPER(iniciales) ))"),"DANIEL E.D.T.") -> DANIEL E.D.T. | J13: =IFERROR(__xludf.DUMMYFUNCTION("IF(H13="""","""",IFERROR( IF(REGEXMATCH(E13,""VELOCIDAD""), IF(H13>=MAX(INDEX(BAREMOS!F:X,MATCH(1,(BAREMOS!A:A=A13)*(BAREMOS!B:B=B13)*(BAREMOS!C:C=C13)*(BAREMOS!D:D=D13),0),0)),1, IF(H13<=MIN(INDEX(BAREMOS!F:X,MATCH(1,(BAREMOS!A:A=A13)*(BAREMOS!B"&":B=B13)*(BAREMOS!C:C=C13)*(BAREMOS!D:D=D13),0),0)),19, MATCH(H13,INDEX(BAREMOS!F:X,MATCH(1,(BAREMOS!A:A=A13)*(BAREMOS!B:B=B13)*(BAREMOS!C:C=C13)*(BAREMOS!D:D=D13),0),0),-1) ) ), IF(H13<=MIN(INDEX(BAREMOS!F:X,MATCH(1,(BAREMOS!A:A=A13)*"&"(BAREMOS!B:B=B13)*(BAREMOS!C:C=C13)*(BAREMOS!D:D=D13),0),0)),1, IF(H13>=MAX(INDEX(BAREMOS!F:X,MATCH(1,(BAREMOS!A:A=A13)*(BAREMOS!B:B=B13)*(BAREMOS!C:C=C13)*(BAREMOS!D:D=D13),0),0)),19, MATCH(H13,INDEX(BAREMOS!F:X,MATCH(1,(BAREMOS!A:A=A13)*("&"BAREMOS!B:B=B13)*(BAREMOS!C:C=C13)*(BAREMOS!D:D=D13),0),0),1) ) ) ) ,"""")) "),5.0) -> 5 | K13: =IF(J13="","",INDEX(SEQUENCE(1,19,1,0.5),1,J13)) -> 3
A14: {=IF(E14="","",IFERROR(INDEX(CONFIGURACION!C:C,MATCH(E14,CONFIGURACION!E:E,0)),""))} -> BCH | B14: {=IF(E14="","",IFERROR(INDEX(CONFIGURACION!D:D,MATCH(E14,CONFIGURACION!E:E,0)),""))} -> 1 | C14: MASCULINO | D14: L. BALON | E14: B1 | F14: Judith Cardona Gallego | G14: 1 TRIMESTRE | H14: 5 | I14: =IFERROR(__xludf.DUMMYFUNCTION("IF(F14="""","""",LET( nombre, TRIM(F14), primer, REGEXEXTRACT(nombre, ""^\S+""), resto, TRIM(REGEXREPLACE(nombre, ""^\S+\s*"", """")), iniciales, IF( resto="""", """", TEXTJOIN("""",1,ARRAYFORMULA(LEFT(SPLIT(resto,"" ""),1) & ""."")) "&" ), UPPER(primer) & "" "" & UPPER(iniciales) ))"),"JUDITH C.G.") -> JUDITH C.G. | J14: =IFERROR(__xludf.DUMMYFUNCTION("IF(H14="""","""",IFERROR( IF(REGEXMATCH(E14,""VELOCIDAD""), IF(H14>=MAX(INDEX(BAREMOS!F:X,MATCH(1,(BAREMOS!A:A=A14)*(BAREMOS!B:B=B14)*(BAREMOS!C:C=C14)*(BAREMOS!D:D=D14),0),0)),1, IF(H14<=MIN(INDEX(BAREMOS!F:X,MATCH(1,(BAREMOS!A:A=A14)*(BAREMOS!B"&":B=B14)*(BAREMOS!C:C=C14)*(BAREMOS!D:D=D14),0),0)),19, MATCH(H14,INDEX(BAREMOS!F:X,MATCH(1,(BAREMOS!A:A=A14)*(BAREMOS!B:B=B14)*(BAREMOS!C:C=C14)*(BAREMOS!D:D=D14),0),0),-1) ) ), IF(H14<=MIN(INDEX(BAREMOS!F:X,MATCH(1,(BAREMOS!A:A=A14)*"&"(BAREMOS!B:B=B14)*(BAREMOS!C:C=C14)*(BAREMOS!D:D=D14),0),0)),1, IF(H14>=MAX(INDEX(BAREMOS!F:X,MATCH(1,(BAREMOS!A:A=A14)*(BAREMOS!B:B=B14)*(BAREMOS!C:C=C14)*(BAREMOS!D:D=D14),0),0)),19, MATCH(H14,INDEX(BAREMOS!F:X,MATCH(1,(BAREMOS!A:A=A14)*("&"BAREMOS!B:B=B14)*(BAREMOS!C:C=C14)*(BAREMOS!D:D=D14),0),0),1) ) ) ) ,"""")) "),2.0) -> 2 | K14: =IF(J14="","",INDEX(SEQUENCE(1,19,1,0.5),1,J14)) -> 1.5
A15: {=IF(E15="","",IFERROR(INDEX(CONFIGURACION!C:C,MATCH(E15,CONFIGURACION!E:E,0)),""))} -> BCH | B15: {=IF(E15="","",IFERROR(INDEX(CONFIGURACION!D:D,MATCH(E15,CONFIGURACION!E:E,0)),""))} -> 1 | C15: MASCULINO | D15: VELOCIDAD | E15: B1 | F15: Luis López Bayardo | G15: 1 TRIMESTRE | H15: 46061 | I15: =IFERROR(__xludf.DUMMYFUNCTION("IF(F15="""","""",LET( nombre, TRIM(F15), primer, REGEXEXTRACT(nombre, ""^\S+""), resto, TRIM(REGEXREPLACE(nombre, ""^\S+\s*"", """")), iniciales, IF( resto="""", """", TEXTJOIN("""",1,ARRAYFORMULA(LEFT(SPLIT(resto,"" ""),1) & ""."")) "&" ), UPPER(primer) & "" "" & UPPER(iniciales) ))"),"LUIS L.B.") -> LUIS L.B. | J15: =IFERROR(__xludf.DUMMYFUNCTION("IF(H15="""","""",IFERROR( IF(REGEXMATCH(E15,""VELOCIDAD""), IF(H15>=MAX(INDEX(BAREMOS!F:X,MATCH(1,(BAREMOS!A:A=A15)*(BAREMOS!B:B=B15)*(BAREMOS!C:C=C15)*(BAREMOS!D:D=D15),0),0)),1, IF(H15<=MIN(INDEX(BAREMOS!F:X,MATCH(1,(BAREMOS!A:A=A15)*(BAREMOS!B"&":B=B15)*(BAREMOS!C:C=C15)*(BAREMOS!D:D=D15),0),0)),19, MATCH(H15,INDEX(BAREMOS!F:X,MATCH(1,(BAREMOS!A:A=A15)*(BAREMOS!B:B=B15)*(BAREMOS!C:C=C15)*(BAREMOS!D:D=D15),0),0),-1) ) ), IF(H15<=MIN(INDEX(BAREMOS!F:X,MATCH(1,(BAREMOS!A:A=A15)*"&"(BAREMOS!B:B=B15)*(BAREMOS!C:C=C15)*(BAREMOS!D:D=D15),0),0)),1, IF(H15>=MAX(INDEX(BAREMOS!F:X,MATCH(1,(BAREMOS!A:A=A15)*(BAREMOS!B:B=B15)*(BAREMOS!C:C=C15)*(BAREMOS!D:D=D15),0),0)),19, MATCH(H15,INDEX(BAREMOS!F:X,MATCH(1,(BAREMOS!A:A=A15)*("&"BAREMOS!B:B=B15)*(BAREMOS!C:C=C15)*(BAREMOS!D:D=D15),0),0),1) ) ) ) ,"""")) "),6.0) -> 6 | K15: =IF(J15="","",INDEX(SEQUENCE(1,19,1,0.5),1,J15)) -> 3.5
A16: {=IF(E16="","",IFERROR(INDEX(CONFIGURACION!C:C,MATCH(E16,CONFIGURACION!E:E,0)),""))} -> BCH | B16: {=IF(E16="","",IFERROR(INDEX(CONFIGURACION!D:D,MATCH(E16,CONFIGURACION!E:E,0)),""))} -> 1 | C16: MASCULINO | D16: COOPER | E16: B1 | F16: Luz Mariuxi Murillo Calvache | G16: 1 TRIMESTRE | H16: 2222 | I16: =IFERROR(__xludf.DUMMYFUNCTION("IF(F16="""","""",LET( nombre, TRIM(F16), primer, REGEXEXTRACT(nombre, ""^\S+""), resto, TRIM(REGEXREPLACE(nombre, ""^\S+\s*"", """")), iniciales, IF( resto="""", """", TEXTJOIN("""",1,ARRAYFORMULA(LEFT(SPLIT(resto,"" ""),1) & ""."")) "&" ), UPPER(primer) & "" "" & UPPER(iniciales) ))"),"LUZ M.M.C.") -> LUZ M.M.C. | J16: =IFERROR(__xludf.DUMMYFUNCTION("IF(H16="""","""",IFERROR( IF(REGEXMATCH(E16,""VELOCIDAD""), IF(H16>=MAX(INDEX(BAREMOS!F:X,MATCH(1,(BAREMOS!A:A=A16)*(BAREMOS!B:B=B16)*(BAREMOS!C:C=C16)*(BAREMOS!D:D=D16),0),0)),1, IF(H16<=MIN(INDEX(BAREMOS!F:X,MATCH(1,(BAREMOS!A:A=A16)*(BAREMOS!B"&":B=B16)*(BAREMOS!C:C=C16)*(BAREMOS!D:D=D16),0),0)),19, MATCH(H16,INDEX(BAREMOS!F:X,MATCH(1,(BAREMOS!A:A=A16)*(BAREMOS!B:B=B16)*(BAREMOS!C:C=C16)*(BAREMOS!D:D=D16),0),0),-1) ) ), IF(H16<=MIN(INDEX(BAREMOS!F:X,MATCH(1,(BAREMOS!A:A=A16)*"&"(BAREMOS!B:B=B16)*(BAREMOS!C:C=C16)*(BAREMOS!D:D=D16),0),0)),1, IF(H16>=MAX(INDEX(BAREMOS!F:X,MATCH(1,(BAREMOS!A:A=A16)*(BAREMOS!B:B=B16)*(BAREMOS!C:C=C16)*(BAREMOS!D:D=D16),0),0)),19, MATCH(H16,INDEX(BAREMOS!F:X,MATCH(1,(BAREMOS!A:A=A16)*("&"BAREMOS!B:B=B16)*(BAREMOS!C:C=C16)*(BAREMOS!D:D=D16),0),0),1) ) ) ) ,"""")) "),3.0) -> 3 | K16: =IF(J16="","",INDEX(SEQUENCE(1,19,1,0.5),1,J16)) -> 2
A17: {=IF(E17="","",IFERROR(INDEX(CONFIGURACION!C:C,MATCH(E17,CONFIGURACION!E:E,0)),""))} -> BCH | B17: {=IF(E17="","",IFERROR(INDEX(CONFIGURACION!D:D,MATCH(E17,CONFIGURACION!E:E,0)),""))} -> 1 | C17: MASCULINO | D17: S. HORIZONTAL | E17: B1 | F17: Luis Enrique Santander Rosero | G17: 1 TRIMESTRE | H17: 31 | I17: =IFERROR(__xludf.DUMMYFUNCTION("IF(F17="""","""",LET( nombre, TRIM(F17), primer, REGEXEXTRACT(nombre, ""^\S+""), resto, TRIM(REGEXREPLACE(nombre, ""^\S+\s*"", """")), iniciales, IF( resto="""", """", TEXTJOIN("""",1,ARRAYFORMULA(LEFT(SPLIT(resto,"" ""),1) & ""."")) "&" ), UPPER(primer) & "" "" & UPPER(iniciales) ))"),"LUIS E.S.R.") -> LUIS E.S.R. | J17: =IFERROR(__xludf.DUMMYFUNCTION("IF(H17="""","""",IFERROR( IF(REGEXMATCH(E17,""VELOCIDAD""), IF(H17>=MAX(INDEX(BAREMOS!F:X,MATCH(1,(BAREMOS!A:A=A17)*(BAREMOS!B:B=B17)*(BAREMOS!C:C=C17)*(BAREMOS!D:D=D17),0),0)),1, IF(H17<=MIN(INDEX(BAREMOS!F:X,MATCH(1,(BAREMOS!A:A=A17)*(BAREMOS!B"&":B=B17)*(BAREMOS!C:C=C17)*(BAREMOS!D:D=D17),0),0)),19, MATCH(H17,INDEX(BAREMOS!F:X,MATCH(1,(BAREMOS!A:A=A17)*(BAREMOS!B:B=B17)*(BAREMOS!C:C=C17)*(BAREMOS!D:D=D17),0),0),-1) ) ), IF(H17<=MIN(INDEX(BAREMOS!F:X,MATCH(1,(BAREMOS!A:A=A17)*"&"(BAREMOS!B:B=B17)*(BAREMOS!C:C=C17)*(BAREMOS!D:D=D17),0),0)),1, IF(H17>=MAX(INDEX(BAREMOS!F:X,MATCH(1,(BAREMOS!A:A=A17)*(BAREMOS!B:B=B17)*(BAREMOS!C:C=C17)*(BAREMOS!D:D=D17),0),0)),19, MATCH(H17,INDEX(BAREMOS!F:X,MATCH(1,(BAREMOS!A:A=A17)*("&"BAREMOS!B:B=B17)*(BAREMOS!C:C=C17)*(BAREMOS!D:D=D17),0),0),1) ) ) ) ,"""")) "),1.0) -> 1 | K17: =IF(J17="","",INDEX(SEQUENCE(1,19,1,0.5),1,J17)) -> 1
A18: {=IF(E18="","",IFERROR(INDEX(CONFIGURACION!C:C,MATCH(E18,CONFIGURACION!E:E,0)),""))} -> BCH | B18: {=IF(E18="","",IFERROR(INDEX(CONFIGURACION!D:D,MATCH(E18,CONFIGURACION!E:E,0)),""))} -> 1 | C18: FEMENINO | D18: S. VERTICAL | E18: B1 | F18: Gladys Monserrate Ordóñez Alemán | G18: 1 TRIMESTRE | H18: 38 | I18: =IFERROR(__xludf.DUMMYFUNCTION("IF(F18="""","""",LET( nombre, TRIM(F18), primer, REGEXEXTRACT(nombre, ""^\S+""), resto, TRIM(REGEXREPLACE(nombre, ""^\S+\s*"", """")), iniciales, IF( resto="""", """", TEXTJOIN("""",1,ARRAYFORMULA(LEFT(SPLIT(resto,"" ""),1) & ""."")) "&" ), UPPER(primer) & "" "" & UPPER(iniciales) ))"),"GLADYS M.O.A.") -> GLADYS M.O.A. | J18: =IFERROR(__xludf.DUMMYFUNCTION("IF(H18="""","""",IFERROR( IF(REGEXMATCH(E18,""VELOCIDAD""), IF(H18>=MAX(INDEX(BAREMOS!F:X,MATCH(1,(BAREMOS!A:A=A18)*(BAREMOS!B:B=B18)*(BAREMOS!C:C=C18)*(BAREMOS!D:D=D18),0),0)),1, IF(H18<=MIN(INDEX(BAREMOS!F:X,MATCH(1,(BAREMOS!A:A=A18)*(BAREMOS!B"&":B=B18)*(BAREMOS!C:C=C18)*(BAREMOS!D:D=D18),0),0)),19, MATCH(H18,INDEX(BAREMOS!F:X,MATCH(1,(BAREMOS!A:A=A18)*(BAREMOS!B:B=B18)*(BAREMOS!C:C=C18)*(BAREMOS!D:D=D18),0),0),-1) ) ), IF(H18<=MIN(INDEX(BAREMOS!F:X,MATCH(1,(BAREMOS!A:A=A18)*"&"(BAREMOS!B:B=B18)*(BAREMOS!C:C=C18)*(BAREMOS!D:D=D18),0),0)),1, IF(H18>=MAX(INDEX(BAREMOS!F:X,MATCH(1,(BAREMOS!A:A=A18)*(BAREMOS!B:B=B18)*(BAREMOS!C:C=C18)*(BAREMOS!D:D=D18),0),0)),19, MATCH(H18,INDEX(BAREMOS!F:X,MATCH(1,(BAREMOS!A:A=A18)*("&"BAREMOS!B:B=B18)*(BAREMOS!C:C=C18)*(BAREMOS!D:D=D18),0),0),1) ) ) ) ,"""")) "),11.0) -> 11 | K18: =IF(J18="","",INDEX(SEQUENCE(1,19,1,0.5),1,J18)) -> 6
A19: {=IF(E19="","",IFERROR(INDEX(CONFIGURACION!C:C,MATCH(E19,CONFIGURACION!E:E,0)),""))} -> BCH | B19: {=IF(E19="","",IFERROR(INDEX(CONFIGURACION!D:D,MATCH(E19,CONFIGURACION!E:E,0)),""))} -> 1 | C19: FEMENINO | D19: S. HORIZONTAL | E19: B1 | F19: Maria Jose Franco Pico | G19: 1 TRIMESTRE | H19: 190 | I19: =IFERROR(__xludf.DUMMYFUNCTION("IF(F19="""","""",LET( nombre, TRIM(F19), primer, REGEXEXTRACT(nombre, ""^\S+""), resto, TRIM(REGEXREPLACE(nombre, ""^\S+\s*"", """")), iniciales, IF( resto="""", """", TEXTJOIN("""",1,ARRAYFORMULA(LEFT(SPLIT(resto,"" ""),1) & ""."")) "&" ), UPPER(primer) & "" "" & UPPER(iniciales) ))"),"MARIA J.F.P.") -> MARIA J.F.P. | J19: =IFERROR(__xludf.DUMMYFUNCTION("IF(H19="""","""",IFERROR( IF(REGEXMATCH(E19,""VELOCIDAD""), IF(H19>=MAX(INDEX(BAREMOS!F:X,MATCH(1,(BAREMOS!A:A=A19)*(BAREMOS!B:B=B19)*(BAREMOS!C:C=C19)*(BAREMOS!D:D=D19),0),0)),1, IF(H19<=MIN(INDEX(BAREMOS!F:X,MATCH(1,(BAREMOS!A:A=A19)*(BAREMOS!B"&":B=B19)*(BAREMOS!C:C=C19)*(BAREMOS!D:D=D19),0),0)),19, MATCH(H19,INDEX(BAREMOS!F:X,MATCH(1,(BAREMOS!A:A=A19)*(BAREMOS!B:B=B19)*(BAREMOS!C:C=C19)*(BAREMOS!D:D=D19),0),0),-1) ) ), IF(H19<=MIN(INDEX(BAREMOS!F:X,MATCH(1,(BAREMOS!A:A=A19)*"&"(BAREMOS!B:B=B19)*(BAREMOS!C:C=C19)*(BAREMOS!D:D=D19),0),0)),1, IF(H19>=MAX(INDEX(BAREMOS!F:X,MATCH(1,(BAREMOS!A:A=A19)*(BAREMOS!B:B=B19)*(BAREMOS!C:C=C19)*(BAREMOS!D:D=D19),0),0)),19, MATCH(H19,INDEX(BAREMOS!F:X,MATCH(1,(BAREMOS!A:A=A19)*("&"BAREMOS!B:B=B19)*(BAREMOS!C:C=C19)*(BAREMOS!D:D=D19),0),0),1) ) ) ) ,"""")) "),18.0) -> 18 | K19: =IF(J19="","",INDEX(SEQUENCE(1,19,1,0.5),1,J19)) -> 9.5
A20: {=IF(E20="","",IFERROR(INDEX(CONFIGURACION!C:C,MATCH(E20,CONFIGURACION!E:E,0)),""))} -> BCH | B20: {=IF(E20="","",IFERROR(INDEX(CONFIGURACION!D:D,MATCH(E20,CONFIGURACION!E:E,0)),""))} -> 1 | C20: FEMENINO | D20: ABDOMINALES | E20: B1 | F20: Sara Eguiluz Sandemetrio | G20: 1 TRIMESTRE | H20: 23 | I20: =IFERROR(__xludf.DUMMYFUNCTION("IF(F20="""","""",LET( nombre, TRIM(F20), primer, REGEXEXTRACT(nombre, ""^\S+""), resto, TRIM(REGEXREPLACE(nombre, ""^\S+\s*"", """")), iniciales, IF( resto="""", """", TEXTJOIN("""",1,ARRAYFORMULA(LEFT(SPLIT(resto,"" ""),1) & ""."")) "&" ), UPPER(primer) & "" "" & UPPER(iniciales) ))"),"SARA E.S.") -> SARA E.S. | J20: =IFERROR(__xludf.DUMMYFUNCTION("IF(H20="""","""",IFERROR( IF(REGEXMATCH(E20,""VELOCIDAD""), IF(H20>=MAX(INDEX(BAREMOS!F:X,MATCH(1,(BAREMOS!A:A=A20)*(BAREMOS!B:B=B20)*(BAREMOS!C:C=C20)*(BAREMOS!D:D=D20),0),0)),1, IF(H20<=MIN(INDEX(BAREMOS!F:X,MATCH(1,(BAREMOS!A:A=A20)*(BAREMOS!B"&":B=B20)*(BAREMOS!C:C=C20)*(BAREMOS!D:D=D20),0),0)),19, MATCH(H20,INDEX(BAREMOS!F:X,MATCH(1,(BAREMOS!A:A=A20)*(BAREMOS!B:B=B20)*(BAREMOS!C:C=C20)*(BAREMOS!D:D=D20),0),0),-1) ) ), IF(H20<=MIN(INDEX(BAREMOS!F:X,MATCH(1,(BAREMOS!A:A=A20)*"&"(BAREMOS!B:B=B20)*(BAREMOS!C:C=C20)*(BAREMOS!D:D=D20),0),0)),1, IF(H20>=MAX(INDEX(BAREMOS!F:X,MATCH(1,(BAREMOS!A:A=A20)*(BAREMOS!B:B=B20)*(BAREMOS!C:C=C20)*(BAREMOS!D:D=D20),0),0)),19, MATCH(H20,INDEX(BAREMOS!F:X,MATCH(1,(BAREMOS!A:A=A20)*("&"BAREMOS!B:B=B20)*(BAREMOS!C:C=C20)*(BAREMOS!D:D=D20),0),0),1) ) ) ) ,"""")) "),12.0) -> 12 | K20: =IF(J20="","",INDEX(SEQUENCE(1,19,1,0.5),1,J20)) -> 6.5
A21: {=IF(E21="","",IFERROR(INDEX(CONFIGURACION!C:C,MATCH(E21,CONFIGURACION!E:E,0)),""))} -> BCH | B21: {=IF(E21="","",IFERROR(INDEX(CONFIGURACION!D:D,MATCH(E21,CONFIGURACION!E:E,0)),""))} -> 1 | C21: MASCULINO | D21: L. BALON | E21: B1 | F21: Manuel Zuzunaga Garza | G21: 1 TRIMESTRE | H21: 46087 | I21: =IFERROR(__xludf.DUMMYFUNCTION("IF(F21="""","""",LET( nombre, TRIM(F21), primer, REGEXEXTRACT(nombre, ""^\S+""), resto, TRIM(REGEXREPLACE(nombre, ""^\S+\s*"", """")), iniciales, IF( resto="""", """", TEXTJOIN("""",1,ARRAYFORMULA(LEFT(SPLIT(resto,"" ""),1) & ""."")) "&" ), UPPER(primer) & "" "" & UPPER(iniciales) ))"),"MANUEL Z.G.") -> MANUEL Z.G. | J21: =IFERROR(__xludf.DUMMYFUNCTION("IF(H21="""","""",IFERROR( IF(REGEXMATCH(E21,""VELOCIDAD""), IF(H21>=MAX(INDEX(BAREMOS!F:X,MATCH(1,(BAREMOS!A:A=A21)*(BAREMOS!B:B=B21)*(BAREMOS!C:C=C21)*(BAREMOS!D:D=D21),0),0)),1, IF(H21<=MIN(INDEX(BAREMOS!F:X,MATCH(1,(BAREMOS!A:A=A21)*(BAREMOS!B"&":B=B21)*(BAREMOS!C:C=C21)*(BAREMOS!D:D=D21),0),0)),19, MATCH(H21,INDEX(BAREMOS!F:X,MATCH(1,(BAREMOS!A:A=A21)*(BAREMOS!B:B=B21)*(BAREMOS!C:C=C21)*(BAREMOS!D:D=D21),0),0),-1) ) ), IF(H21<=MIN(INDEX(BAREMOS!F:X,MATCH(1,(BAREMOS!A:A=A21)*"&"(BAREMOS!B:B=B21)*(BAREMOS!C:C=C21)*(BAREMOS!D:D=D21),0),0)),1, IF(H21>=MAX(INDEX(BAREMOS!F:X,MATCH(1,(BAREMOS!A:A=A21)*(BAREMOS!B:B=B21)*(BAREMOS!C:C=C21)*(BAREMOS!D:D=D21),0),0)),19, MATCH(H21,INDEX(BAREMOS!F:X,MATCH(1,(BAREMOS!A:A=A21)*("&"BAREMOS!B:B=B21)*(BAREMOS!C:C=C21)*(BAREMOS!D:D=D21),0),0),1) ) ) ) ,"""")) "),17.0) -> 17 | K21: =IF(J21="","",INDEX(SEQUENCE(1,19,1,0.5),1,J21)) -> 9
A22: {=IF(E22="","",IFERROR(INDEX(CONFIGURACION!C:C,MATCH(E22,CONFIGURACION!E:E,0)),""))} -> BCH | B22: {=IF(E22="","",IFERROR(INDEX(CONFIGURACION!D:D,MATCH(E22,CONFIGURACION!E:E,0)),""))} -> 1 | C22: FEMENINO | D22: VELOCIDAD | E22: B1 | F22: Elena Sorní Vital | G22: 1 TRIMESTRE | H22: 46149 | I22: =IFERROR(__xludf.DUMMYFUNCTION("IF(F22="""","""",LET( nombre, TRIM(F22), primer, REGEXEXTRACT(nombre, ""^\S+""), resto, TRIM(REGEXREPLACE(nombre, ""^\S+\s*"", """")), iniciales, IF( resto="""", """", TEXTJOIN("""",1,ARRAYFORMULA(LEFT(SPLIT(resto,"" ""),1) & ""."")) "&" ), UPPER(primer) & "" "" & UPPER(iniciales) ))"),"ELENA S.V.") -> ELENA S.V. | J22: =IFERROR(__xludf.DUMMYFUNCTION("IF(H22="""","""",IFERROR( IF(REGEXMATCH(E22,""VELOCIDAD""), IF(H22>=MAX(INDEX(BAREMOS!F:X,MATCH(1,(BAREMOS!A:A=A22)*(BAREMOS!B:B=B22)*(BAREMOS!C:C=C22)*(BAREMOS!D:D=D22),0),0)),1, IF(H22<=MIN(INDEX(BAREMOS!F:X,MATCH(1,(BAREMOS!A:A=A22)*(BAREMOS!B"&":B=B22)*(BAREMOS!C:C=C22)*(BAREMOS!D:D=D22),0),0)),19, MATCH(H22,INDEX(BAREMOS!F:X,MATCH(1,(BAREMOS!A:A=A22)*(BAREMOS!B:B=B22)*(BAREMOS!C:C=C22)*(BAREMOS!D:D=D22),0),0),-1) ) ), IF(H22<=MIN(INDEX(BAREMOS!F:X,MATCH(1,(BAREMOS!A:A=A22)*"&"(BAREMOS!B:B=B22)*(BAREMOS!C:C=C22)*(BAREMOS!D:D=D22),0),0)),1, IF(H22>=MAX(INDEX(BAREMOS!F:X,MATCH(1,(BAREMOS!A:A=A22)*(BAREMOS!B:B=B22)*(BAREMOS!C:C=C22)*(BAREMOS!D:D=D22),0),0)),19, MATCH(H22,INDEX(BAREMOS!F:X,MATCH(1,(BAREMOS!A:A=A22)*("&"BAREMOS!B:B=B22)*(BAREMOS!C:C=C22)*(BAREMOS!D:D=D22),0),0),1) ) ) ) ,"""")) "),14.0) -> 14 | K22: =IF(J22="","",INDEX(SEQUENCE(1,19,1,0.5),1,J22)) -> 7.5
A23: {=IF(E23="","",IFERROR(INDEX(CONFIGURACION!C:C,MATCH(E23,CONFIGURACION!E:E,0)),""))} -> BCH | B23: {=IF(E23="","",IFERROR(INDEX(CONFIGURACION!D:D,MATCH(E23,CONFIGURACION!E:E,0)),""))} -> 1 | C23: MASCULINO | D23: COOPER | E23: B1 | F23: Roberto Urriaga Bonachera | G23: 1 TRIMESTRE | H23: 2150 | I23: =IFERROR(__xludf.DUMMYFUNCTION("IF(F23="""","""",LET( nombre, TRIM(F23), primer, REGEXEXTRACT(nombre, ""^\S+""), resto, TRIM(REGEXREPLACE(nombre, ""^\S+\s*"", """")), iniciales, IF( resto="""", """", TEXTJOIN("""",1,ARRAYFORMULA(LEFT(SPLIT(resto,"" ""),1) & ""."")) "&" ), UPPER(primer) & "" "" & UPPER(iniciales) ))"),"ROBERTO U.B.") -> ROBERTO U.B. | J23: =IFERROR(__xludf.DUMMYFUNCTION("IF(H23="""","""",IFERROR( IF(REGEXMATCH(E23,""VELOCIDAD""), IF(H23>=MAX(INDEX(BAREMOS!F:X,MATCH(1,(BAREMOS!A:A=A23)*(BAREMOS!B:B=B23)*(BAREMOS!C:C=C23)*(BAREMOS!D:D=D23),0),0)),1, IF(H23<=MIN(INDEX(BAREMOS!F:X,MATCH(1,(BAREMOS!A:A=A23)*(BAREMOS!B"&":B=B23)*(BAREMOS!C:C=C23)*(BAREMOS!D:D=D23),0),0)),19, MATCH(H23,INDEX(BAREMOS!F:X,MATCH(1,(BAREMOS!A:A=A23)*(BAREMOS!B:B=B23)*(BAREMOS!C:C=C23)*(BAREMOS!D:D=D23),0),0),-1) ) ), IF(H23<=MIN(INDEX(BAREMOS!F:X,MATCH(1,(BAREMOS!A:A=A23)*"&"(BAREMOS!B:B=B23)*(BAREMOS!C:C=C23)*(BAREMOS!D:D=D23),0),0)),1, IF(H23>=MAX(INDEX(BAREMOS!F:X,MATCH(1,(BAREMOS!A:A=A23)*(BAREMOS!B:B=B23)*(BAREMOS!C:C=C23)*(BAREMOS!D:D=D23),0),0)),19, MATCH(H23,INDEX(BAREMOS!F:X,MATCH(1,(BAREMOS!A:A=A23)*("&"BAREMOS!B:B=B23)*(BAREMOS!C:C=C23)*(BAREMOS!D:D=D23),0),0),1) ) ) ) ,"""")) "),3.0) -> 3 | K23: =IF(J23="","",INDEX(SEQUENCE(1,19,1,0.5),1,J23)) -> 2
A24: {=IF(E24="","",IFERROR(INDEX(CONFIGURACION!C:C,MATCH(E24,CONFIGURACION!E:E,0)),""))} | B24: {=IF(E24="","",IFERROR(INDEX(CONFIGURACION!D:D,MATCH(E24,CONFIGURACION!E:E,0)),""))} | I24: =IFERROR(__xludf.DUMMYFUNCTION("IF(F24="""","""",LET( nombre, TRIM(F24), primer, REGEXEXTRACT(nombre, ""^\S+""), resto, TRIM(REGEXREPLACE(nombre, ""^\S+\s*"", """")), iniciales, IF( resto="""", """", TEXTJOIN("""",1,ARRAYFORMULA(LEFT(SPLIT(resto,"" ""),1) & ""."")) "&" ), UPPER(primer) & "" "" & UPPER(iniciales) ))"),"") | J24: =IFERROR(__xludf.DUMMYFUNCTION("IF(H24="""","""",IFERROR( IF(REGEXMATCH(E24,""VELOCIDAD""), IF(H24>=MAX(INDEX(BAREMOS!F:X,MATCH(1,(BAREMOS!A:A=A24)*(BAREMOS!B:B=B24)*(BAREMOS!C:C=C24)*(BAREMOS!D:D=D24),0),0)),1, IF(H24<=MIN(INDEX(BAREMOS!F:X,MATCH(1,(BAREMOS!A:A=A24)*(BAREMOS!B"&":B=B24)*(BAREMOS!C:C=C24)*(BAREMOS!D:D=D24),0),0)),19, MATCH(H24,INDEX(BAREMOS!F:X,MATCH(1,(BAREMOS!A:A=A24)*(BAREMOS!B:B=B24)*(BAREMOS!C:C=C24)*(BAREMOS!D:D=D24),0),0),-1) ) ), IF(H24<=MIN(INDEX(BAREMOS!F:X,MATCH(1,(BAREMOS!A:A=A24)*"&"(BAREMOS!B:B=B24)*(BAREMOS!C:C=C24)*(BAREMOS!D:D=D24),0),0)),1, IF(H24>=MAX(INDEX(BAREMOS!F:X,MATCH(1,(BAREMOS!A:A=A24)*(BAREMOS!B:B=B24)*(BAREMOS!C:C=C24)*(BAREMOS!D:D=D24),0),0)),19, MATCH(H24,INDEX(BAREMOS!F:X,MATCH(1,(BAREMOS!A:A=A24)*("&"BAREMOS!B:B=B24)*(BAREMOS!C:C=C24)*(BAREMOS!D:D=D24),0),0),1) ) ) ) ,"""")) "),"") | K24: =IF(J24="","",INDEX(SEQUENCE(1,19,1,0.5),1,J24))
A25: {=IF(E25="","",IFERROR(INDEX(CONFIGURACION!C:C,MATCH(E25,CONFIGURACION!E:E,0)),""))} | B25: {=IF(E25="","",IFERROR(INDEX(CONFIGURACION!D:D,MATCH(E25,CONFIGURACION!E:E,0)),""))} | I25: =IFERROR(__xludf.DUMMYFUNCTION("IF(F25="""","""",LET( nombre, TRIM(F25), primer, REGEXEXTRACT(nombre, ""^\S+""), resto, TRIM(REGEXREPLACE(nombre, ""^\S+\s*"", """")), iniciales, IF( resto="""", """", TEXTJOIN("""",1,ARRAYFORMULA(LEFT(SPLIT(resto,"" ""),1) & ""."")) "&" ), UPPER(primer) & "" "" & UPPER(iniciales) ))"),"") | J25: =IFERROR(__xludf.DUMMYFUNCTION("IF(H25="""","""",IFERROR( IF(REGEXMATCH(E25,""VELOCIDAD""), IF(H25>=MAX(INDEX(BAREMOS!F:X,MATCH(1,(BAREMOS!A:A=A25)*(BAREMOS!B:B=B25)*(BAREMOS!C:C=C25)*(BAREMOS!D:D=D25),0),0)),1, IF(H25<=MIN(INDEX(BAREMOS!F:X,MATCH(1,(BAREMOS!A:A=A25)*(BAREMOS!B"&":B=B25)*(BAREMOS!C:C=C25)*(BAREMOS!D:D=D25),0),0)),19, MATCH(H25,INDEX(BAREMOS!F:X,MATCH(1,(BAREMOS!A:A=A25)*(BAREMOS!B:B=B25)*(BAREMOS!C:C=C25)*(BAREMOS!D:D=D25),0),0),-1) ) ), IF(H25<=MIN(INDEX(BAREMOS!F:X,MATCH(1,(BAREMOS!A:A=A25)*"&"(BAREMOS!B:B=B25)*(BAREMOS!C:C=C25)*(BAREMOS!D:D=D25),0),0)),1, IF(H25>=MAX(INDEX(BAREMOS!F:X,MATCH(1,(BAREMOS!A:A=A25)*(BAREMOS!B:B=B25)*(BAREMOS!C:C=C25)*(BAREMOS!D:D=D25),0),0)),19, MATCH(H25,INDEX(BAREMOS!F:X,MATCH(1,(BAREMOS!A:A=A25)*("&"BAREMOS!B:B=B25)*(BAREMOS!C:C=C25)*(BAREMOS!D:D=D25),0),0),1) ) ) ) ,"""")) "),"") | K25: =IF(J25="","",INDEX(SEQUENCE(1,19,1,0.5),1,J25))
A26: {=IF(E26="","",IFERROR(INDEX(CONFIGURACION!C:C,MATCH(E26,CONFIGURACION!E:E,0)),""))} | B26: {=IF(E26="","",IFERROR(INDEX(CONFIGURACION!D:D,MATCH(E26,CONFIGURACION!E:E,0)),""))} | I26: =IFERROR(__xludf.DUMMYFUNCTION("IF(F26="""","""",LET( nombre, TRIM(F26), primer, REGEXEXTRACT(nombre, ""^\S+""), resto, TRIM(REGEXREPLACE(nombre, ""^\S+\s*"", """")), iniciales, IF( resto="""", """", TEXTJOIN("""",1,ARRAYFORMULA(LEFT(SPLIT(resto,"" ""),1) & ""."")) "&" ), UPPER(primer) & "" "" & UPPER(iniciales) ))"),"") | J26: =IFERROR(__xludf.DUMMYFUNCTION("IF(H26="""","""",IFERROR( IF(REGEXMATCH(E26,""VELOCIDAD""), IF(H26>=MAX(INDEX(BAREMOS!F:X,MATCH(1,(BAREMOS!A:A=A26)*(BAREMOS!B:B=B26)*(BAREMOS!C:C=C26)*(BAREMOS!D:D=D26),0),0)),1, IF(H26<=MIN(INDEX(BAREMOS!F:X,MATCH(1,(BAREMOS!A:A=A26)*(BAREMOS!B"&":B=B26)*(BAREMOS!C:C=C26)*(BAREMOS!D:D=D26),0),0)),19, MATCH(H26,INDEX(BAREMOS!F:X,MATCH(1,(BAREMOS!A:A=A26)*(BAREMOS!B:B=B26)*(BAREMOS!C:C=C26)*(BAREMOS!D:D=D26),0),0),-1) ) ), IF(H26<=MIN(INDEX(BAREMOS!F:X,MATCH(1,(BAREMOS!A:A=A26)*"&"(BAREMOS!B:B=B26)*(BAREMOS!C:C=C26)*(BAREMOS!D:D=D26),0),0)),1, IF(H26>=MAX(INDEX(BAREMOS!F:X,MATCH(1,(BAREMOS!A:A=A26)*(BAREMOS!B:B=B26)*(BAREMOS!C:C=C26)*(BAREMOS!D:D=D26),0),0)),19, MATCH(H26,INDEX(BAREMOS!F:X,MATCH(1,(BAREMOS!A:A=A26)*("&"BAREMOS!B:B=B26)*(BAREMOS!C:C=C26)*(BAREMOS!D:D=D26),0),0),1) ) ) ) ,"""")) "),"") | K26: =IF(J26="","",INDEX(SEQUENCE(1,19,1,0.5),1,J26))
A27: {=IF(E27="","",IFERROR(INDEX(CONFIGURACION!C:C,MATCH(E27,CONFIGURACION!E:E,0)),""))} | B27: {=IF(E27="","",IFERROR(INDEX(CONFIGURACION!D:D,MATCH(E27,CONFIGURACION!E:E,0)),""))} | I27: =IFERROR(__xludf.DUMMYFUNCTION("IF(F27="""","""",LET( nombre, TRIM(F27), primer, REGEXEXTRACT(nombre, ""^\S+""), resto, TRIM(REGEXREPLACE(nombre, ""^\S+\s*"", """")), iniciales, IF( resto="""", """", TEXTJOIN("""",1,ARRAYFORMULA(LEFT(SPLIT(resto,"" ""),1) & ""."")) "&" ), UPPER(primer) & "" "" & UPPER(iniciales) ))"),"") | J27: =IFERROR(__xludf.DUMMYFUNCTION("IF(H27="""","""",IFERROR( IF(REGEXMATCH(E27,""VELOCIDAD""), IF(H27>=MAX(INDEX(BAREMOS!F:X,MATCH(1,(BAREMOS!A:A=A27)*(BAREMOS!B:B=B27)*(BAREMOS!C:C=C27)*(BAREMOS!D:D=D27),0),0)),1, IF(H27<=MIN(INDEX(BAREMOS!F:X,MATCH(1,(BAREMOS!A:A=A27)*(BAREMOS!B"&":B=B27)*(BAREMOS!C:C=C27)*(BAREMOS!D:D=D27),0),0)),19, MATCH(H27,INDEX(BAREMOS!F:X,MATCH(1,(BAREMOS!A:A=A27)*(BAREMOS!B:B=B27)*(BAREMOS!C:C=C27)*(BAREMOS!D:D=D27),0),0),-1) ) ), IF(H27<=MIN(INDEX(BAREMOS!F:X,MATCH(1,(BAREMOS!A:A=A27)*"&"(BAREMOS!B:B=B27)*(BAREMOS!C:C=C27)*(BAREMOS!D:D=D27),0),0)),1, IF(H27>=MAX(INDEX(BAREMOS!F:X,MATCH(1,(BAREMOS!A:A=A27)*(BAREMOS!B:B=B27)*(BAREMOS!C:C=C27)*(BAREMOS!D:D=D27),0),0)),19, MATCH(H27,INDEX(BAREMOS!F:X,MATCH(1,(BAREMOS!A:A=A27)*("&"BAREMOS!B:B=B27)*(BAREMOS!C:C=C27)*(BAREMOS!D:D=D27),0),0),1) ) ) ) ,"""")) "),"") | K27: =IF(J27="","",INDEX(SEQUENCE(1,19,1,0.5),1,J27))
A28: {=IF(E28="","",IFERROR(INDEX(CONFIGURACION!C:C,MATCH(E28,CONFIGURACION!E:E,0)),""))} | B28: {=IF(E28="","",IFERROR(INDEX(CONFIGURACION!D:D,MATCH(E28,CONFIGURACION!E:E,0)),""))} | I28: =IFERROR(__xludf.DUMMYFUNCTION("IF(F28="""","""",LET( nombre, TRIM(F28), primer, REGEXEXTRACT(nombre, ""^\S+""), resto, TRIM(REGEXREPLACE(nombre, ""^\S+\s*"", """")), iniciales, IF( resto="""", """", TEXTJOIN("""",1,ARRAYFORMULA(LEFT(SPLIT(resto,"" ""),1) & ""."")) "&" ), UPPER(primer) & "" "" & UPPER(iniciales) ))"),"") | J28: =IFERROR(__xludf.DUMMYFUNCTION("IF(H28="""","""",IFERROR( IF(REGEXMATCH(E28,""VELOCIDAD""), IF(H28>=MAX(INDEX(BAREMOS!F:X,MATCH(1,(BAREMOS!A:A=A28)*(BAREMOS!B:B=B28)*(BAREMOS!C:C=C28)*(BAREMOS!D:D=D28),0),0)),1, IF(H28<=MIN(INDEX(BAREMOS!F:X,MATCH(1,(BAREMOS!A:A=A28)*(BAREMOS!B"&":B=B28)*(BAREMOS!C:C=C28)*(BAREMOS!D:D=D28),0),0)),19, MATCH(H28,INDEX(BAREMOS!F:X,MATCH(1,(BAREMOS!A:A=A28)*(BAREMOS!B:B=B28)*(BAREMOS!C:C=C28)*(BAREMOS!D:D=D28),0),0),-1) ) ), IF(H28<=MIN(INDEX(BAREMOS!F:X,MATCH(1,(BAREMOS!A:A=A28)*"&"(BAREMOS!B:B=B28)*(BAREMOS!C:C=C28)*(BAREMOS!D:D=D28),0),0)),1, IF(H28>=MAX(INDEX(BAREMOS!F:X,MATCH(1,(BAREMOS!A:A=A28)*(BAREMOS!B:B=B28)*(BAREMOS!C:C=C28)*(BAREMOS!D:D=D28),0),0)),19, MATCH(H28,INDEX(BAREMOS!F:X,MATCH(1,(BAREMOS!A:A=A28)*("&"BAREMOS!B:B=B28)*(BAREMOS!C:C=C28)*(BAREMOS!D:D=D28),0),0),1) ) ) ) ,"""")) "),"") | K28: =IF(J28="","",INDEX(SEQUENCE(1,19,1,0.5),1,J28))
A29: {=IF(E29="","",IFERROR(INDEX(CONFIGURACION!C:C,MATCH(E29,CONFIGURACION!E:E,0)),""))} | B29: {=IF(E29="","",IFERROR(INDEX(CONFIGURACION!D:D,MATCH(E29,CONFIGURACION!E:E,0)),""))} | I29: =IFERROR(__xludf.DUMMYFUNCTION("IF(F29="""","""",LET( nombre, TRIM(F29), primer, REGEXEXTRACT(nombre, ""^\S+""), resto, TRIM(REGEXREPLACE(nombre, ""^\S+\s*"", """")), iniciales, IF( resto="""", """", TEXTJOIN("""",1,ARRAYFORMULA(LEFT(SPLIT(resto,"" ""),1) & ""."")) "&" ), UPPER(primer) & "" "" & UPPER(iniciales) ))"),"") | J29: =IFERROR(__xludf.DUMMYFUNCTION("IF(H29="""","""",IFERROR( IF(REGEXMATCH(E29,""VELOCIDAD""), IF(H29>=MAX(INDEX(BAREMOS!F:X,MATCH(1,(BAREMOS!A:A=A29)*(BAREMOS!B:B=B29)*(BAREMOS!C:C=C29)*(BAREMOS!D:D=D29),0),0)),1, IF(H29<=MIN(INDEX(BAREMOS!F:X,MATCH(1,(BAREMOS!A:A=A29)*(BAREMOS!B"&":B=B29)*(BAREMOS!C:C=C29)*(BAREMOS!D:D=D29),0),0)),19, MATCH(H29,INDEX(BAREMOS!F:X,MATCH(1,(BAREMOS!A:A=A29)*(BAREMOS!B:B=B29)*(BAREMOS!C:C=C29)*(BAREMOS!D:D=D29),0),0),-1) ) ), IF(H29<=MIN(INDEX(BAREMOS!F:X,MATCH(1,(BAREMOS!A:A=A29)*"&"(BAREMOS!B:B=B29)*(BAREMOS!C:C=C29)*(BAREMOS!D:D=D29),0),0)),1, IF(H29>=MAX(INDEX(BAREMOS!F:X,MATCH(1,(BAREMOS!A:A=A29)*(BAREMOS!B:B=B29)*(BAREMOS!C:C=C29)*(BAREMOS!D:D=D29),0),0)),19, MATCH(H29,INDEX(BAREMOS!F:X,MATCH(1,(BAREMOS!A:A=A29)*("&"BAREMOS!B:B=B29)*(BAREMOS!C:C=C29)*(BAREMOS!D:D=D29),0),0),1) ) ) ) ,"""")) "),"") | K29: =IF(J29="","",INDEX(SEQUENCE(1,19,1,0.5),1,J29))
A30: {=IF(E30="","",IFERROR(INDEX(CONFIGURACION!C:C,MATCH(E30,CONFIGURACION!E:E,0)),""))} | B30: {=IF(E30="","",IFERROR(INDEX(CONFIGURACION!D:D,MATCH(E30,CONFIGURACION!E:E,0)),""))} | I30: =IFERROR(__xludf.DUMMYFUNCTION("IF(F30="""","""",LET( nombre, TRIM(F30), primer, REGEXEXTRACT(nombre, ""^\S+""), resto, TRIM(REGEXREPLACE(nombre, ""^\S+\s*"", """")), iniciales, IF( resto="""", """", TEXTJOIN("""",1,ARRAYFORMULA(LEFT(SPLIT(resto,"" ""),1) & ""."")) "&" ), UPPER(primer) & "" "" & UPPER(iniciales) ))"),"") | J30: =IFERROR(__xludf.DUMMYFUNCTION("IF(H30="""","""",IFERROR( IF(REGEXMATCH(E30,""VELOCIDAD""), IF(H30>=MAX(INDEX(BAREMOS!F:X,MATCH(1,(BAREMOS!A:A=A30)*(BAREMOS!B:B=B30)*(BAREMOS!C:C=C30)*(BAREMOS!D:D=D30),0),0)),1, IF(H30<=MIN(INDEX(BAREMOS!F:X,MATCH(1,(BAREMOS!A:A=A30)*(BAREMOS!B"&":B=B30)*(BAREMOS!C:C=C30)*(BAREMOS!D:D=D30),0),0)),19, MATCH(H30,INDEX(BAREMOS!F:X,MATCH(1,(BAREMOS!A:A=A30)*(BAREMOS!B:B=B30)*(BAREMOS!C:C=C30)*(BAREMOS!D:D=D30),0),0),-1) ) ), IF(H30<=MIN(INDEX(BAREMOS!F:X,MATCH(1,(BAREMOS!A:A=A30)*"&"(BAREMOS!B:B=B30)*(BAREMOS!C:C=C30)*(BAREMOS!D:D=D30),0),0)),1, IF(H30>=MAX(INDEX(BAREMOS!F:X,MATCH(1,(BAREMOS!A:A=A30)*(BAREMOS!B:B=B30)*(BAREMOS!C:C=C30)*(BAREMOS!D:D=D30),0),0)),19, MATCH(H30,INDEX(BAREMOS!F:X,MATCH(1,(BAREMOS!A:A=A30)*("&"BAREMOS!B:B=B30)*(BAREMOS!C:C=C30)*(BAREMOS!D:D=D30),0),0),1) ) ) ) ,"""")) "),"") | K30: =IF(J30="","",INDEX(SEQUENCE(1,19,1,0.5),1,J30))
